File: ras_to_csv_convert_plot/example/ras/TiO2-2-3h-1.ras
*RAS_DATA_START
*RAS_HEADER_START
*CORR_POS_DB_NAME "correction_file_060219"
*CORR_POS_GONIO_RADIUS ""
*CORR_POS_NODE_INDEX01 ""
*CORR_POS_NODE_INDEX02 ""
*CORR_POS_NODE_INDEX03 ""
*CORR_POS_NODE_INDEX04 ""
*CORR_POS_NODE_INDEX05 ""
*CORR_POS_NODE_INDEX06 ""
*CORR_POS_NODE_INDEX07 ""
*CORR_POS_NODE_INDEX08 ""
*CORR_POS_NODE_INDEX09 ""
*CORR_POS_NODE_INDEX10 ""
*CORR_POS_NODE_INDEX11 ""
*CORR_POS_NODE_LABEL01 "Si(111)"
*CORR_POS_NODE_LABEL02 "Si(220)"
*CORR_POS_NODE_LABEL03 "Si(311)"
*CORR_POS_NODE_LABEL04 "Si(400)"
*CORR_POS_NODE_LABEL05 "Si(331)"
*CORR_POS_NODE_LABEL06 "Si(422)"
*CORR_POS_NODE_LABEL07 "Si(511)"
*CORR_POS_NODE_LABEL08 "Si(440)"
*CORR_POS_NODE_LABEL09 "Si(531)"
*CORR_POS_NODE_LABEL10 "Si(620)"
*CORR_POS_NODE_LABEL11 "Si(533)"
*CORR_POS_NODE_POS_CALC01 "28.4137"
*CORR_POS_NODE_POS_CALC02 "47.2707"
*CORR_POS_NODE_POS_CALC03 "56.0883"
*CORR_POS_NODE_POS_CALC04 "69.0934"
*CORR_POS_NODE_POS_CALC05 "76.3385"
*CORR_POS_NODE_POS_CALC06 "87.9915"
*CORR_POS_NODE_POS_CALC07 "94.9137"
*CORR_POS_NODE_POS_CALC08 "106.67"
*CORR_POS_NODE_POS_CALC09 "114.054"
*CORR_POS_NODE_POS_CALC10 "127.508"
*CORR_POS_NODE_POS_CALC11 "136.858"
*CORR_POS_NODE_POS_MEAS01 "28.4636"
*CORR_POS_NODE_POS_MEAS02 "47.3217"
*CORR_POS_NODE_POS_MEAS03 "56.1422"
*CORR_POS_NODE_POS_MEAS04 "69.1431"
*CORR_POS_NODE_POS_MEAS05 "76.3906"
*CORR_POS_NODE_POS_MEAS06 "88.0416"
*CORR_POS_NODE_POS_MEAS07 "94.9694"
*CORR_POS_NODE_POS_MEAS08 "106.719"
*CORR_POS_NODE_POS_MEAS09 "114.106"
*CORR_POS_NODE_POS_MEAS10 "127.554"
*CORR_POS_NODE_POS_MEAS11 "136.911"
*CORR_POS_OPT_ATTR "集中法"
*CORR_POS_PARAM_MU ""
*CORR_POS_PARAM_PL ""
*CORR_POS_SEMODEL_TYPE "0"
*CORR_POS_STANDARD_TYPE ""
*CORR_POS_VALUE_ANALYZER "None"
*CORR_POS_VALUE_CMONO "None"
*CORR_POS_VALUE_IMONO "None"
*CORR_POS_VALUE_IS "0.625deg"
*CORR_POS_VALUE_ISL "10.0mm"
*CORR_POS_VALUE_ISOLLER "2.5deg"
*CORR_POS_VALUE_RS1 "13.0mm"
*CORR_POS_VALUE_RS2 "13.0mm"
*CORR_POS_VALUE_RSOLLER "2.5deg"
*CORR_POS_XG_FOCUS_L ""
*CORR_POS_XG_WAVE_TYPE ""
*CORR_POS_XG_WAVE_VALUE ""
*DISP_FMT_X "%.2f"
*DISP_FMT_Y "%.0f"
*DISP_FULLSCALE "12810.0000000000"
*DISP_LINE_COLOR "255.0000000000"
*DISP_LINE_STYLE "0.0000000000"
*DISP_LINE_WIDTH "0.2500000000"
*DISP_NOTE "Collected Data-1"
*DISP_OFFSET_Y "0.0000000000"
*DISP_PEAKSEARCH_UNIT_Y "cps"
*DISP_RANGE_BOTTOM "0.0000000000"
*DISP_RANGE_LEFT "5.0000000000"
*DISP_RANGE_LOGCUTOFF "0.0100000000"
*DISP_RANGE_RIGHT "90.0000000000"
*DISP_RANGE_TOP "12810.0000000000"
*DISP_SCALE_MODE_Y "0.0000000000"
*DISP_TAB_NAME "Theta/2-Theta"
*DISP_TITLE_Y "Intensity"
*DISP_UNIT_Y "cps"
*DISP_WINDOW_NAME "MSG_MACROENGINE"
*FILE_COMMENT " "
*FILE_MD5 ""
*FILE_MEMO " "
*FILE_OPERATOR "SDU_RIGAKU"
*FILE_SAMPLE "TiO2-2-3h-1"
*FILE_TYPE "RAS_RAW"
*FILE_USERGROUP "System User"
*FILE_VERSION "1.0000000000"
*HW_ATTACHMENT_ID "ATT1031"
*HW_ATTACHMENT_NAME "6サンプルチェンジャ|ASC-6"
*HW_COUNTER_ID-0 "CUT0025"
*HW_COUNTER_ID-1 "CUT0020"
*HW_COUNTER_ID-2 "CUT0020"
*HW_COUNTER_ID-3 "CMC0021"
*HW_COUNTER_NAME-0 "D/teX Ultra|D/teX Ultra"
*HW_COUNTER_NAME-1 "None|None"
*HW_COUNTER_NAME-2 "None|None"
*HW_COUNTER_NAME-3 "検出器モノクロメータ|Detector monochromator"
*HW_COUNTER_SELECT_NAME "D/teX Ultra|D/teX Ultra"
*HW_GONIOMETER_ID "GON0070"
*HW_GONIOMETER_NAME "MiniFlex 300/600|MiniFlex 300/600"
*HW_GONIOMETER_RADIUS-0 "79.0"
*HW_GONIOMETER_RADIUS-1 "91.5"
*HW_GONIOMETER_RADIUS-2 "150.0"
*HW_GONIOMETER_RADIUS-3 "0"
*HW_GONIOMETER_RADIUS-4 "103.4"
*HW_GONIOMETER_RADIUS-5 "150.0"
*HW_GONIOMETER_RADIUS-6 "46.6"
*HW_GONIOMETER_RADIUS-7 "160.0"
*HW_I_OPT_ID-0 "ISL0021"
*HW_I_OPT_ID-1 "ISO0021"
*HW_I_OPT_NAME-0 "発散スリット|Divergence slit"
*HW_I_OPT_NAME-1 "入射平行スリット|Incident parallel slit"
*HW_R_ATTENUATER_AUTOMODE "0"
*HW_R_OPT_ID-0 "RSS0021"
*HW_R_OPT_ID-1 "RSO0021"
*HW_R_OPT_ID-2 "RRS0021"
*HW_R_OPT_NAME-0 "散乱スリット|Scattering slit"
*HW_R_OPT_NAME-1 "受光平行スリット|Receiving soller slit"
*HW_R_OPT_NAME-2 "受光スリット|Receiving slit"
*HW_SAMPLE_HOLDER_ID "SMP0000"
*HW_SAMPLE_HOLDER_NAME "無し|None"
*HW_XG_CURRENT_MAX "15"
*HW_XG_CURRENT_MIN "2"
*HW_XG_CURRENT_RESOLUTION "1"
*HW_XG_CURRENT_UNIT "mA"
*HW_XG_FOCUS "1mm x 10mm"
*HW_XG_FOCUS_TYPE "Normal"
*HW_XG_ID ""
*HW_XG_NAME "300W/600W 封入管-B|300W/600W Sealed tube-B"
*HW_XG_TARGET_ATOMIC_NUMBER "29.0000000000"
*HW_XG_TARGET_NAME "Cu"
*HW_XG_TYPE "Hermetic"
*HW_XG_VOLTAGE_MAX "40"
*HW_XG_VOLTAGE_MIN "20"
*HW_XG_VOLTAGE_RESOLUTION "1"
*HW_XG_VOLTAGE_UNIT "kV"
*HW_XG_WATT_MAX "1"
*HW_XG_WATT_UNIT "kW"
*HW_XG_WAVE_LENGTH_ALPHA1 "1.540593"
*HW_XG_WAVE_LENGTH_ALPHA2 "1.544414"
*HW_XG_WAVE_LENGTH_BETA "1.392250"
*MEAS_COND_AXIS_NAME-0 "Theta/2-Theta"
*MEAS_COND_AXIS_NAME-1 "Spin"
*MEAS_COND_AXIS_NAME-2 "Change"
*MEAS_COND_AXIS_NAME-3 "Soller(inc.)"
*MEAS_COND_AXIS_NAME-4 "IHS"
*MEAS_COND_AXIS_NAME-5 "DS"
*MEAS_COND_AXIS_NAME-6 "SS"
*MEAS_COND_AXIS_NAME-7 "Soller(rec.)"
*MEAS_COND_AXIS_NAME-8 "RS"
*MEAS_COND_AXIS_NAME-9 "Filter"
*MEAS_COND_AXIS_NAME-10 "Monochromator"
*MEAS_COND_AXIS_NAME-11 "PHA"
*MEAS_COND_AXIS_NAME_INTERNAL-0 "TwoThetaTheta"
*MEAS_COND_AXIS_NAME_INTERNAL-1 "Spin"
*MEAS_COND_AXIS_NAME_INTERNAL-2 "Change"
*MEAS_COND_AXIS_NAME_INTERNAL-3 "IncidentSollerSlit"
*MEAS_COND_AXIS_NAME_INTERNAL-4 "IncidentAxdSlit"
*MEAS_COND_AXIS_NAME_INTERNAL-5 "IncidentSlitBox"
*MEAS_COND_AXIS_NAME_INTERNAL-6 "ReceivingSlitBox1"
*MEAS_COND_AXIS_NAME_INTERNAL-7 "ReceivingSollerSlit"
*MEAS_COND_AXIS_NAME_INTERNAL-8 "ReceivingSlitBox2"
*MEAS_COND_AXIS_NAME_INTERNAL-9 "Filter"
*MEAS_COND_AXIS_NAME_INTERNAL-10 "CounterMonochromator"
*MEAS_COND_AXIS_NAME_INTERNAL-11 "PHA"
*MEAS_COND_AXIS_NAME_MAGICNO-0 "268632064.0000000000"
*MEAS_COND_AXIS_NAME_MAGICNO-1 "16842752.0000000000"
*MEAS_COND_AXIS_NAME_MAGICNO-2 "16842752.0000000000"
*MEAS_COND_AXIS_NAME_MAGICNO-3 "20971521.0000000000"
*MEAS_COND_AXIS_NAME_MAGICNO-4 "22020097.0000000000"
*MEAS_COND_AXIS_NAME_MAGICNO-5 "22020097.0000000000"
*MEAS_COND_AXIS_NAME_MAGICNO-6 "23068673.0000000000"
*MEAS_COND_AXIS_NAME_MAGICNO-7 "20971521.0000000000"
*MEAS_COND_AXIS_NAME_MAGICNO-8 "23068673.0000000000"
*MEAS_COND_AXIS_NAME_MAGICNO-9 "20971521.0000000000"
*MEAS_COND_AXIS_NAME_MAGICNO-10 "20971521.0000000000"
*MEAS_COND_AXIS_NAME_MAGICNO-11 "0.0000000000"
*MEAS_COND_AXIS_OFFSET-0 "0.0000000000"
*MEAS_COND_AXIS_OFFSET-1 "-"
*MEAS_COND_AXIS_OFFSET-2 "-"
*MEAS_COND_AXIS_OFFSET-3 "-"
*MEAS_COND_AXIS_OFFSET-4 "-"
*MEAS_COND_AXIS_OFFSET-5 "-"
*MEAS_COND_AXIS_OFFSET-6 "-"
*MEAS_COND_AXIS_OFFSET-7 "-"
*MEAS_COND_AXIS_OFFSET-8 "-"
*MEAS_COND_AXIS_OFFSET-9 "-"
*MEAS_COND_AXIS_OFFSET-10 "-"
*MEAS_COND_AXIS_OFFSET-11 "-"
*MEAS_COND_AXIS_POSITION-0 "10.0000000000"
*MEAS_COND_AXIS_POSITION-1 "0.0000000000"
*MEAS_COND_AXIS_POSITION-2 "2.0000000000"
*MEAS_COND_AXIS_POSITION-3 "2.5deg"
*MEAS_COND_AXIS_POSITION-4 "10.0mm"
*MEAS_COND_AXIS_POSITION-5 "0.625deg"
*MEAS_COND_AXIS_POSITION-6 "13.0mm"
*MEAS_COND_AXIS_POSITION-7 "2.5deg"
*MEAS_COND_AXIS_POSITION-8 "13.0mm"
*MEAS_COND_AXIS_POSITION-9 "K-beta(x1)"
*MEAS_COND_AXIS_POSITION-10 "None"
*MEAS_COND_AXIS_POSITION-11 "42.0000000000"
*MEAS_COND_AXIS_UNIT-0 "deg"
*MEAS_COND_AXIS_UNIT-1 ""
*MEAS_COND_AXIS_UNIT-2 ""
*MEAS_COND_AXIS_UNIT-3 ""
*MEAS_COND_AXIS_UNIT-4 ""
*MEAS_COND_AXIS_UNIT-5 ""
*MEAS_COND_AXIS_UNIT-6 ""
*MEAS_COND_AXIS_UNIT-7 ""
*MEAS_COND_AXIS_UNIT-8 ""
*MEAS_COND_AXIS_UNIT-9 ""
*MEAS_COND_AXIS_UNIT-10 ""
*MEAS_COND_AXIS_UNIT-11 "div"
*MEAS_COND_CORRECTION_SLIT_COUNTERMONO "None"
*MEAS_COND_CORRECTION_SLIT_DS "0.625deg"
*MEAS_COND_CORRECTION_SLIT_FILTER "None"
*MEAS_COND_CORRECTION_SLIT_IHS "10.0mm"
*MEAS_COND_CORRECTION_SLIT_RS "13.0mm"
*MEAS_COND_CORRECTION_SLIT_SOLLER_INC "2.5deg"
*MEAS_COND_CORRECTION_SLIT_SOLLER_REC "2.5deg"
*MEAS_COND_CORRECTION_SLIT_SS "13.0mm"
*MEAS_COND_COUNTER_CNTLOSS_CORR "0.0000000000"
*MEAS_COND_COUNTER_PHABASE "42.0000000000"
*MEAS_COND_COUNTER_PHAWINDOW "15.0000000000"
*MEAS_COND_COUNTER_PHA_UNIT "div"
*MEAS_COND_COUNTER_TAUDIFF "0.2500000000"
*MEAS_COND_COUNTER_TAUINT "0.7500000000"
*MEAS_COND_IRRADIATION_MODE "OFF"
*MEAS_COND_IRRADIATION_WIDTH ""
*MEAS_COND_OPT_ATTR " "
*MEAS_COND_OPT_NAME ""
*MEAS_COND_UNSYMMETRIC_MODE "OFF"
*MEAS_COND_XG_CURRENT "15.0000000000"
*MEAS_COND_XG_VOLTAGE "40.0000000000"
*MEAS_COND_XG_WAVE_TYPE "Ka"
*MEAS_DATA_COUNT "4251.0000000000"
*MEAS_SCAN_AXIS_X "Theta/2-Theta"
*MEAS_SCAN_AXIS_X_INTERNAL "TwoThetaTheta"
*MEAS_SCAN_END_TIME "03/04/19 15:24:39"
*MEAS_SCAN_MODE "CONTINUOUS"
*MEAS_SCAN_MONITOR "0"
*MEAS_SCAN_RESOLUTION_X "0.005"
*MEAS_SCAN_SPEED "10.000"
*MEAS_SCAN_SPEED_UNIT "deg/min"
*MEAS_SCAN_START "5.0000000000"
*MEAS_SCAN_START_TIME "03/04/19 15:15:23"
*MEAS_SCAN_STEP "0.0200000000"
*MEAS_SCAN_STOP "90.0000000000"
*MEAS_SCAN_UNIT_X "deg"
*MEAS_SCAN_UNIT_Y "counts"
*SLIT_SYSTEM "0"
*RAS_HEADER_END
*RAS_INT_START
5.000 543.000 1.000
5.060 478.000 1.000
5.120 507.000 1.000
5.180 467.000 1.000
5.240 478.000 1.000
5.300 499.000 1.000
5.360 430.000 1.000
5.420 457.000 1.000
5.480 436.000 1.000
5.540 425.000 1.000
5.600 407.000 1.000
5.660 388.000 1.000
5.720 357.000 1.000
5.780 363.000 1.000
5.840 355.000 1.000
5.900 380.000 1.000
5.960 345.000 1.000
6.020 352.000 1.000
6.080 349.000 1.000
6.140 332.000 1.000
6.200 324.000 1.000
6.260 313.000 1.000
6.320 301.000 1.000
6.380 315.000 1.000
6.440 291.000 1.000
6.500 282.000 1.000
6.560 262.000 1.000
6.620 286.000 1.000
6.680 274.000 1.000
6.740 255.000 1.000
6.800 280.000 1.000
6.860 255.000 1.000
6.920 269.000 1.000
6.980 253.000 1.000
7.040 240.000 1.000
7.100 234.000 1.000
7.160 217.000 1.000
7.220 233.000 1.000
7.280 231.000 1.000
7.340 205.000 1.000
7.400 240.000 1.000
7.460 234.000 1.000
7.520 222.000 1.000
7.580 227.000 1.000
7.640 199.000 1.000
7.700 237.000 1.000
7.760 217.000 1.000
7.820 215.000 1.000
7.880 210.000 1.000
7.940 195.000 1.000
8.000 180.000 1.000
8.060 211.000 1.000
8.120 208.000 1.000
8.180 191.000 1.000
8.240 213.000 1.000
8.300 198.000 1.000
8.360 190.000 1.000
8.420 193.000 1.000
8.480 213.000 1.000
8.540 197.000 1.000
8.600 198.000 1.000
8.660 188.000 1.000
8.720 204.000 1.000
8.780 178.000 1.000
8.840 171.000 1.000
8.900 177.000 1.000
8.960 182.000 1.000
9.020 165.000 1.000
9.080 187.000 1.000
9.140 178.000 1.000
9.200 212.000 1.000
9.260 187.000 1.000
9.320 183.000 1.000
9.380 184.000 1.000
9.440 170.000 1.000
9.500 192.000 1.000
9.560 161.000 1.000
9.620 186.000 1.000
9.680 170.000 1.000
9.740 195.000 1.000
9.800 174.000 1.000
9.860 174.000 1.000
9.920 170.000 1.000
9.980 175.000 1.000
10.040 166.000 1.000
10.100 165.000 1.000
10.160 174.000 1.000
10.220 190.000 1.000
10.280 178.000 1.000
10.340 163.000 1.000
10.400 169.000 1.000
10.460 161.000 1.000
10.520 166.000 1.000
10.580 171.000 1.000
10.640 175.000 1.000
10.700 180.000 1.000
10.760 189.000 1.000
10.820 156.000 1.000
10.880 158.000 1.000
10.940 169.000 1.000
11.000 147.000 1.000
11.060 174.000 1.000
11.120 182.000 1.000
11.180 164.000 1.000
11.240 189.000 1.000
11.300 170.000 1.000
11.360 164.000 1.000
11.420 167.000 1.000
11.480 185.000 1.000
11.540 164.000 1.000
11.600 147.000 1.000
11.660 162.000 1.000
11.720 158.000 1.000
11.780 160.000 1.000
11.840 157.000 1.000
11.900 166.000 1.000
11.960 173.000 1.000
12.020 166.000 1.000
12.080 155.000 1.000
12.140 154.000 1.000
12.200 154.000 1.000
12.260 149.000 1.000
12.320 162.000 1.000
12.380 173.000 1.000
12.440 165.000 1.000
12.500 161.000 1.000
12.560 143.000 1.000
12.620 152.000 1.000
12.680 148.000 1.000
12.740 145.000 1.000
12.800 156.000 1.000
12.860 157.000 1.000
12.920 154.000 1.000
12.980 169.000 1.000
13.040 162.000 1.000
13.100 164.000 1.000
13.160 166.000 1.000
13.220 166.000 1.000
13.280 153.000 1.000
13.340 164.000 1.000
13.400 168.000 1.000
13.460 161.000 1.000
13.520 164.000 1.000
13.580 158.000 1.000
13.640 163.000 1.000
13.700 162.000 1.000
13.760 180.000 1.000
13.820 165.000 1.000
13.880 179.000 1.000
13.940 185.000 1.000
14.000 192.000 1.000
14.060 172.000 1.000
14.120 170.000 1.000
14.180 196.000 1.000
14.240 187.000 1.000
14.300 182.000 1.000
14.360 202.000 1.000
14.420 200.000 1.000
14.480 199.000 1.000
14.540 187.000 1.000
14.600 192.000 1.000
14.660 184.000 1.000
14.720 192.000 1.000
14.780 182.000 1.000
14.840 182.000 1.000
14.900 171.000 1.000
14.960 169.000 1.000
15.020 182.000 1.000
15.080 169.000 1.000
15.140 180.000 1.000
15.200 183.000 1.000
15.260 167.000 1.000
15.320 175.000 1.000
15.380 162.000 1.000
15.440 157.000 1.000
15.500 165.000 1.000
15.560 169.000 1.000
15.620 164.000 1.000
15.680 147.000 1.000
15.740 157.000 1.000
15.800 162.000 1.000
15.860 147.000 1.000
15.920 171.000 1.000
15.980 145.000 1.000
16.040 153.000 1.000
16.100 152.000 1.000
16.160 148.000 1.000
16.220 135.000 1.000
16.280 153.000 1.000
16.340 154.000 1.000
16.400 151.000 1.000
16.460 147.000 1.000
16.520 137.000 1.000
16.580 139.000 1.000
16.640 148.000 1.000
16.700 167.000 1.000
16.760 141.000 1.000
16.820 141.000 1.000
16.880 148.000 1.000
16.940 118.000 1.000
17.000 139.000 1.000
17.060 150.000 1.000
17.120 142.000 1.000
17.180 132.000 1.000
17.240 144.000 1.000
17.300 154.000 1.000
17.360 132.000 1.000
17.420 137.000 1.000
17.480 112.000 1.000
17.540 128.000 1.000
17.600 139.000 1.000
17.660 143.000 1.000
17.720 133.000 1.000
17.780 137.000 1.000
17.840 126.000 1.000
17.900 141.000 1.000
17.960 138.000 1.000
18.020 140.000 1.000
18.080 138.000 1.000
18.140 132.000 1.000
18.200 135.000 1.000
18.260 142.000 1.000
18.320 137.000 1.000
18.380 121.000 1.000
18.440 132.000 1.000
18.500 122.000 1.000
18.560 116.000 1.000
18.620 121.000 1.000
18.680 133.000 1.000
18.740 126.000 1.000
18.800 130.000 1.000
18.860 131.000 1.000
18.920 122.000 1.000
18.980 130.000 1.000
19.040 112.000 1.000
19.100 137.000 1.000
19.160 127.000 1.000
19.220 135.000 1.000
19.280 137.000 1.000
19.340 129.000 1.000
19.400 132.000 1.000
19.460 146.000 1.000
19.520 125.000 1.000
19.580 132.000 1.000
19.640 125.000 1.000
19.700 128.000 1.000
19.760 127.000 1.000
19.820 125.000 1.000
19.880 124.000 1.000
19.940 139.000 1.000
20.000 136.000 1.000
20.060 129.000 1.000
20.120 125.000 1.000
20.180 121.000 1.000
20.240 138.000 1.000
20.300 130.000 1.000
20.360 120.000 1.000
20.420 141.000 1.000
20.480 137.000 1.000
20.540 132.000 1.000
20.600 131.000 1.000
20.660 130.000 1.000
20.720 125.000 1.000
20.780 128.000 1.000
20.840 127.000 1.000
20.900 139.000 1.000
20.960 132.000 1.000
21.020 116.000 1.000
21.080 136.000 1.000
21.140 122.000 1.000
21.200 135.000 1.000
21.260 139.000 1.000
21.320 130.000 1.000
21.380 128.000 1.000
21.440 140.000 1.000
21.500 135.000 1.000
21.560 127.000 1.000
21.620 126.000 1.000
21.680 124.000 1.000
21.740 133.000 1.000
21.800 137.000 1.000
21.860 133.000 1.000
21.920 142.000 1.000
21.980 140.000 1.000
22.040 139.000 1.000
22.100 124.000 1.000
22.160 138.000 1.000
22.220 126.000 1.000
22.280 120.000 1.000
22.340 143.000 1.000
22.400 140.000 1.000
22.460 149.000 1.000
22.520 139.000 1.000
22.580 154.000 1.000
22.640 151.000 1.000
22.700 153.000 1.000
22.760 158.000 1.000
22.820 150.000 1.000
22.880 161.000 1.000
22.940 168.000 1.000
23.000 164.000 1.000
23.060 158.000 1.000
23.120 170.000 1.000
23.180 175.000 1.000
23.240 177.000 1.000
23.300 165.000 1.000
23.360 173.000 1.000
23.420 180.000 1.000
23.480 181.000 1.000
23.540 202.000 1.000
23.600 200.000 1.000
23.660 204.000 1.000
23.720 205.000 1.000
23.780 213.000 1.000
23.840 225.000 1.000
23.900 240.000 1.000
23.960 231.000 1.000
24.020 218.000 1.000
24.080 232.000 1.000
24.140 249.000 1.000
24.200 227.000 1.000
24.260 248.000 1.000
24.320 243.000 1.000
24.380 265.000 1.000
24.440 262.000 1.000
24.500 257.000 1.000
24.560 262.000 1.000
24.620 280.000 1.000
24.680 273.000 1.000
24.740 291.000 1.000
24.800 292.000 1.000
24.860 281.000 1.000
24.920 296.000 1.000
24.980 311.000 1.000
25.040 314.000 1.000
25.100 310.000 1.000
25.160 300.000 1.000
25.220 311.000 1.000
25.280 316.000 1.000
25.340 308.000 1.000
25.400 326.000 1.000
25.460 312.000 1.000
25.520 320.000 1.000
25.580 309.000 1.000
25.640 303.000 1.000
25.700 307.000 1.000
25.760 316.000 1.000
25.820 285.000 1.000
25.880 317.000 1.000
25.940 297.000 1.000
26.000 285.000 1.000
26.060 283.000 1.000
26.120 263.000 1.000
26.180 285.000 1.000
26.240 275.000 1.000
26.300 274.000 1.000
26.360 237.000 1.000
26.420 249.000 1.000
26.480 270.000 1.000
26.540 251.000 1.000
26.600 277.000 1.000
26.660 255.000 1.000
26.720 300.000 1.000
26.780 280.000 1.000
26.840 305.000 1.000
26.900 304.000 1.000
26.960 350.000 1.000
27.020 374.000 1.000
27.080 461.000 1.000
27.140 582.000 1.000
27.200 798.000 1.000
27.260 976.000 1.000
27.320 1180.000 1.000
27.380 1255.000 1.000
27.440 1144.000 1.000
27.500 928.000 1.000
27.560 778.000 1.000
27.620 538.000 1.000
27.680 461.000 1.000
27.740 381.000 1.000
27.800 325.000 1.000
27.860 295.000 1.000
27.920 246.000 1.000
27.980 265.000 1.000
28.040 232.000 1.000
28.100 215.000 1.000
28.160 237.000 1.000
28.220 205.000 1.000
28.280 230.000 1.000
28.340 202.000 1.000
28.400 203.000 1.000
28.460 213.000 1.000
28.520 194.000 1.000
28.580 212.000 1.000
28.640 193.000 1.000
28.700 193.000 1.000
28.760 199.000 1.000
28.820 178.000 1.000
28.880 179.000 1.000
28.940 182.000 1.000
29.000 185.000 1.000
29.060 174.000 1.000
29.120 178.000 1.000
29.180 168.000 1.000
29.240 151.000 1.000
29.300 168.000 1.000
29.360 163.000 1.000
29.420 152.000 1.000
29.480 146.000 1.000
29.540 136.000 1.000
29.600 145.000 1.000
29.660 169.000 1.000
29.720 155.000 1.000
29.780 151.000 1.000
29.840 153.000 1.000
29.900 146.000 1.000
29.960 149.000 1.000
30.020 143.000 1.000
30.080 137.000 1.000
30.140 127.000 1.000
30.200 143.000 1.000
30.260 147.000 1.000
30.320 154.000 1.000
30.380 147.000 1.000
30.440 146.000 1.000
30.500 142.000 1.000
30.560 138.000 1.000
30.620 144.000 1.000
30.680 144.000 1.000
30.740 149.000 1.000
30.800 129.000 1.000
30.860 121.000 1.000
30.920 133.000 1.000
30.980 134.000 1.000
31.040 127.000 1.000
31.100 133.000 1.000
31.160 131.000 1.000
31.220 130.000 1.000
31.280 129.000 1.000
31.340 130.000 1.000
31.400 105.000 1.000
31.460 120.000 1.000
31.520 117.000 1.000
31.580 113.000 1.000
31.640 97.000 1.000
31.700 110.000 1.000
31.760 99.000 1.000
31.820 115.000 1.000
31.880 112.000 1.000
31.940 92.000 1.000
32.000 105.000 1.000
32.060 117.000 1.000
32.120 101.000 1.000
32.180 105.000 1.000
32.240 100.000 1.000
32.300 101.000 1.000
32.360 103.000 1.000
32.420 102.000 1.000
32.480 96.000 1.000
32.540 87.000 1.000
32.600 88.000 1.000
32.660 118.000 1.000
32.720 93.000 1.000
32.780 107.000 1.000
32.840 94.000 1.000
32.900 97.000 1.000
32.960 103.000 1.000
33.020 109.000 1.000
33.080 93.000 1.000
33.140 88.000 1.000
33.200 100.000 1.000
33.260 114.000 1.000
33.320 85.000 1.000
33.380 98.000 1.000
33.440 92.000 1.000
33.500 98.000 1.000
33.560 103.000 1.000
33.620 93.000 1.000
33.680 103.000 1.000
33.740 88.000 1.000
33.800 109.000 1.000
33.860 87.000 1.000
33.920 88.000 1.000
33.980 91.000 1.000
34.040 93.000 1.000
34.100 90.000 1.000
34.160 101.000 1.000
34.220 91.000 1.000
34.280 86.000 1.000
34.340 85.000 1.000
34.400 88.000 1.000
34.460 87.000 1.000
34.520 89.000 1.000
34.580 84.000 1.000
34.640 92.000 1.000
34.700 91.000 1.000
34.760 91.000 1.000
34.820 106.000 1.000
34.880 95.000 1.000
34.940 98.000 1.000
35.000 99.000 1.000
35.060 109.000 1.000
35.120 86.000 1.000
35.180 105.000 1.000
35.240 106.000 1.000
35.300 116.000 1.000
35.360 114.000 1.000
35.420 105.000 1.000
35.480 127.000 1.000
35.540 115.000 1.000
35.600 139.000 1.000
35.660 146.000 1.000
35.720 162.000 1.000
35.780 168.000 1.000
35.840 201.000 1.000
35.900 278.000 1.000
35.960 379.000 1.000
36.020 556.000 1.000
36.080 648.000 1.000
36.140 607.000 1.000
36.200 453.000 1.000
36.260 334.000 1.000
36.320 255.000 1.000
36.380 196.000 1.000
36.440 178.000 1.000
36.500 160.000 1.000
36.560 142.000 1.000
36.620 127.000 1.000
36.680 133.000 1.000
36.740 121.000 1.000
36.800 116.000 1.000
36.860 112.000 1.000
36.920 134.000 1.000
36.980 117.000 1.000
37.040 112.000 1.000
37.100 134.000 1.000
37.160 125.000 1.000
37.220 123.000 1.000
37.280 120.000 1.000
37.340 126.000 1.000
37.400 123.000 1.000
37.460 113.000 1.000
37.520 110.000 1.000
37.580 113.000 1.000
37.640 116.000 1.000
37.700 125.000 1.000
37.760 118.000 1.000
37.820 120.000 1.000
37.880 113.000 1.000
37.940 128.000 1.000
38.000 118.000 1.000
38.060 108.000 1.000
38.120 118.000 1.000
38.180 112.000 1.000
38.240 119.000 1.000
38.300 109.000 1.000
38.360 119.000 1.000
38.420 107.000 1.000
38.480 103.000 1.000
38.540 95.000 1.000
38.600 102.000 1.000
38.660 111.000 1.000
38.720 100.000 1.000
38.780 102.000 1.000
38.840 118.000 1.000
38.900 119.000 1.000
38.960 127.000 1.000
39.020 146.000 1.000
39.080 140.000 1.000
39.140 140.000 1.000
39.200 122.000 1.000
39.260 117.000 1.000
39.320 116.000 1.000
39.380 94.000 1.000
39.440 107.000 1.000
39.500 95.000 1.000
39.560 87.000 1.000
39.620 86.000 1.000
39.680 108.000 1.000
39.740 92.000 1.000
39.800 84.000 1.000
39.860 87.000 1.000
39.920 96.000 1.000
39.980 95.000 1.000
40.040 89.000 1.000
40.100 81.000 1.000
40.160 91.000 1.000
40.220 81.000 1.000
40.280 77.000 1.000
40.340 79.000 1.000
40.400 71.000 1.000
40.460 76.000 1.000
40.520 84.000 1.000
40.580 79.000 1.000
40.640 87.000 1.000
40.700 91.000 1.000
40.760 98.000 1.000
40.820 108.000 1.000
40.880 106.000 1.000
40.940 116.000 1.000
41.000 139.000 1.000
41.060 195.000 1.000
41.120 275.000 1.000
41.180 332.000 1.000
41.240 354.000 1.000
41.300 305.000 1.000
41.360 238.000 1.000
41.420 172.000 1.000
41.480 136.000 1.000
41.540 114.000 1.000
41.600 119.000 1.000
41.660 89.000 1.000
41.720 81.000 1.000
41.780 86.000 1.000
41.840 87.000 1.000
41.900 80.000 1.000
41.960 70.000 1.000
42.020 82.000 1.000
42.080 80.000 1.000
42.140 88.000 1.000
42.200 75.000 1.000
42.260 79.000 1.000
42.320 74.000 1.000
42.380 72.000 1.000
42.440 77.000 1.000
42.500 81.000 1.000
42.560 63.000 1.000
42.620 75.000 1.000
42.680 77.000 1.000
42.740 76.000 1.000
42.800 88.000 1.000
42.860 83.000 1.000
42.920 77.000 1.000
42.980 73.000 1.000
43.040 88.000 1.000
43.100 88.000 1.000
43.160 88.000 1.000
43.220 86.000 1.000
43.280 87.000 1.000
43.340 87.000 1.000
43.400 84.000 1.000
43.460 86.000 1.000
43.520 102.000 1.000
43.580 94.000 1.000
43.640 117.000 1.000
43.700 135.000 1.000
43.760 147.000 1.000
43.820 158.000 1.000
43.880 162.000 1.000
43.940 183.000 1.000
44.000 162.000 1.000
44.060 140.000 1.000
44.120 137.000 1.000
44.180 114.000 1.000
44.240 106.000 1.000
44.300 98.000 1.000
44.360 94.000 1.000
44.420 104.000 1.000
44.480 105.000 1.000
44.540 93.000 1.000
44.600 91.000 1.000
44.660 102.000 1.000
44.720 83.000 1.000
44.780 81.000 1.000
44.840 87.000 1.000
44.900 90.000 1.000
44.960 76.000 1.000
45.020 88.000 1.000
45.080 81.000 1.000
45.140 85.000 1.000
45.200 84.000 1.000
45.260 84.000 1.000
45.320 74.000 1.000
45.380 76.000 1.000
45.440 76.000 1.000
45.500 67.000 1.000
45.560 72.000 1.000
45.620 80.000 1.000
45.680 73.000 1.000
45.740 83.000 1.000
45.800 70.000 1.000
45.860 75.000 1.000
45.920 76.000 1.000
45.980 80.000 1.000
46.040 83.000 1.000
46.100 77.000 1.000
46.160 77.000 1.000
46.220 72.000 1.000
46.280 74.000 1.000
46.340 79.000 1.000
46.400 74.000 1.000
46.460 85.000 1.000
46.520 80.000 1.000
46.580 78.000 1.000
46.640 74.000 1.000
46.700 88.000 1.000
46.760 86.000 1.000
46.820 82.000 1.000
46.880 96.000 1.000
46.940 99.000 1.000
47.000 90.000 1.000
47.060 97.000 1.000
47.120 80.000 1.000
47.180 83.000 1.000
47.240 93.000 1.000
47.300 109.000 1.000
47.360 92.000 1.000
47.420 103.000 1.000
47.480 99.000 1.000
47.540 100.000 1.000
47.600 96.000 1.000
47.660 89.000 1.000
47.720 105.000 1.000
47.780 103.000 1.000
47.840 106.000 1.000
47.900 99.000 1.000
47.960 113.000 1.000
48.020 111.000 1.000
48.080 96.000 1.000
48.140 97.000 1.000
48.200 97.000 1.000
48.260 108.000 1.000
48.320 120.000 1.000
48.380 114.000 1.000
48.440 111.000 1.000
48.500 97.000 1.000
48.560 99.000 1.000
48.620 92.000 1.000
48.680 106.000 1.000
48.740 90.000 1.000
48.800 112.000 1.000
48.860 93.000 1.000
48.920 93.000 1.000
48.980 86.000 1.000
49.040 105.000 1.000
49.100 86.000 1.000
49.160 86.000 1.000
49.220 90.000 1.000
49.280 82.000 1.000
49.340 90.000 1.000
49.400 94.000 1.000
49.460 91.000 1.000
49.520 88.000 1.000
49.580 89.000 1.000
49.640 78.000 1.000
49.700 79.000 1.000
49.760 82.000 1.000
49.820 69.000 1.000
49.880 76.000 1.000
49.940 79.000 1.000
50.000 73.000 1.000
50.060 74.000 1.000
50.120 68.000 1.000
50.180 72.000 1.000
50.240 65.000 1.000
50.300 64.000 1.000
50.360 72.000 1.000
50.420 66.000 1.000
50.480 72.000 1.000
50.540 62.000 1.000
50.600 74.000 1.000
50.660 63.000 1.000
50.720 73.000 1.000
50.780 69.000 1.000
50.840 68.000 1.000
50.900 62.000 1.000
50.960 72.000 1.000
51.020 67.000 1.000
51.080 65.000 1.000
51.140 70.000 1.000
51.200 62.000 1.000
51.260 60.000 1.000
51.320 72.000 1.000
51.380 77.000 1.000
51.440 59.000 1.000
51.500 59.000 1.000
51.560 55.000 1.000
51.620 75.000 1.000
51.680 67.000 1.000
51.740 76.000 1.000
51.800 61.000 1.000
51.860 74.000 1.000
51.920 60.000 1.000
51.980 80.000 1.000
52.040 70.000 1.000
52.100 66.000 1.000
52.160 68.000 1.000
52.220 70.000 1.000
52.280 76.000 1.000
52.340 71.000 1.000
52.400 71.000 1.000
52.460 71.000 1.000
52.520 70.000 1.000
52.580 76.000 1.000
52.640 81.000 1.000
52.700 82.000 1.000
52.760 99.000 1.000
52.820 105.000 1.000
52.880 89.000 1.000
52.940 93.000 1.000
53.000 99.000 1.000
53.060 99.000 1.000
53.120 95.000 1.000
53.180 95.000 1.000
53.240 98.000 1.000
53.300 112.000 1.000
53.360 117.000 1.000
53.420 106.000 1.000
53.480 118.000 1.000
53.540 132.000 1.000
53.600 134.000 1.000
53.660 139.000 1.000
53.720 154.000 1.000
53.780 158.000 1.000
53.840 211.000 1.000
53.900 222.000 1.000
53.960 249.000 1.000
54.020 327.000 1.000
54.080 420.000 1.000
54.140 561.000 1.000
54.200 600.000 1.000
54.260 612.000 1.000
54.320 608.000 1.000
54.380 498.000 1.000
54.440 412.000 1.000
54.500 342.000 1.000
54.560 286.000 1.000
54.620 206.000 1.000
54.680 216.000 1.000
54.740 181.000 1.000
54.800 171.000 1.000
54.860 153.000 1.000
54.920 140.000 1.000
54.980 140.000 1.000
55.040 136.000 1.000
55.100 141.000 1.000
55.160 126.000 1.000
55.220 129.000 1.000
55.280 115.000 1.000
55.340 120.000 1.000
55.400 127.000 1.000
55.460 112.000 1.000
55.520 90.000 1.000
55.580 102.000 1.000
55.640 97.000 1.000
55.700 100.000 1.000
55.760 104.000 1.000
55.820 102.000 1.000
55.880 113.000 1.000
55.940 82.000 1.000
56.000 117.000 1.000
56.060 125.000 1.000
56.120 121.000 1.000
56.180 131.000 1.000
56.240 144.000 1.000
56.300 181.000 1.000
56.360 205.000 1.000
56.420 231.000 1.000
56.480 234.000 1.000
56.540 228.000 1.000
56.600 200.000 1.000
56.660 187.000 1.000
56.720 171.000 1.000
56.780 139.000 1.000
56.840 113.000 1.000
56.900 119.000 1.000
56.960 111.000 1.000
57.020 99.000 1.000
57.080 94.000 1.000
57.140 96.000 1.000
57.200 89.000 1.000
57.260 80.000 1.000
57.320 84.000 1.000
57.380 80.000 1.000
57.440 84.000 1.000
57.500 73.000 1.000
57.560 73.000 1.000
57.620 83.000 1.000
57.680 82.000 1.000
57.740 70.000 1.000
57.800 79.000 1.000
57.860 66.000 1.000
57.920 74.000 1.000
57.980 75.000 1.000
58.040 77.000 1.000
58.100 68.000 1.000
58.160 68.000 1.000
58.220 70.000 1.000
58.280 75.000 1.000
58.340 77.000 1.000
58.400 74.000 1.000
58.460 73.000 1.000
58.520 69.000 1.000
58.580 56.000 1.000
58.640 68.000 1.000
58.700 66.000 1.000
58.760 70.000 1.000
58.820 63.000 1.000
58.880 68.000 1.000
58.940 69.000 1.000
59.000 56.000 1.000
59.060 60.000 1.000
59.120 66.000 1.000
59.180 55.000 1.000
59.240 68.000 1.000
59.300 62.000 1.000
59.360 60.000 1.000
59.420 62.000 1.000
59.480 64.000 1.000
59.540 58.000 1.000
59.600 58.000 1.000
59.660 65.000 1.000
59.720 68.000 1.000
59.780 53.000 1.000
59.840 57.000 1.000
59.900 58.000 1.000
59.960 49.000 1.000
60.020 54.000 1.000
60.080 63.000 1.000
60.140 57.000 1.000
60.200 58.000 1.000
60.260 59.000 1.000
60.320 62.000 1.000
60.380 52.000 1.000
60.440 54.000 1.000
60.500 54.000 1.000
60.560 58.000 1.000
60.620 62.000 1.000
60.680 47.000 1.000
60.740 59.000 1.000
60.800 63.000 1.000
60.860 59.000 1.000
60.920 61.000 1.000
60.980 65.000 1.000
61.040 64.000 1.000
61.100 65.000 1.000
61.160 58.000 1.000
61.220 54.000 1.000
61.280 63.000 1.000
61.340 63.000 1.000
61.400 61.000 1.000
61.460 86.000 1.000
61.520 61.000 1.000
61.580 62.000 1.000
61.640 73.000 1.000
61.700 79.000 1.000
61.760 78.000 1.000
61.820 70.000 1.000
61.880 66.000 1.000
61.940 73.000 1.000
62.000 76.000 1.000
62.060 72.000 1.000
62.120 74.000 1.000
62.180 85.000 1.000
62.240 78.000 1.000
62.300 89.000 1.000
62.360 90.000 1.000
62.420 78.000 1.000
62.480 90.000 1.000
62.540 88.000 1.000
62.600 103.000 1.000
62.660 110.000 1.000
62.720 128.000 1.000
62.780 186.000 1.000
62.840 186.000 1.000
62.900 164.000 1.000
62.960 143.000 1.000
63.020 136.000 1.000
63.080 118.000 1.000
63.140 103.000 1.000
63.200 93.000 1.000
63.260 84.000 1.000
63.320 91.000 1.000
63.380 97.000 1.000
63.440 86.000 1.000
63.500 86.000 1.000
63.560 89.000 1.000
63.620 106.000 1.000
63.680 118.000 1.000
63.740 129.000 1.000
63.800 118.000 1.000
63.860 132.000 1.000
63.920 139.000 1.000
63.980 130.000 1.000
64.040 116.000 1.000
64.100 102.000 1.000
64.160 102.000 1.000
64.220 97.000 1.000
64.280 88.000 1.000
64.340 82.000 1.000
64.400 77.000 1.000
64.460 66.000 1.000
64.520 74.000 1.000
64.580 76.000 1.000
64.640 71.000 1.000
64.700 71.000 1.000
64.760 63.000 1.000
64.820 57.000 1.000
64.880 67.000 1.000
64.940 61.000 1.000
65.000 61.000 1.000
65.060 59.000 1.000
65.120 59.000 1.000
65.180 63.000 1.000
65.240 63.000 1.000
65.300 62.000 1.000
65.360 74.000 1.000
65.420 58.000 1.000
65.480 53.000 1.000
65.540 64.000 1.000
65.600 57.000 1.000
65.660 47.000 1.000
65.720 53.000 1.000
65.780 51.000 1.000
65.840 53.000 1.000
65.900 53.000 1.000
65.960 57.000 1.000
66.020 54.000 1.000
66.080 57.000 1.000
66.140 53.000 1.000
66.200 50.000 1.000
66.260 59.000 1.000
66.320 48.000 1.000
66.380 55.000 1.000
66.440 55.000 1.000
66.500 55.000 1.000
66.560 63.000 1.000
66.620 58.000 1.000
66.680 58.000 1.000
66.740 70.000 1.000
66.800 60.000 1.000
66.860 64.000 1.000
66.920 55.000 1.000
66.980 58.000 1.000
67.040 51.000 1.000
67.100 51.000 1.000
67.160 56.000 1.000
67.220 56.000 1.000
67.280 47.000 1.000
67.340 53.000 1.000
67.400 54.000 1.000
67.460 57.000 1.000
67.520 58.000 1.000
67.580 68.000 1.000
67.640 70.000 1.000
67.700 66.000 1.000
67.760 58.000 1.000
67.820 61.000 1.000
67.880 59.000 1.000
67.940 67.000 1.000
68.000 50.000 1.000
68.060 67.000 1.000
68.120 69.000 1.000
68.180 69.000 1.000
68.240 84.000 1.000
68.300 68.000 1.000
68.360 81.000 1.000
68.420 83.000 1.000
68.480 97.000 1.000
68.540 106.000 1.000
68.600 132.000 1.000
68.660 149.000 1.000
68.720 181.000 1.000
68.780 201.000 1.000
68.840 230.000 1.000
68.900 213.000 1.000
68.960 202.000 1.000
69.020 184.000 1.000
69.080 153.000 1.000
69.140 154.000 1.000
69.200 120.000 1.000
69.260 116.000 1.000
69.320 104.000 1.000
69.380 93.000 1.000
69.440 97.000 1.000
69.500 82.000 1.000
69.560 80.000 1.000
69.620 93.000 1.000
69.680 107.000 1.000
69.740 130.000 1.000
69.800 161.000 1.000
69.860 142.000 1.000
69.920 121.000 1.000
69.980 127.000 1.000
70.040 122.000 1.000
70.100 107.000 1.000
70.160 92.000 1.000
70.220 75.000 1.000
70.280 70.000 1.000
70.340 71.000 1.000
70.400 59.000 1.000
70.460 52.000 1.000
70.520 62.000 1.000
70.580 57.000 1.000
70.640 46.000 1.000
70.700 56.000 1.000
70.760 48.000 1.000
70.820 51.000 1.000
70.880 46.000 1.000
70.940 39.000 1.000
71.000 55.000 1.000
71.060 54.000 1.000
71.120 50.000 1.000
71.180 44.000 1.000
71.240 45.000 1.000
71.300 46.000 1.000
71.360 42.000 1.000
71.420 45.000 1.000
71.480 51.000 1.000
71.540 46.000 1.000
71.600 50.000 1.000
71.660 44.000 1.000
71.720 45.000 1.000
71.780 42.000 1.000
71.840 49.000 1.000
71.900 47.000 1.000
71.960 40.000 1.000
72.020 48.000 1.000
72.080 49.000 1.000
72.140 49.000 1.000
72.200 51.000 1.000
72.260 46.000 1.000
72.320 52.000 1.000
72.380 53.000 1.000
72.440 46.000 1.000
72.500 48.000 1.000
72.560 41.000 1.000
72.620 45.000 1.000
72.680 33.000 1.000
72.740 34.000 1.000
72.800 44.000 1.000
72.860 40.000 1.000
72.920 41.000 1.000
72.980 38.000 1.000
73.040 34.000 1.000
73.100 43.000 1.000
73.160 39.000 1.000
73.220 34.000 1.000
73.280 36.000 1.000
73.340 53.000 1.000
73.400 40.000 1.000
73.460 46.000 1.000
73.520 39.000 1.000
73.580 39.000 1.000
73.640 41.000 1.000
73.700 46.000 1.000
73.760 44.000 1.000
73.820 45.000 1.000
73.880 51.000 1.000
73.940 40.000 1.000
74.000 41.000 1.000
74.060 40.000 1.000
74.120 46.000 1.000
74.180 46.000 1.000
74.240 48.000 1.000
74.300 47.000 1.000
74.360 56.000 1.000
74.420 47.000 1.000
74.480 46.000 1.000
74.540 48.000 1.000
74.600 46.000 1.000
74.660 58.000 1.000
74.720 48.000 1.000
74.780 55.000 1.000
74.840 55.000 1.000
74.900 44.000 1.000
74.960 48.000 1.000
75.020 47.000 1.000
75.080 50.000 1.000
75.140 42.000 1.000
75.200 47.000 1.000
75.260 48.000 1.000
75.320 48.000 1.000
75.380 47.000 1.000
75.440 61.000 1.000
75.500 48.000 1.000
75.560 53.000 1.000
75.620 49.000 1.000
75.680 58.000 1.000
75.740 51.000 1.000
75.800 52.000 1.000
75.860 44.000 1.000
75.920 46.000 1.000
75.980 46.000 1.000
76.040 56.000 1.000
76.100 53.000 1.000
76.160 45.000 1.000
76.220 60.000 1.000
76.280 51.000 1.000
76.340 44.000 1.000
76.400 59.000 1.000
76.460 61.000 1.000
76.520 70.000 1.000
76.580 63.000 1.000
76.640 60.000 1.000
76.700 56.000 1.000
76.760 57.000 1.000
76.820 62.000 1.000
76.880 44.000 1.000
76.940 45.000 1.000
77.000 66.000 1.000
77.060 55.000 1.000
77.120 51.000 1.000
77.180 36.000 1.000
77.240 44.000 1.000
77.300 48.000 1.000
77.360 48.000 1.000
77.420 57.000 1.000
77.480 54.000 1.000
77.540 36.000 1.000
77.600 47.000 1.000
77.660 34.000 1.000
77.720 38.000 1.000
77.780 36.000 1.000
77.840 41.000 1.000
77.900 42.000 1.000
77.960 33.000 1.000
78.020 43.000 1.000
78.080 34.000 1.000
78.140 37.000 1.000
78.200 33.000 1.000
78.260 42.000 1.000
78.320 35.000 1.000
78.380 38.000 1.000
78.440 43.000 1.000
78.500 41.000 1.000
78.560 41.000 1.000
78.620 37.000 1.000
78.680 31.000 1.000
78.740 35.000 1.000
78.800 34.000 1.000
78.860 43.000 1.000
78.920 34.000 1.000
78.980 35.000 1.000
79.040 33.000 1.000
79.100 30.000 1.000
79.160 42.000 1.000
79.220 34.000 1.000
79.280 38.000 1.000
79.340 43.000 1.000
79.400 38.000 1.000
79.460 42.000 1.000
79.520 42.000 1.000
79.580 43.000 1.000
79.640 39.000 1.000
79.700 45.000 1.000
79.760 49.000 1.000
79.820 52.000 1.000
79.880 38.000 1.000
79.940 40.000 1.000
80.000 46.000 1.000
80.060 38.000 1.000
80.120 37.000 1.000
80.180 33.000 1.000
80.240 28.000 1.000
80.300 41.000 1.000
80.360 32.000 1.000
80.420 37.000 1.000
80.480 34.000 1.000
80.540 37.000 1.000
80.600 38.000 1.000
80.660 34.000 1.000
80.720 34.000 1.000
80.780 36.000 1.000
80.840 38.000 1.000
80.900 43.000 1.000
80.960 36.000 1.000
81.020 40.000 1.000
81.080 40.000 1.000
81.140 37.000 1.000
81.200 40.000 1.000
81.260 36.000 1.000
81.320 32.000 1.000
81.380 43.000 1.000
81.440 35.000 1.000
81.500 36.000 1.000
81.560 41.000 1.000
81.620 42.000 1.000
81.680 47.000 1.000
81.740 46.000 1.000
81.800 41.000 1.000
81.860 50.000 1.000
81.920 54.000 1.000
81.980 57.000 1.000
82.040 55.000 1.000
82.100 62.000 1.000
82.160 56.000 1.000
82.220 59.000 1.000
82.280 53.000 1.000
82.340 64.000 1.000
82.400 53.000 1.000
82.460 48.000 1.000
82.520 44.000 1.000
82.580 49.000 1.000
82.640 46.000 1.000
82.700 50.000 1.000
82.760 47.000 1.000
82.820 49.000 1.000
82.880 39.000 1.000
82.940 40.000 1.000
83.000 43.000 1.000
83.060 48.000 1.000
83.120 48.000 1.000
83.180 45.000 1.000
83.240 43.000 1.000
83.300 41.000 1.000
83.360 45.000 1.000
83.420 48.000 1.000
83.480 35.000 1.000
83.540 51.000 1.000
83.600 42.000 1.000
83.660 43.000 1.000
83.720 57.000 1.000
83.780 59.000 1.000
83.840 60.000 1.000
83.900 66.000 1.000
83.960 59.000 1.000
84.020 50.000 1.000
84.080 58.000 1.000
84.140 49.000 1.000
84.200 47.000 1.000
84.260 49.000 1.000
84.320 56.000 1.000
84.380 40.000 1.000
84.440 39.000 1.000
84.500 50.000 1.000
84.560 47.000 1.000
84.620 42.000 1.000
84.680 38.000 1.000
84.740 43.000 1.000
84.800 39.000 1.000
84.860 45.000 1.000
84.920 33.000 1.000
84.980 34.000 1.000
85.040 39.000 1.000
85.100 40.000 1.000
85.160 31.000 1.000
85.220 39.000 1.000
85.280 31.000 1.000
85.340 28.000 1.000
85.400 25.000 1.000
85.460 23.000 1.000
85.520 33.000 1.000
85.580 35.000 1.000
85.640 35.000 1.000
85.700 33.000 1.000
85.760 26.000 1.000
85.820 29.000 1.000
85.880 23.000 1.000
85.940 41.000 1.000
86.000 36.000 1.000
86.060 31.000 1.000
86.120 36.000 1.000
86.180 28.000 1.000
86.240 32.000 1.000
86.300 34.000 1.000
86.360 36.000 1.000
86.420 36.000 1.000
86.480 34.000 1.000
86.540 33.000 1.000
86.600 29.000 1.000
86.660 31.000 1.000
86.720 37.000 1.000
86.780 32.000 1.000
86.840 32.000 1.000
86.900 37.000 1.000
86.960 39.000 1.000
87.020 35.000 1.000
87.080 42.000 1.000
87.140 40.000 1.000
87.200 34.000 1.000
87.260 34.000 1.000
87.320 36.000 1.000
87.380 36.000 1.000
87.440 35.000 1.000
87.500 34.000 1.000
87.560 35.000 1.000
87.620 30.000 1.000
87.680 31.000 1.000
87.740 33.000 1.000
87.800 27.000 1.000
87.860 34.000 1.000
87.920 28.000 1.000
87.980 32.000 1.000
88.040 36.000 1.000
88.100 31.000 1.000
88.160 28.000 1.000
88.220 37.000 1.000
88.280 27.000 1.000
88.340 30.000 1.000
88.400 39.000 1.000
88.460 30.000 1.000
88.520 32.000 1.000
88.580 25.000 1.000
88.640 34.000 1.000
88.700 34.000 1.000
88.760 37.000 1.000
88.820 35.000 1.000
88.880 31.000 1.000
88.940 34.000 1.000
89.000 37.000 1.000
89.060 41.000 1.000
89.120 45.000 1.000
89.180 51.000 1.000
89.240 64.000 1.000
89.300 69.000 1.000
89.360 80.000 1.000
89.420 85.000 1.000
89.480 74.000 1.000
89.540 79.000 1.000
89.600 81.000 1.000
89.660 66.000 1.000
89.720 73.000 1.000
89.780 57.000 1.000
89.840 58.000 1.000
89.900 55.000 1.000
89.960 51.000 1.000
90.000 51.000 1.000
*RAS_INT_END
*RAS_DATA_END