File: ras_to_csv_convert_plot/example/ras/TiO2-1-9h-BET.ras
*RAS_DATA_START
*RAS_HEADER_START
*CORR_POS_DB_NAME "correction_file_020419"
*CORR_POS_GONIO_RADIUS ""
*CORR_POS_NODE_INDEX01 ""
*CORR_POS_NODE_INDEX02 ""
*CORR_POS_NODE_INDEX03 ""
*CORR_POS_NODE_INDEX04 ""
*CORR_POS_NODE_INDEX05 ""
*CORR_POS_NODE_INDEX06 ""
*CORR_POS_NODE_INDEX07 ""
*CORR_POS_NODE_INDEX08 ""
*CORR_POS_NODE_INDEX09 ""
*CORR_POS_NODE_INDEX10 ""
*CORR_POS_NODE_INDEX11 ""
*CORR_POS_NODE_LABEL01 "Si(111)"
*CORR_POS_NODE_LABEL02 "Si(220)"
*CORR_POS_NODE_LABEL03 "Si(311)"
*CORR_POS_NODE_LABEL04 "Si(400)"
*CORR_POS_NODE_LABEL05 "Si(331)"
*CORR_POS_NODE_LABEL06 "Si(422)"
*CORR_POS_NODE_LABEL07 "Si(511)"
*CORR_POS_NODE_LABEL08 "Si(440)"
*CORR_POS_NODE_LABEL09 "Si(531)"
*CORR_POS_NODE_LABEL10 "Si(620)"
*CORR_POS_NODE_LABEL11 "Si(533)"
*CORR_POS_NODE_POS_CALC01 "28.4137"
*CORR_POS_NODE_POS_CALC02 "47.2707"
*CORR_POS_NODE_POS_CALC03 "56.0883"
*CORR_POS_NODE_POS_CALC04 "69.0934"
*CORR_POS_NODE_POS_CALC05 "76.3385"
*CORR_POS_NODE_POS_CALC06 "87.9915"
*CORR_POS_NODE_POS_CALC07 "94.9137"
*CORR_POS_NODE_POS_CALC08 "106.67"
*CORR_POS_NODE_POS_CALC09 "114.054"
*CORR_POS_NODE_POS_CALC10 "127.508"
*CORR_POS_NODE_POS_CALC11 "136.858"
*CORR_POS_NODE_POS_MEAS01 "28.463"
*CORR_POS_NODE_POS_MEAS02 "47.3124"
*CORR_POS_NODE_POS_MEAS03 "56.1276"
*CORR_POS_NODE_POS_MEAS04 "69.1418"
*CORR_POS_NODE_POS_MEAS05 "76.3865"
*CORR_POS_NODE_POS_MEAS06 "88.0411"
*CORR_POS_NODE_POS_MEAS07 "94.9598"
*CORR_POS_NODE_POS_MEAS08 "106.713"
*CORR_POS_NODE_POS_MEAS09 "114.102"
*CORR_POS_NODE_POS_MEAS10 "127.558"
*CORR_POS_NODE_POS_MEAS11 "136.911"
*CORR_POS_OPT_ATTR "集中法"
*CORR_POS_PARAM_MU ""
*CORR_POS_PARAM_PL ""
*CORR_POS_SEMODEL_TYPE "0"
*CORR_POS_STANDARD_TYPE ""
*CORR_POS_VALUE_ANALYZER "None"
*CORR_POS_VALUE_CMONO "None"
*CORR_POS_VALUE_IMONO "None"
*CORR_POS_VALUE_IS "0.625deg"
*CORR_POS_VALUE_ISL "10.0mm"
*CORR_POS_VALUE_ISOLLER "2.5deg"
*CORR_POS_VALUE_RS1 "13.0mm"
*CORR_POS_VALUE_RS2 "13.0mm"
*CORR_POS_VALUE_RSOLLER "2.5deg"
*CORR_POS_XG_FOCUS_L ""
*CORR_POS_XG_WAVE_TYPE ""
*CORR_POS_XG_WAVE_VALUE ""
*DISP_FMT_X "%.2f"
*DISP_FMT_Y "%.0f"
*DISP_FULLSCALE "23870.0000000000"
*DISP_LINE_COLOR "255.0000000000"
*DISP_LINE_STYLE "0.0000000000"
*DISP_LINE_WIDTH "0.2500000000"
*DISP_NOTE "Collected Data-3"
*DISP_OFFSET_Y "0.0000000000"
*DISP_PEAKSEARCH_UNIT_Y "cps"
*DISP_RANGE_BOTTOM "0.0000000000"
*DISP_RANGE_LEFT "5.0000000000"
*DISP_RANGE_LOGCUTOFF "0.0100000000"
*DISP_RANGE_RIGHT "90.0000000000"
*DISP_RANGE_TOP "23870.0000000000"
*DISP_SCALE_MODE_Y "0.0000000000"
*DISP_TAB_NAME "Theta/2-Theta"
*DISP_TITLE_Y "Intensity"
*DISP_UNIT_Y "cps"
*DISP_WINDOW_NAME "MSG_MACROENGINE"
*FILE_COMMENT " "
*FILE_MD5 ""
*FILE_MEMO " "
*FILE_OPERATOR "SDU_RIGAKU"
*FILE_SAMPLE "TiO2-1-9h-BET"
*FILE_TYPE "RAS_RAW"
*FILE_USERGROUP "System User"
*FILE_VERSION "1.0000000000"
*HW_ATTACHMENT_ID "ATT1031"
*HW_ATTACHMENT_NAME "6サンプルチェンジャ|ASC-6"
*HW_COUNTER_ID-0 "CUT0025"
*HW_COUNTER_ID-1 "CUT0020"
*HW_COUNTER_ID-2 "CUT0020"
*HW_COUNTER_ID-3 "CMC0021"
*HW_COUNTER_NAME-0 "D/teX Ultra|D/teX Ultra"
*HW_COUNTER_NAME-1 "None|None"
*HW_COUNTER_NAME-2 "None|None"
*HW_COUNTER_NAME-3 "検出器モノクロメータ|Detector monochromator"
*HW_COUNTER_SELECT_NAME "D/teX Ultra|D/teX Ultra"
*HW_GONIOMETER_ID "GON0070"
*HW_GONIOMETER_NAME "MiniFlex 300/600|MiniFlex 300/600"
*HW_GONIOMETER_RADIUS-0 "79.0"
*HW_GONIOMETER_RADIUS-1 "91.5"
*HW_GONIOMETER_RADIUS-2 "150.0"
*HW_GONIOMETER_RADIUS-3 "0"
*HW_GONIOMETER_RADIUS-4 "103.4"
*HW_GONIOMETER_RADIUS-5 "150.0"
*HW_GONIOMETER_RADIUS-6 "46.6"
*HW_GONIOMETER_RADIUS-7 "160.0"
*HW_I_OPT_ID-0 "ISL0021"
*HW_I_OPT_ID-1 "ISO0021"
*HW_I_OPT_NAME-0 "発散スリット|Divergence slit"
*HW_I_OPT_NAME-1 "入射平行スリット|Incident parallel slit"
*HW_R_ATTENUATER_AUTOMODE "0"
*HW_R_OPT_ID-0 "RSS0021"
*HW_R_OPT_ID-1 "RSO0021"
*HW_R_OPT_ID-2 "RRS0021"
*HW_R_OPT_NAME-0 "散乱スリット|Scattering slit"
*HW_R_OPT_NAME-1 "受光平行スリット|Receiving soller slit"
*HW_R_OPT_NAME-2 "受光スリット|Receiving slit"
*HW_SAMPLE_HOLDER_ID "SMP0000"
*HW_SAMPLE_HOLDER_NAME "無し|None"
*HW_XG_CURRENT_MAX "15"
*HW_XG_CURRENT_MIN "2"
*HW_XG_CURRENT_RESOLUTION "1"
*HW_XG_CURRENT_UNIT "mA"
*HW_XG_FOCUS "1mm x 10mm"
*HW_XG_FOCUS_TYPE "Normal"
*HW_XG_ID ""
*HW_XG_NAME "300W/600W 封入管-B|300W/600W Sealed tube-B"
*HW_XG_TARGET_ATOMIC_NUMBER "29.0000000000"
*HW_XG_TARGET_NAME "Cu"
*HW_XG_TYPE "Hermetic"
*HW_XG_VOLTAGE_MAX "40"
*HW_XG_VOLTAGE_MIN "20"
*HW_XG_VOLTAGE_RESOLUTION "1"
*HW_XG_VOLTAGE_UNIT "kV"
*HW_XG_WATT_MAX "1"
*HW_XG_WATT_UNIT "kW"
*HW_XG_WAVE_LENGTH_ALPHA1 "1.540593"
*HW_XG_WAVE_LENGTH_ALPHA2 "1.544414"
*HW_XG_WAVE_LENGTH_BETA "1.392250"
*MEAS_COND_AXIS_NAME-0 "Theta/2-Theta"
*MEAS_COND_AXIS_NAME-1 "Spin"
*MEAS_COND_AXIS_NAME-2 "Change"
*MEAS_COND_AXIS_NAME-3 "Soller(inc.)"
*MEAS_COND_AXIS_NAME-4 "IHS"
*MEAS_COND_AXIS_NAME-5 "DS"
*MEAS_COND_AXIS_NAME-6 "SS"
*MEAS_COND_AXIS_NAME-7 "Soller(rec.)"
*MEAS_COND_AXIS_NAME-8 "RS"
*MEAS_COND_AXIS_NAME-9 "Filter"
*MEAS_COND_AXIS_NAME-10 "Monochromator"
*MEAS_COND_AXIS_NAME-11 "PHA"
*MEAS_COND_AXIS_NAME_INTERNAL-0 "TwoThetaTheta"
*MEAS_COND_AXIS_NAME_INTERNAL-1 "Spin"
*MEAS_COND_AXIS_NAME_INTERNAL-2 "Change"
*MEAS_COND_AXIS_NAME_INTERNAL-3 "IncidentSollerSlit"
*MEAS_COND_AXIS_NAME_INTERNAL-4 "IncidentAxdSlit"
*MEAS_COND_AXIS_NAME_INTERNAL-5 "IncidentSlitBox"
*MEAS_COND_AXIS_NAME_INTERNAL-6 "ReceivingSlitBox1"
*MEAS_COND_AXIS_NAME_INTERNAL-7 "ReceivingSollerSlit"
*MEAS_COND_AXIS_NAME_INTERNAL-8 "ReceivingSlitBox2"
*MEAS_COND_AXIS_NAME_INTERNAL-9 "Filter"
*MEAS_COND_AXIS_NAME_INTERNAL-10 "CounterMonochromator"
*MEAS_COND_AXIS_NAME_INTERNAL-11 "PHA"
*MEAS_COND_AXIS_NAME_MAGICNO-0 "268632064.0000000000"
*MEAS_COND_AXIS_NAME_MAGICNO-1 "16842752.0000000000"
*MEAS_COND_AXIS_NAME_MAGICNO-2 "16842752.0000000000"
*MEAS_COND_AXIS_NAME_MAGICNO-3 "20971521.0000000000"
*MEAS_COND_AXIS_NAME_MAGICNO-4 "22020097.0000000000"
*MEAS_COND_AXIS_NAME_MAGICNO-5 "22020097.0000000000"
*MEAS_COND_AXIS_NAME_MAGICNO-6 "23068673.0000000000"
*MEAS_COND_AXIS_NAME_MAGICNO-7 "20971521.0000000000"
*MEAS_COND_AXIS_NAME_MAGICNO-8 "23068673.0000000000"
*MEAS_COND_AXIS_NAME_MAGICNO-9 "20971521.0000000000"
*MEAS_COND_AXIS_NAME_MAGICNO-10 "20971521.0000000000"
*MEAS_COND_AXIS_NAME_MAGICNO-11 "0.0000000000"
*MEAS_COND_AXIS_OFFSET-0 "0.0000000000"
*MEAS_COND_AXIS_OFFSET-1 "-"
*MEAS_COND_AXIS_OFFSET-2 "-"
*MEAS_COND_AXIS_OFFSET-3 "-"
*MEAS_COND_AXIS_OFFSET-4 "-"
*MEAS_COND_AXIS_OFFSET-5 "-"
*MEAS_COND_AXIS_OFFSET-6 "-"
*MEAS_COND_AXIS_OFFSET-7 "-"
*MEAS_COND_AXIS_OFFSET-8 "-"
*MEAS_COND_AXIS_OFFSET-9 "-"
*MEAS_COND_AXIS_OFFSET-10 "-"
*MEAS_COND_AXIS_OFFSET-11 "-"
*MEAS_COND_AXIS_POSITION-0 "10.0000000000"
*MEAS_COND_AXIS_POSITION-1 "0.0000000000"
*MEAS_COND_AXIS_POSITION-2 "3.0000000000"
*MEAS_COND_AXIS_POSITION-3 "2.5deg"
*MEAS_COND_AXIS_POSITION-4 "10.0mm"
*MEAS_COND_AXIS_POSITION-5 "0.625deg"
*MEAS_COND_AXIS_POSITION-6 "13.0mm"
*MEAS_COND_AXIS_POSITION-7 "2.5deg"
*MEAS_COND_AXIS_POSITION-8 "13.0mm"
*MEAS_COND_AXIS_POSITION-9 "K-beta(x1)"
*MEAS_COND_AXIS_POSITION-10 "None"
*MEAS_COND_AXIS_POSITION-11 "42.0000000000"
*MEAS_COND_AXIS_UNIT-0 "deg"
*MEAS_COND_AXIS_UNIT-1 ""
*MEAS_COND_AXIS_UNIT-2 ""
*MEAS_COND_AXIS_UNIT-3 ""
*MEAS_COND_AXIS_UNIT-4 ""
*MEAS_COND_AXIS_UNIT-5 ""
*MEAS_COND_AXIS_UNIT-6 ""
*MEAS_COND_AXIS_UNIT-7 ""
*MEAS_COND_AXIS_UNIT-8 ""
*MEAS_COND_AXIS_UNIT-9 ""
*MEAS_COND_AXIS_UNIT-10 ""
*MEAS_COND_AXIS_UNIT-11 "div"
*MEAS_COND_CORRECTION_SLIT_COUNTERMONO "None"
*MEAS_COND_CORRECTION_SLIT_DS "0.625deg"
*MEAS_COND_CORRECTION_SLIT_FILTER "None"
*MEAS_COND_CORRECTION_SLIT_IHS "10.0mm"
*MEAS_COND_CORRECTION_SLIT_RS "13.0mm"
*MEAS_COND_CORRECTION_SLIT_SOLLER_INC "2.5deg"
*MEAS_COND_CORRECTION_SLIT_SOLLER_REC "2.5deg"
*MEAS_COND_CORRECTION_SLIT_SS "13.0mm"
*MEAS_COND_COUNTER_CNTLOSS_CORR "0.0000000000"
*MEAS_COND_COUNTER_PHABASE "42.0000000000"
*MEAS_COND_COUNTER_PHAWINDOW "15.0000000000"
*MEAS_COND_COUNTER_PHA_UNIT "div"
*MEAS_COND_COUNTER_TAUDIFF "0.2500000000"
*MEAS_COND_COUNTER_TAUINT "0.7500000000"
*MEAS_COND_IRRADIATION_MODE "OFF"
*MEAS_COND_IRRADIATION_WIDTH ""
*MEAS_COND_OPT_ATTR " "
*MEAS_COND_OPT_NAME ""
*MEAS_COND_UNSYMMETRIC_MODE "OFF"
*MEAS_COND_XG_CURRENT "15.0000000000"
*MEAS_COND_XG_VOLTAGE "40.0000000000"
*MEAS_COND_XG_WAVE_TYPE "Ka"
*MEAS_DATA_COUNT "4251.0000000000"
*MEAS_SCAN_AXIS_X "Theta/2-Theta"
*MEAS_SCAN_AXIS_X_INTERNAL "TwoThetaTheta"
*MEAS_SCAN_END_TIME "04/16/19 13:49:30"
*MEAS_SCAN_MODE "CONTINUOUS"
*MEAS_SCAN_MONITOR "0"
*MEAS_SCAN_RESOLUTION_X "0.005"
*MEAS_SCAN_SPEED "10.000"
*MEAS_SCAN_SPEED_UNIT "deg/min"
*MEAS_SCAN_START "5.0000000000"
*MEAS_SCAN_START_TIME "04/16/19 13:40:14"
*MEAS_SCAN_STEP "0.0200000000"
*MEAS_SCAN_STOP "90.0000000000"
*MEAS_SCAN_UNIT_X "deg"
*MEAS_SCAN_UNIT_Y "counts"
*SLIT_SYSTEM "0"
*RAS_HEADER_END
*RAS_INT_START
5.000 392.000 1.000
5.060 316.000 1.000
5.120 363.000 1.000
5.180 339.000 1.000
5.240 312.000 1.000
5.300 344.000 1.000
5.360 333.000 1.000
5.420 295.000 1.000
5.480 286.000 1.000
5.540 276.000 1.000
5.600 255.000 1.000
5.660 266.000 1.000
5.720 258.000 1.000
5.780 254.000 1.000
5.840 240.000 1.000
5.900 256.000 1.000
5.960 229.000 1.000
6.020 265.000 1.000
6.080 246.000 1.000
6.140 208.000 1.000
6.200 218.000 1.000
6.260 218.000 1.000
6.320 208.000 1.000
6.380 231.000 1.000
6.440 216.000 1.000
6.500 224.000 1.000
6.560 198.000 1.000
6.620 210.000 1.000
6.680 183.000 1.000
6.740 220.000 1.000
6.800 209.000 1.000
6.860 185.000 1.000
6.920 186.000 1.000
6.980 186.000 1.000
7.040 186.000 1.000
7.100 191.000 1.000
7.160 202.000 1.000
7.220 167.000 1.000
7.280 182.000 1.000
7.340 169.000 1.000
7.400 172.000 1.000
7.460 168.000 1.000
7.520 180.000 1.000
7.580 165.000 1.000
7.640 191.000 1.000
7.700 156.000 1.000
7.760 167.000 1.000
7.820 176.000 1.000
7.880 171.000 1.000
7.940 164.000 1.000
8.000 147.000 1.000
8.060 162.000 1.000
8.120 168.000 1.000
8.180 159.000 1.000
8.240 154.000 1.000
8.300 155.000 1.000
8.360 156.000 1.000
8.420 140.000 1.000
8.480 165.000 1.000
8.540 159.000 1.000
8.600 164.000 1.000
8.660 152.000 1.000
8.720 147.000 1.000
8.780 145.000 1.000
8.840 154.000 1.000
8.900 139.000 1.000
8.960 154.000 1.000
9.020 153.000 1.000
9.080 157.000 1.000
9.140 153.000 1.000
9.200 152.000 1.000
9.260 148.000 1.000
9.320 158.000 1.000
9.380 140.000 1.000
9.440 147.000 1.000
9.500 143.000 1.000
9.560 132.000 1.000
9.620 144.000 1.000
9.680 139.000 1.000
9.740 126.000 1.000
9.800 144.000 1.000
9.860 139.000 1.000
9.920 138.000 1.000
9.980 131.000 1.000
10.040 156.000 1.000
10.100 146.000 1.000
10.160 156.000 1.000
10.220 131.000 1.000
10.280 162.000 1.000
10.340 144.000 1.000
10.400 142.000 1.000
10.460 131.000 1.000
10.520 140.000 1.000
10.580 137.000 1.000
10.640 132.000 1.000
10.700 140.000 1.000
10.760 131.000 1.000
10.820 162.000 1.000
10.880 138.000 1.000
10.940 122.000 1.000
11.000 130.000 1.000
11.060 152.000 1.000
11.120 150.000 1.000
11.180 152.000 1.000
11.240 119.000 1.000
11.300 131.000 1.000
11.360 138.000 1.000
11.420 153.000 1.000
11.480 150.000 1.000
11.540 125.000 1.000
11.600 135.000 1.000
11.660 133.000 1.000
11.720 137.000 1.000
11.780 134.000 1.000
11.840 137.000 1.000
11.900 137.000 1.000
11.960 127.000 1.000
12.020 147.000 1.000
12.080 142.000 1.000
12.140 132.000 1.000
12.200 142.000 1.000
12.260 133.000 1.000
12.320 135.000 1.000
12.380 118.000 1.000
12.440 133.000 1.000
12.500 129.000 1.000
12.560 136.000 1.000
12.620 122.000 1.000
12.680 119.000 1.000
12.740 141.000 1.000
12.800 134.000 1.000
12.860 118.000 1.000
12.920 135.000 1.000
12.980 133.000 1.000
13.040 152.000 1.000
13.100 139.000 1.000
13.160 134.000 1.000
13.220 122.000 1.000
13.280 119.000 1.000
13.340 147.000 1.000
13.400 139.000 1.000
13.460 129.000 1.000
13.520 134.000 1.000
13.580 132.000 1.000
13.640 136.000 1.000
13.700 126.000 1.000
13.760 135.000 1.000
13.820 135.000 1.000
13.880 122.000 1.000
13.940 142.000 1.000
14.000 135.000 1.000
14.060 144.000 1.000
14.120 131.000 1.000
14.180 151.000 1.000
14.240 138.000 1.000
14.300 118.000 1.000
14.360 143.000 1.000
14.420 124.000 1.000
14.480 129.000 1.000
14.540 131.000 1.000
14.600 118.000 1.000
14.660 120.000 1.000
14.720 149.000 1.000
14.780 139.000 1.000
14.840 140.000 1.000
14.900 134.000 1.000
14.960 126.000 1.000
15.020 116.000 1.000
15.080 137.000 1.000
15.140 136.000 1.000
15.200 120.000 1.000
15.260 131.000 1.000
15.320 128.000 1.000
15.380 120.000 1.000
15.440 121.000 1.000
15.500 112.000 1.000
15.560 107.000 1.000
15.620 120.000 1.000
15.680 125.000 1.000
15.740 110.000 1.000
15.800 108.000 1.000
15.860 118.000 1.000
15.920 115.000 1.000
15.980 105.000 1.000
16.040 125.000 1.000
16.100 114.000 1.000
16.160 117.000 1.000
16.220 129.000 1.000
16.280 112.000 1.000
16.340 90.000 1.000
16.400 117.000 1.000
16.460 114.000 1.000
16.520 104.000 1.000
16.580 110.000 1.000
16.640 101.000 1.000
16.700 114.000 1.000
16.760 109.000 1.000
16.820 108.000 1.000
16.880 101.000 1.000
16.940 111.000 1.000
17.000 113.000 1.000
17.060 110.000 1.000
17.120 115.000 1.000
17.180 114.000 1.000
17.240 121.000 1.000
17.300 108.000 1.000
17.360 110.000 1.000
17.420 100.000 1.000
17.480 94.000 1.000
17.540 105.000 1.000
17.600 120.000 1.000
17.660 106.000 1.000
17.720 114.000 1.000
17.780 109.000 1.000
17.840 108.000 1.000
17.900 82.000 1.000
17.960 107.000 1.000
18.020 115.000 1.000
18.080 118.000 1.000
18.140 105.000 1.000
18.200 82.000 1.000
18.260 96.000 1.000
18.320 100.000 1.000
18.380 91.000 1.000
18.440 99.000 1.000
18.500 102.000 1.000
18.560 101.000 1.000
18.620 91.000 1.000
18.680 100.000 1.000
18.740 99.000 1.000
18.800 95.000 1.000
18.860 94.000 1.000
18.920 98.000 1.000
18.980 97.000 1.000
19.040 100.000 1.000
19.100 94.000 1.000
19.160 82.000 1.000
19.220 91.000 1.000
19.280 102.000 1.000
19.340 104.000 1.000
19.400 108.000 1.000
19.460 91.000 1.000
19.520 86.000 1.000
19.580 93.000 1.000
19.640 102.000 1.000
19.700 103.000 1.000
19.760 105.000 1.000
19.820 95.000 1.000
19.880 88.000 1.000
19.940 92.000 1.000
20.000 90.000 1.000
20.060 97.000 1.000
20.120 107.000 1.000
20.180 102.000 1.000
20.240 98.000 1.000
20.300 92.000 1.000
20.360 93.000 1.000
20.420 86.000 1.000
20.480 93.000 1.000
20.540 90.000 1.000
20.600 93.000 1.000
20.660 104.000 1.000
20.720 103.000 1.000
20.780 87.000 1.000
20.840 100.000 1.000
20.900 91.000 1.000
20.960 83.000 1.000
21.020 86.000 1.000
21.080 103.000 1.000
21.140 91.000 1.000
21.200 77.000 1.000
21.260 90.000 1.000
21.320 96.000 1.000
21.380 74.000 1.000
21.440 99.000 1.000
21.500 96.000 1.000
21.560 86.000 1.000
21.620 91.000 1.000
21.680 84.000 1.000
21.740 78.000 1.000
21.800 85.000 1.000
21.860 85.000 1.000
21.920 93.000 1.000
21.980 88.000 1.000
22.040 101.000 1.000
22.100 80.000 1.000
22.160 95.000 1.000
22.220 89.000 1.000
22.280 83.000 1.000
22.340 93.000 1.000
22.400 100.000 1.000
22.460 85.000 1.000
22.520 86.000 1.000
22.580 88.000 1.000
22.640 81.000 1.000
22.700 82.000 1.000
22.760 98.000 1.000
22.820 88.000 1.000
22.880 90.000 1.000
22.940 109.000 1.000
23.000 96.000 1.000
23.060 101.000 1.000
23.120 96.000 1.000
23.180 111.000 1.000
23.240 96.000 1.000
23.300 99.000 1.000
23.360 98.000 1.000
23.420 104.000 1.000
23.480 97.000 1.000
23.540 100.000 1.000
23.600 99.000 1.000
23.660 102.000 1.000
23.720 108.000 1.000
23.780 100.000 1.000
23.840 101.000 1.000
23.900 110.000 1.000
23.960 105.000 1.000
24.020 122.000 1.000
24.080 125.000 1.000
24.140 128.000 1.000
24.200 112.000 1.000
24.260 103.000 1.000
24.320 109.000 1.000
24.380 128.000 1.000
24.440 128.000 1.000
24.500 125.000 1.000
24.560 107.000 1.000
24.620 120.000 1.000
24.680 131.000 1.000
24.740 122.000 1.000
24.800 137.000 1.000
24.860 135.000 1.000
24.920 143.000 1.000
24.980 143.000 1.000
25.040 138.000 1.000
25.100 122.000 1.000
25.160 149.000 1.000
25.220 155.000 1.000
25.280 139.000 1.000
25.340 159.000 1.000
25.400 147.000 1.000
25.460 137.000 1.000
25.520 150.000 1.000
25.580 155.000 1.000
25.640 152.000 1.000
25.700 149.000 1.000
25.760 152.000 1.000
25.820 156.000 1.000
25.880 149.000 1.000
25.940 139.000 1.000
26.000 166.000 1.000
26.060 161.000 1.000
26.120 156.000 1.000
26.180 151.000 1.000
26.240 142.000 1.000
26.300 165.000 1.000
26.360 148.000 1.000
26.420 169.000 1.000
26.480 175.000 1.000
26.540 178.000 1.000
26.600 169.000 1.000
26.660 192.000 1.000
26.720 218.000 1.000
26.780 217.000 1.000
26.840 257.000 1.000
26.900 258.000 1.000
26.960 309.000 1.000
27.020 331.000 1.000
27.080 444.000 1.000
27.140 562.000 1.000
27.200 705.000 1.000
27.260 1086.000 1.000
27.320 1498.000 1.000
27.380 2067.000 1.000
27.440 2385.000 1.000
27.500 2308.000 1.000
27.560 1942.000 1.000
27.620 1489.000 1.000
27.680 1071.000 1.000
27.740 742.000 1.000
27.800 569.000 1.000
27.860 411.000 1.000
27.920 347.000 1.000
27.980 322.000 1.000
28.040 264.000 1.000
28.100 244.000 1.000
28.160 212.000 1.000
28.220 181.000 1.000
28.280 171.000 1.000
28.340 177.000 1.000
28.400 150.000 1.000
28.460 147.000 1.000
28.520 149.000 1.000
28.580 138.000 1.000
28.640 134.000 1.000
28.700 121.000 1.000
28.760 124.000 1.000
28.820 135.000 1.000
28.880 116.000 1.000
28.940 126.000 1.000
29.000 121.000 1.000
29.060 109.000 1.000
29.120 108.000 1.000
29.180 110.000 1.000
29.240 108.000 1.000
29.300 113.000 1.000
29.360 104.000 1.000
29.420 99.000 1.000
29.480 101.000 1.000
29.540 101.000 1.000
29.600 111.000 1.000
29.660 89.000 1.000
29.720 98.000 1.000
29.780 93.000 1.000
29.840 88.000 1.000
29.900 77.000 1.000
29.960 85.000 1.000
30.020 90.000 1.000
30.080 87.000 1.000
30.140 90.000 1.000
30.200 91.000 1.000
30.260 88.000 1.000
30.320 83.000 1.000
30.380 91.000 1.000
30.440 88.000 1.000
30.500 80.000 1.000
30.560 88.000 1.000
30.620 80.000 1.000
30.680 83.000 1.000
30.740 81.000 1.000
30.800 83.000 1.000
30.860 78.000 1.000
30.920 77.000 1.000
30.980 84.000 1.000
31.040 82.000 1.000
31.100 85.000 1.000
31.160 79.000 1.000
31.220 83.000 1.000
31.280 79.000 1.000
31.340 82.000 1.000
31.400 74.000 1.000
31.460 77.000 1.000
31.520 77.000 1.000
31.580 83.000 1.000
31.640 68.000 1.000
31.700 73.000 1.000
31.760 80.000 1.000
31.820 72.000 1.000
31.880 73.000 1.000
31.940 78.000 1.000
32.000 69.000 1.000
32.060 66.000 1.000
32.120 59.000 1.000
32.180 66.000 1.000
32.240 66.000 1.000
32.300 68.000 1.000
32.360 65.000 1.000
32.420 69.000 1.000
32.480 65.000 1.000
32.540 73.000 1.000
32.600 72.000 1.000
32.660 61.000 1.000
32.720 73.000 1.000
32.780 68.000 1.000
32.840 59.000 1.000
32.900 67.000 1.000
32.960 70.000 1.000
33.020 64.000 1.000
33.080 66.000 1.000
33.140 60.000 1.000
33.200 60.000 1.000
33.260 58.000 1.000
33.320 78.000 1.000
33.380 73.000 1.000
33.440 61.000 1.000
33.500 74.000 1.000
33.560 59.000 1.000
33.620 60.000 1.000
33.680 69.000 1.000
33.740 65.000 1.000
33.800 58.000 1.000
33.860 62.000 1.000
33.920 58.000 1.000
33.980 70.000 1.000
34.040 61.000 1.000
34.100 62.000 1.000
34.160 60.000 1.000
34.220 70.000 1.000
34.280 57.000 1.000
34.340 70.000 1.000
34.400 69.000 1.000
34.460 59.000 1.000
34.520 64.000 1.000
34.580 69.000 1.000
34.640 67.000 1.000
34.700 71.000 1.000
34.760 61.000 1.000
34.820 72.000 1.000
34.880 74.000 1.000
34.940 70.000 1.000
35.000 80.000 1.000
35.060 68.000 1.000
35.120 70.000 1.000
35.180 79.000 1.000
35.240 82.000 1.000
35.300 85.000 1.000
35.360 83.000 1.000
35.420 100.000 1.000
35.480 98.000 1.000
35.540 95.000 1.000
35.600 121.000 1.000
35.660 128.000 1.000
35.720 147.000 1.000
35.780 163.000 1.000
35.840 211.000 1.000
35.900 267.000 1.000
35.960 399.000 1.000
36.020 625.000 1.000
36.080 1053.000 1.000
36.140 1303.000 1.000
36.200 1201.000 1.000
36.260 886.000 1.000
36.320 534.000 1.000
36.380 341.000 1.000
36.440 267.000 1.000
36.500 182.000 1.000
36.560 150.000 1.000
36.620 143.000 1.000
36.680 129.000 1.000
36.740 114.000 1.000
36.800 107.000 1.000
36.860 99.000 1.000
36.920 93.000 1.000
36.980 107.000 1.000
37.040 82.000 1.000
37.100 83.000 1.000
37.160 90.000 1.000
37.220 78.000 1.000
37.280 91.000 1.000
37.340 65.000 1.000
37.400 88.000 1.000
37.460 80.000 1.000
37.520 79.000 1.000
37.580 81.000 1.000
37.640 76.000 1.000
37.700 66.000 1.000
37.760 78.000 1.000
37.820 79.000 1.000
37.880 81.000 1.000
37.940 70.000 1.000
38.000 66.000 1.000
38.060 78.000 1.000
38.120 64.000 1.000
38.180 75.000 1.000
38.240 67.000 1.000
38.300 71.000 1.000
38.360 66.000 1.000
38.420 60.000 1.000
38.480 72.000 1.000
38.540 63.000 1.000
38.600 77.000 1.000
38.660 75.000 1.000
38.720 75.000 1.000
38.780 82.000 1.000
38.840 81.000 1.000
38.900 72.000 1.000
38.960 101.000 1.000
39.020 118.000 1.000
39.080 146.000 1.000
39.140 159.000 1.000
39.200 174.000 1.000
39.260 175.000 1.000
39.320 138.000 1.000
39.380 130.000 1.000
39.440 102.000 1.000
39.500 89.000 1.000
39.560 76.000 1.000
39.620 80.000 1.000
39.680 67.000 1.000
39.740 65.000 1.000
39.800 79.000 1.000
39.860 71.000 1.000
39.920 59.000 1.000
39.980 63.000 1.000
40.040 71.000 1.000
40.100 72.000 1.000
40.160 56.000 1.000
40.220 60.000 1.000
40.280 53.000 1.000
40.340 72.000 1.000
40.400 63.000 1.000
40.460 60.000 1.000
40.520 68.000 1.000
40.580 69.000 1.000
40.640 76.000 1.000
40.700 89.000 1.000
40.760 68.000 1.000
40.820 94.000 1.000
40.880 92.000 1.000
40.940 106.000 1.000
41.000 146.000 1.000
41.060 153.000 1.000
41.120 259.000 1.000
41.180 421.000 1.000
41.240 592.000 1.000
41.300 650.000 1.000
41.360 564.000 1.000
41.420 436.000 1.000
41.480 285.000 1.000
41.540 206.000 1.000
41.600 145.000 1.000
41.660 116.000 1.000
41.720 96.000 1.000
41.780 81.000 1.000
41.840 75.000 1.000
41.900 65.000 1.000
41.960 70.000 1.000
42.020 71.000 1.000
42.080 65.000 1.000
42.140 63.000 1.000
42.200 60.000 1.000
42.260 50.000 1.000
42.320 54.000 1.000
42.380 60.000 1.000
42.440 55.000 1.000
42.500 50.000 1.000
42.560 59.000 1.000
42.620 60.000 1.000
42.680 52.000 1.000
42.740 46.000 1.000
42.800 55.000 1.000
42.860 49.000 1.000
42.920 53.000 1.000
42.980 57.000 1.000
43.040 54.000 1.000
43.100 58.000 1.000
43.160 49.000 1.000
43.220 57.000 1.000
43.280 58.000 1.000
43.340 54.000 1.000
43.400 59.000 1.000
43.460 59.000 1.000
43.520 65.000 1.000
43.580 77.000 1.000
43.640 85.000 1.000
43.700 88.000 1.000
43.760 90.000 1.000
43.820 118.000 1.000
43.880 144.000 1.000
43.940 171.000 1.000
44.000 214.000 1.000
44.060 185.000 1.000
44.120 204.000 1.000
44.180 179.000 1.000
44.240 130.000 1.000
44.300 107.000 1.000
44.360 102.000 1.000
44.420 80.000 1.000
44.480 78.000 1.000
44.540 60.000 1.000
44.600 62.000 1.000
44.660 65.000 1.000
44.720 55.000 1.000
44.780 63.000 1.000
44.840 55.000 1.000
44.900 49.000 1.000
44.960 57.000 1.000
45.020 58.000 1.000
45.080 46.000 1.000
45.140 58.000 1.000
45.200 43.000 1.000
45.260 40.000 1.000
45.320 53.000 1.000
45.380 49.000 1.000
45.440 53.000 1.000
45.500 53.000 1.000
45.560 49.000 1.000
45.620 41.000 1.000
45.680 41.000 1.000
45.740 49.000 1.000
45.800 41.000 1.000
45.860 54.000 1.000
45.920 44.000 1.000
45.980 45.000 1.000
46.040 47.000 1.000
46.100 40.000 1.000
46.160 48.000 1.000
46.220 39.000 1.000
46.280 46.000 1.000
46.340 38.000 1.000
46.400 50.000 1.000
46.460 50.000 1.000
46.520 43.000 1.000
46.580 51.000 1.000
46.640 45.000 1.000
46.700 52.000 1.000
46.760 38.000 1.000
46.820 42.000 1.000
46.880 53.000 1.000
46.940 41.000 1.000
47.000 52.000 1.000
47.060 50.000 1.000
47.120 45.000 1.000
47.180 43.000 1.000
47.240 41.000 1.000
47.300 49.000 1.000
47.360 46.000 1.000
47.420 50.000 1.000
47.480 58.000 1.000
47.540 58.000 1.000
47.600 57.000 1.000
47.660 45.000 1.000
47.720 50.000 1.000
47.780 52.000 1.000
47.840 56.000 1.000
47.900 56.000 1.000
47.960 71.000 1.000
48.020 62.000 1.000
48.080 53.000 1.000
48.140 56.000 1.000
48.200 48.000 1.000
48.260 59.000 1.000
48.320 47.000 1.000
48.380 50.000 1.000
48.440 50.000 1.000
48.500 52.000 1.000
48.560 55.000 1.000
48.620 53.000 1.000
48.680 55.000 1.000
48.740 35.000 1.000
48.800 49.000 1.000
48.860 51.000 1.000
48.920 39.000 1.000
48.980 49.000 1.000
49.040 52.000 1.000
49.100 52.000 1.000
49.160 65.000 1.000
49.220 47.000 1.000
49.280 52.000 1.000
49.340 40.000 1.000
49.400 42.000 1.000
49.460 46.000 1.000
49.520 63.000 1.000
49.580 43.000 1.000
49.640 52.000 1.000
49.700 62.000 1.000
49.760 48.000 1.000
49.820 39.000 1.000
49.880 40.000 1.000
49.940 42.000 1.000
50.000 45.000 1.000
50.060 41.000 1.000
50.120 46.000 1.000
50.180 49.000 1.000
50.240 45.000 1.000
50.300 38.000 1.000
50.360 48.000 1.000
50.420 51.000 1.000
50.480 44.000 1.000
50.540 39.000 1.000
50.600 35.000 1.000
50.660 36.000 1.000
50.720 47.000 1.000
50.780 43.000 1.000
50.840 43.000 1.000
50.900 36.000 1.000
50.960 46.000 1.000
51.020 47.000 1.000
51.080 41.000 1.000
51.140 38.000 1.000
51.200 42.000 1.000
51.260 37.000 1.000
51.320 38.000 1.000
51.380 45.000 1.000
51.440 39.000 1.000
51.500 40.000 1.000
51.560 47.000 1.000
51.620 41.000 1.000
51.680 49.000 1.000
51.740 42.000 1.000
51.800 41.000 1.000
51.860 46.000 1.000
51.920 45.000 1.000
51.980 49.000 1.000
52.040 49.000 1.000
52.100 49.000 1.000
52.160 53.000 1.000
52.220 57.000 1.000
52.280 48.000 1.000
52.340 54.000 1.000
52.400 51.000 1.000
52.460 52.000 1.000
52.520 55.000 1.000
52.580 48.000 1.000
52.640 56.000 1.000
52.700 61.000 1.000
52.760 74.000 1.000
52.820 55.000 1.000
52.880 64.000 1.000
52.940 73.000 1.000
53.000 79.000 1.000
53.060 62.000 1.000
53.120 66.000 1.000
53.180 70.000 1.000
53.240 83.000 1.000
53.300 74.000 1.000
53.360 83.000 1.000
53.420 87.000 1.000
53.480 109.000 1.000
53.540 91.000 1.000
53.600 97.000 1.000
53.660 98.000 1.000
53.720 114.000 1.000
53.780 160.000 1.000
53.840 158.000 1.000
53.900 179.000 1.000
53.960 234.000 1.000
54.020 317.000 1.000
54.080 369.000 1.000
54.140 529.000 1.000
54.200 754.000 1.000
54.260 1041.000 1.000
54.320 1181.000 1.000
54.380 1198.000 1.000
54.440 1080.000 1.000
54.500 839.000 1.000
54.560 700.000 1.000
54.620 455.000 1.000
54.680 378.000 1.000
54.740 278.000 1.000
54.800 214.000 1.000
54.860 186.000 1.000
54.920 145.000 1.000
54.980 141.000 1.000
55.040 133.000 1.000
55.100 134.000 1.000
55.160 110.000 1.000
55.220 91.000 1.000
55.280 107.000 1.000
55.340 103.000 1.000
55.400 93.000 1.000
55.460 96.000 1.000
55.520 100.000 1.000
55.580 73.000 1.000
55.640 80.000 1.000
55.700 80.000 1.000
55.760 72.000 1.000
55.820 89.000 1.000
55.880 101.000 1.000
55.940 79.000 1.000
56.000 85.000 1.000
56.060 90.000 1.000
56.120 108.000 1.000
56.180 107.000 1.000
56.240 119.000 1.000
56.300 152.000 1.000
56.360 182.000 1.000
56.420 247.000 1.000
56.480 311.000 1.000
56.540 365.000 1.000
56.600 384.000 1.000
56.660 381.000 1.000
56.720 313.000 1.000
56.780 271.000 1.000
56.840 213.000 1.000
56.900 151.000 1.000
56.960 138.000 1.000
57.020 100.000 1.000
57.080 85.000 1.000
57.140 85.000 1.000
57.200 79.000 1.000
57.260 62.000 1.000
57.320 76.000 1.000
57.380 70.000 1.000
57.440 65.000 1.000
57.500 66.000 1.000
57.560 55.000 1.000
57.620 64.000 1.000
57.680 65.000 1.000
57.740 52.000 1.000
57.800 51.000 1.000
57.860 56.000 1.000
57.920 59.000 1.000
57.980 50.000 1.000
58.040 61.000 1.000
58.100 59.000 1.000
58.160 44.000 1.000
58.220 52.000 1.000
58.280 47.000 1.000
58.340 50.000 1.000
58.400 44.000 1.000
58.460 34.000 1.000
58.520 52.000 1.000
58.580 44.000 1.000
58.640 52.000 1.000
58.700 48.000 1.000
58.760 39.000 1.000
58.820 52.000 1.000
58.880 36.000 1.000
58.940 54.000 1.000
59.000 40.000 1.000
59.060 46.000 1.000
59.120 30.000 1.000
59.180 44.000 1.000
59.240 43.000 1.000
59.300 44.000 1.000
59.360 44.000 1.000
59.420 38.000 1.000
59.480 41.000 1.000
59.540 48.000 1.000
59.600 43.000 1.000
59.660 38.000 1.000
59.720 52.000 1.000
59.780 44.000 1.000
59.840 35.000 1.000
59.900 33.000 1.000
59.960 41.000 1.000
60.020 46.000 1.000
60.080 41.000 1.000
60.140 35.000 1.000
60.200 46.000 1.000
60.260 36.000 1.000
60.320 40.000 1.000
60.380 38.000 1.000
60.440 37.000 1.000
60.500 45.000 1.000
60.560 35.000 1.000
60.620 39.000 1.000
60.680 32.000 1.000
60.740 44.000 1.000
60.800 30.000 1.000
60.860 37.000 1.000
60.920 37.000 1.000
60.980 42.000 1.000
61.040 38.000 1.000
61.100 43.000 1.000
61.160 38.000 1.000
61.220 44.000 1.000
61.280 47.000 1.000
61.340 43.000 1.000
61.400 38.000 1.000
61.460 46.000 1.000
61.520 47.000 1.000
61.580 41.000 1.000
61.640 46.000 1.000
61.700 46.000 1.000
61.760 44.000 1.000
61.820 56.000 1.000
61.880 41.000 1.000
61.940 45.000 1.000
62.000 49.000 1.000
62.060 48.000 1.000
62.120 41.000 1.000
62.180 56.000 1.000
62.240 42.000 1.000
62.300 49.000 1.000
62.360 48.000 1.000
62.420 53.000 1.000
62.480 57.000 1.000
62.540 65.000 1.000
62.600 76.000 1.000
62.660 78.000 1.000
62.720 110.000 1.000
62.780 182.000 1.000
62.840 292.000 1.000
62.900 251.000 1.000
62.960 187.000 1.000
63.020 222.000 1.000
63.080 166.000 1.000
63.140 103.000 1.000
63.200 80.000 1.000
63.260 72.000 1.000
63.320 68.000 1.000
63.380 73.000 1.000
63.440 64.000 1.000
63.500 63.000 1.000
63.560 80.000 1.000
63.620 87.000 1.000
63.680 91.000 1.000
63.740 87.000 1.000
63.800 122.000 1.000
63.860 131.000 1.000
63.920 164.000 1.000
63.980 169.000 1.000
64.040 152.000 1.000
64.100 138.000 1.000
64.160 152.000 1.000
64.220 125.000 1.000
64.280 107.000 1.000
64.340 91.000 1.000
64.400 68.000 1.000
64.460 79.000 1.000
64.520 58.000 1.000
64.580 64.000 1.000
64.640 66.000 1.000
64.700 62.000 1.000
64.760 46.000 1.000
64.820 56.000 1.000
64.880 49.000 1.000
64.940 50.000 1.000
65.000 58.000 1.000
65.060 46.000 1.000
65.120 44.000 1.000
65.180 46.000 1.000
65.240 42.000 1.000
65.300 45.000 1.000
65.360 46.000 1.000
65.420 55.000 1.000
65.480 54.000 1.000
65.540 49.000 1.000
65.600 55.000 1.000
65.660 45.000 1.000
65.720 40.000 1.000
65.780 46.000 1.000
65.840 41.000 1.000
65.900 40.000 1.000
65.960 41.000 1.000
66.020 41.000 1.000
66.080 39.000 1.000
66.140 39.000 1.000
66.200 44.000 1.000
66.260 30.000 1.000
66.320 35.000 1.000
66.380 48.000 1.000
66.440 46.000 1.000
66.500 36.000 1.000
66.560 47.000 1.000
66.620 41.000 1.000
66.680 47.000 1.000
66.740 43.000 1.000
66.800 38.000 1.000
66.860 42.000 1.000
66.920 46.000 1.000
66.980 41.000 1.000
67.040 39.000 1.000
67.100 41.000 1.000
67.160 36.000 1.000
67.220 39.000 1.000
67.280 41.000 1.000
67.340 45.000 1.000
67.400 46.000 1.000
67.460 40.000 1.000
67.520 44.000 1.000
67.580 42.000 1.000
67.640 49.000 1.000
67.700 46.000 1.000
67.760 46.000 1.000
67.820 41.000 1.000
67.880 51.000 1.000
67.940 50.000 1.000
68.000 45.000 1.000
68.060 63.000 1.000
68.120 59.000 1.000
68.180 55.000 1.000
68.240 59.000 1.000
68.300 66.000 1.000
68.360 76.000 1.000
68.420 83.000 1.000
68.480 75.000 1.000
68.540 102.000 1.000
68.600 116.000 1.000
68.660 142.000 1.000
68.720 191.000 1.000
68.780 227.000 1.000
68.840 279.000 1.000
68.900 327.000 1.000
68.960 342.000 1.000
69.020 352.000 1.000
69.080 328.000 1.000
69.140 281.000 1.000
69.200 251.000 1.000
69.260 197.000 1.000
69.320 160.000 1.000
69.380 143.000 1.000
69.440 124.000 1.000
69.500 125.000 1.000
69.560 111.000 1.000
69.620 108.000 1.000
69.680 152.000 1.000
69.740 164.000 1.000
69.800 247.000 1.000
69.860 285.000 1.000
69.920 230.000 1.000
69.980 200.000 1.000
70.040 202.000 1.000
70.100 171.000 1.000
70.160 149.000 1.000
70.220 85.000 1.000
70.280 82.000 1.000
70.340 67.000 1.000
70.400 63.000 1.000
70.460 61.000 1.000
70.520 45.000 1.000
70.580 37.000 1.000
70.640 42.000 1.000
70.700 51.000 1.000
70.760 44.000 1.000
70.820 43.000 1.000
70.880 42.000 1.000
70.940 40.000 1.000
71.000 45.000 1.000
71.060 44.000 1.000
71.120 42.000 1.000
71.180 42.000 1.000
71.240 34.000 1.000
71.300 43.000 1.000
71.360 37.000 1.000
71.420 36.000 1.000
71.480 31.000 1.000
71.540 37.000 1.000
71.600 30.000 1.000
71.660 35.000 1.000
71.720 44.000 1.000
71.780 36.000 1.000
71.840 42.000 1.000
71.900 38.000 1.000
71.960 37.000 1.000
72.020 42.000 1.000
72.080 36.000 1.000
72.140 41.000 1.000
72.200 43.000 1.000
72.260 45.000 1.000
72.320 62.000 1.000
72.380 49.000 1.000
72.440 47.000 1.000
72.500 51.000 1.000
72.560 48.000 1.000
72.620 38.000 1.000
72.680 46.000 1.000
72.740 34.000 1.000
72.800 33.000 1.000
72.860 40.000 1.000
72.920 45.000 1.000
72.980 37.000 1.000
73.040 36.000 1.000
73.100 41.000 1.000
73.160 31.000 1.000
73.220 39.000 1.000
73.280 35.000 1.000
73.340 32.000 1.000
73.400 32.000 1.000
73.460 30.000 1.000
73.520 33.000 1.000
73.580 35.000 1.000
73.640 30.000 1.000
73.700 29.000 1.000
73.760 32.000 1.000
73.820 39.000 1.000
73.880 34.000 1.000
73.940 35.000 1.000
74.000 35.000 1.000
74.060 36.000 1.000
74.120 40.000 1.000
74.180 34.000 1.000
74.240 41.000 1.000
74.300 32.000 1.000
74.360 34.000 1.000
74.420 41.000 1.000
74.480 34.000 1.000
74.540 37.000 1.000
74.600 35.000 1.000
74.660 39.000 1.000
74.720 39.000 1.000
74.780 34.000 1.000
74.840 30.000 1.000
74.900 27.000 1.000
74.960 30.000 1.000
75.020 37.000 1.000
75.080 31.000 1.000
75.140 29.000 1.000
75.200 34.000 1.000
75.260 31.000 1.000
75.320 32.000 1.000
75.380 37.000 1.000
75.440 32.000 1.000
75.500 30.000 1.000
75.560 43.000 1.000
75.620 35.000 1.000
75.680 27.000 1.000
75.740 37.000 1.000
75.800 31.000 1.000
75.860 37.000 1.000
75.920 34.000 1.000
75.980 37.000 1.000
76.040 37.000 1.000
76.100 31.000 1.000
76.160 40.000 1.000
76.220 41.000 1.000
76.280 41.000 1.000
76.340 46.000 1.000
76.400 49.000 1.000
76.460 54.000 1.000
76.520 65.000 1.000
76.580 82.000 1.000
76.640 70.000 1.000
76.700 61.000 1.000
76.760 54.000 1.000
76.820 58.000 1.000
76.880 46.000 1.000
76.940 44.000 1.000
77.000 30.000 1.000
77.060 39.000 1.000
77.120 40.000 1.000
77.180 38.000 1.000
77.240 37.000 1.000
77.300 32.000 1.000
77.360 27.000 1.000
77.420 30.000 1.000
77.480 24.000 1.000
77.540 29.000 1.000
77.600 31.000 1.000
77.660 32.000 1.000
77.720 35.000 1.000
77.780 28.000 1.000
77.840 27.000 1.000
77.900 29.000 1.000
77.960 22.000 1.000
78.020 27.000 1.000
78.080 22.000 1.000
78.140 27.000 1.000
78.200 27.000 1.000
78.260 28.000 1.000
78.320 24.000 1.000
78.380 27.000 1.000
78.440 30.000 1.000
78.500 24.000 1.000
78.560 33.000 1.000
78.620 23.000 1.000
78.680 24.000 1.000
78.740 28.000 1.000
78.800 21.000 1.000
78.860 36.000 1.000
78.920 21.000 1.000
78.980 33.000 1.000
79.040 30.000 1.000
79.100 21.000 1.000
79.160 34.000 1.000
79.220 28.000 1.000
79.280 30.000 1.000
79.340 25.000 1.000
79.400 24.000 1.000
79.460 33.000 1.000
79.520 24.000 1.000
79.580 33.000 1.000
79.640 35.000 1.000
79.700 38.000 1.000
79.760 48.000 1.000
79.820 46.000 1.000
79.880 48.000 1.000
79.940 53.000 1.000
80.000 40.000 1.000
80.060 44.000 1.000
80.120 40.000 1.000
80.180 34.000 1.000
80.240 42.000 1.000
80.300 32.000 1.000
80.360 27.000 1.000
80.420 29.000 1.000
80.480 38.000 1.000
80.540 26.000 1.000
80.600 27.000 1.000
80.660 36.000 1.000
80.720 30.000 1.000
80.780 29.000 1.000
80.840 24.000 1.000
80.900 27.000 1.000
80.960 24.000 1.000
81.020 30.000 1.000
81.080 34.000 1.000
81.140 29.000 1.000
81.200 36.000 1.000
81.260 24.000 1.000
81.320 31.000 1.000
81.380 31.000 1.000
81.440 28.000 1.000
81.500 34.000 1.000
81.560 30.000 1.000
81.620 34.000 1.000
81.680 35.000 1.000
81.740 38.000 1.000
81.800 39.000 1.000
81.860 41.000 1.000
81.920 47.000 1.000
81.980 49.000 1.000
82.040 63.000 1.000
82.100 78.000 1.000
82.160 83.000 1.000
82.220 78.000 1.000
82.280 92.000 1.000
82.340 88.000 1.000
82.400 85.000 1.000
82.460 72.000 1.000
82.520 63.000 1.000
82.580 66.000 1.000
82.640 53.000 1.000
82.700 47.000 1.000
82.760 53.000 1.000
82.820 43.000 1.000
82.880 38.000 1.000
82.940 38.000 1.000
83.000 35.000 1.000
83.060 40.000 1.000
83.120 32.000 1.000
83.180 31.000 1.000
83.240 31.000 1.000
83.300 42.000 1.000
83.360 39.000 1.000
83.420 40.000 1.000
83.480 36.000 1.000
83.540 35.000 1.000
83.600 33.000 1.000
83.660 39.000 1.000
83.720 37.000 1.000
83.780 43.000 1.000
83.840 45.000 1.000
83.900 62.000 1.000
83.960 53.000 1.000
84.020 56.000 1.000
84.080 65.000 1.000
84.140 59.000 1.000
84.200 62.000 1.000
84.260 64.000 1.000
84.320 49.000 1.000
84.380 40.000 1.000
84.440 59.000 1.000
84.500 48.000 1.000
84.560 45.000 1.000
84.620 37.000 1.000
84.680 43.000 1.000
84.740 38.000 1.000
84.800 35.000 1.000
84.860 40.000 1.000
84.920 35.000 1.000
84.980 32.000 1.000
85.040 36.000 1.000
85.100 38.000 1.000
85.160 29.000 1.000
85.220 33.000 1.000
85.280 33.000 1.000
85.340 24.000 1.000
85.400 25.000 1.000
85.460 29.000 1.000
85.520 21.000 1.000
85.580 33.000 1.000
85.640 19.000 1.000
85.700 27.000 1.000
85.760 22.000 1.000
85.820 29.000 1.000
85.880 28.000 1.000
85.940 30.000 1.000
86.000 29.000 1.000
86.060 27.000 1.000
86.120 26.000 1.000
86.180 25.000 1.000
86.240 32.000 1.000
86.300 30.000 1.000
86.360 30.000 1.000
86.420 26.000 1.000
86.480 35.000 1.000
86.540 26.000 1.000
86.600 27.000 1.000
86.660 30.000 1.000
86.720 23.000 1.000
86.780 35.000 1.000
86.840 36.000 1.000
86.900 40.000 1.000
86.960 30.000 1.000
87.020 30.000 1.000
87.080 38.000 1.000
87.140 36.000 1.000
87.200 45.000 1.000
87.260 38.000 1.000
87.320 48.000 1.000
87.380 41.000 1.000
87.440 39.000 1.000
87.500 37.000 1.000
87.560 38.000 1.000
87.620 28.000 1.000
87.680 32.000 1.000
87.740 34.000 1.000
87.800 28.000 1.000
87.860 36.000 1.000
87.920 26.000 1.000
87.980 35.000 1.000
88.040 32.000 1.000
88.100 26.000 1.000
88.160 28.000 1.000
88.220 30.000 1.000
88.280 29.000 1.000
88.340 24.000 1.000
88.400 31.000 1.000
88.460 26.000 1.000
88.520 41.000 1.000
88.580 39.000 1.000
88.640 28.000 1.000
88.700 32.000 1.000
88.760 34.000 1.000
88.820 39.000 1.000
88.880 36.000 1.000
88.940 37.000 1.000
89.000 45.000 1.000
89.060 36.000 1.000
89.120 50.000 1.000
89.180 49.000 1.000
89.240 57.000 1.000
89.300 62.000 1.000
89.360 95.000 1.000
89.420 124.000 1.000
89.480 150.000 1.000
89.540 137.000 1.000
89.600 139.000 1.000
89.660 127.000 1.000
89.720 110.000 1.000
89.780 100.000 1.000
89.840 97.000 1.000
89.900 84.000 1.000
89.960 81.000 1.000
90.000 81.000 1.000
*RAS_INT_END
*RAS_DATA_END