File: ras_to_csv_convert_plot/example/ras/TiO2-3-3h-2.ras
*RAS_DATA_START
*RAS_HEADER_START
*CORR_POS_DB_NAME "correction_file_060219"
*CORR_POS_GONIO_RADIUS ""
*CORR_POS_NODE_INDEX01 ""
*CORR_POS_NODE_INDEX02 ""
*CORR_POS_NODE_INDEX03 ""
*CORR_POS_NODE_INDEX04 ""
*CORR_POS_NODE_INDEX05 ""
*CORR_POS_NODE_INDEX06 ""
*CORR_POS_NODE_INDEX07 ""
*CORR_POS_NODE_INDEX08 ""
*CORR_POS_NODE_INDEX09 ""
*CORR_POS_NODE_INDEX10 ""
*CORR_POS_NODE_INDEX11 ""
*CORR_POS_NODE_LABEL01 "Si(111)"
*CORR_POS_NODE_LABEL02 "Si(220)"
*CORR_POS_NODE_LABEL03 "Si(311)"
*CORR_POS_NODE_LABEL04 "Si(400)"
*CORR_POS_NODE_LABEL05 "Si(331)"
*CORR_POS_NODE_LABEL06 "Si(422)"
*CORR_POS_NODE_LABEL07 "Si(511)"
*CORR_POS_NODE_LABEL08 "Si(440)"
*CORR_POS_NODE_LABEL09 "Si(531)"
*CORR_POS_NODE_LABEL10 "Si(620)"
*CORR_POS_NODE_LABEL11 "Si(533)"
*CORR_POS_NODE_POS_CALC01 "28.4137"
*CORR_POS_NODE_POS_CALC02 "47.2707"
*CORR_POS_NODE_POS_CALC03 "56.0883"
*CORR_POS_NODE_POS_CALC04 "69.0934"
*CORR_POS_NODE_POS_CALC05 "76.3385"
*CORR_POS_NODE_POS_CALC06 "87.9915"
*CORR_POS_NODE_POS_CALC07 "94.9137"
*CORR_POS_NODE_POS_CALC08 "106.67"
*CORR_POS_NODE_POS_CALC09 "114.054"
*CORR_POS_NODE_POS_CALC10 "127.508"
*CORR_POS_NODE_POS_CALC11 "136.858"
*CORR_POS_NODE_POS_MEAS01 "28.4636"
*CORR_POS_NODE_POS_MEAS02 "47.3217"
*CORR_POS_NODE_POS_MEAS03 "56.1422"
*CORR_POS_NODE_POS_MEAS04 "69.1431"
*CORR_POS_NODE_POS_MEAS05 "76.3906"
*CORR_POS_NODE_POS_MEAS06 "88.0416"
*CORR_POS_NODE_POS_MEAS07 "94.9694"
*CORR_POS_NODE_POS_MEAS08 "106.719"
*CORR_POS_NODE_POS_MEAS09 "114.106"
*CORR_POS_NODE_POS_MEAS10 "127.554"
*CORR_POS_NODE_POS_MEAS11 "136.911"
*CORR_POS_OPT_ATTR "集中法"
*CORR_POS_PARAM_MU ""
*CORR_POS_PARAM_PL ""
*CORR_POS_SEMODEL_TYPE "0"
*CORR_POS_STANDARD_TYPE ""
*CORR_POS_VALUE_ANALYZER "None"
*CORR_POS_VALUE_CMONO "None"
*CORR_POS_VALUE_IMONO "None"
*CORR_POS_VALUE_IS "0.625deg"
*CORR_POS_VALUE_ISL "10.0mm"
*CORR_POS_VALUE_ISOLLER "2.5deg"
*CORR_POS_VALUE_RS1 "13.0mm"
*CORR_POS_VALUE_RS2 "13.0mm"
*CORR_POS_VALUE_RSOLLER "2.5deg"
*CORR_POS_XG_FOCUS_L ""
*CORR_POS_XG_WAVE_TYPE ""
*CORR_POS_XG_WAVE_VALUE ""
*DISP_FMT_X "%.2f"
*DISP_FMT_Y "%.0f"
*DISP_FULLSCALE "15830.0000000000"
*DISP_LINE_COLOR "255.0000000000"
*DISP_LINE_STYLE "0.0000000000"
*DISP_LINE_WIDTH "0.2500000000"
*DISP_NOTE "Collected Data-3"
*DISP_OFFSET_Y "0.0000000000"
*DISP_PEAKSEARCH_UNIT_Y "cps"
*DISP_RANGE_BOTTOM "0.0000000000"
*DISP_RANGE_LEFT "5.0000000000"
*DISP_RANGE_LOGCUTOFF "0.0100000000"
*DISP_RANGE_RIGHT "90.0000000000"
*DISP_RANGE_TOP "15830.0000000000"
*DISP_SCALE_MODE_Y "0.0000000000"
*DISP_TAB_NAME "Theta/2-Theta"
*DISP_TITLE_Y "Intensity"
*DISP_UNIT_Y "cps"
*DISP_WINDOW_NAME "MSG_MACROENGINE"
*FILE_COMMENT " "
*FILE_MD5 ""
*FILE_MEMO " "
*FILE_OPERATOR "SDU_RIGAKU"
*FILE_SAMPLE "TiO2-3-3h-2"
*FILE_TYPE "RAS_RAW"
*FILE_USERGROUP "System User"
*FILE_VERSION "1.0000000000"
*HW_ATTACHMENT_ID "ATT1031"
*HW_ATTACHMENT_NAME "6サンプルチェンジャ|ASC-6"
*HW_COUNTER_ID-0 "CUT0025"
*HW_COUNTER_ID-1 "CUT0020"
*HW_COUNTER_ID-2 "CUT0020"
*HW_COUNTER_ID-3 "CMC0021"
*HW_COUNTER_NAME-0 "D/teX Ultra|D/teX Ultra"
*HW_COUNTER_NAME-1 "None|None"
*HW_COUNTER_NAME-2 "None|None"
*HW_COUNTER_NAME-3 "検出器モノクロメータ|Detector monochromator"
*HW_COUNTER_SELECT_NAME "D/teX Ultra|D/teX Ultra"
*HW_GONIOMETER_ID "GON0070"
*HW_GONIOMETER_NAME "MiniFlex 300/600|MiniFlex 300/600"
*HW_GONIOMETER_RADIUS-0 "79.0"
*HW_GONIOMETER_RADIUS-1 "91.5"
*HW_GONIOMETER_RADIUS-2 "150.0"
*HW_GONIOMETER_RADIUS-3 "0"
*HW_GONIOMETER_RADIUS-4 "103.4"
*HW_GONIOMETER_RADIUS-5 "150.0"
*HW_GONIOMETER_RADIUS-6 "46.6"
*HW_GONIOMETER_RADIUS-7 "160.0"
*HW_I_OPT_ID-0 "ISL0021"
*HW_I_OPT_ID-1 "ISO0021"
*HW_I_OPT_NAME-0 "発散スリット|Divergence slit"
*HW_I_OPT_NAME-1 "入射平行スリット|Incident parallel slit"
*HW_R_ATTENUATER_AUTOMODE "0"
*HW_R_OPT_ID-0 "RSS0021"
*HW_R_OPT_ID-1 "RSO0021"
*HW_R_OPT_ID-2 "RRS0021"
*HW_R_OPT_NAME-0 "散乱スリット|Scattering slit"
*HW_R_OPT_NAME-1 "受光平行スリット|Receiving soller slit"
*HW_R_OPT_NAME-2 "受光スリット|Receiving slit"
*HW_SAMPLE_HOLDER_ID "SMP0000"
*HW_SAMPLE_HOLDER_NAME "無し|None"
*HW_XG_CURRENT_MAX "15"
*HW_XG_CURRENT_MIN "2"
*HW_XG_CURRENT_RESOLUTION "1"
*HW_XG_CURRENT_UNIT "mA"
*HW_XG_FOCUS "1mm x 10mm"
*HW_XG_FOCUS_TYPE "Normal"
*HW_XG_ID ""
*HW_XG_NAME "300W/600W 封入管-B|300W/600W Sealed tube-B"
*HW_XG_TARGET_ATOMIC_NUMBER "29.0000000000"
*HW_XG_TARGET_NAME "Cu"
*HW_XG_TYPE "Hermetic"
*HW_XG_VOLTAGE_MAX "40"
*HW_XG_VOLTAGE_MIN "20"
*HW_XG_VOLTAGE_RESOLUTION "1"
*HW_XG_VOLTAGE_UNIT "kV"
*HW_XG_WATT_MAX "1"
*HW_XG_WATT_UNIT "kW"
*HW_XG_WAVE_LENGTH_ALPHA1 "1.540593"
*HW_XG_WAVE_LENGTH_ALPHA2 "1.544414"
*HW_XG_WAVE_LENGTH_BETA "1.392250"
*MEAS_COND_AXIS_NAME-0 "Theta/2-Theta"
*MEAS_COND_AXIS_NAME-1 "Spin"
*MEAS_COND_AXIS_NAME-2 "Change"
*MEAS_COND_AXIS_NAME-3 "Soller(inc.)"
*MEAS_COND_AXIS_NAME-4 "IHS"
*MEAS_COND_AXIS_NAME-5 "DS"
*MEAS_COND_AXIS_NAME-6 "SS"
*MEAS_COND_AXIS_NAME-7 "Soller(rec.)"
*MEAS_COND_AXIS_NAME-8 "RS"
*MEAS_COND_AXIS_NAME-9 "Filter"
*MEAS_COND_AXIS_NAME-10 "Monochromator"
*MEAS_COND_AXIS_NAME-11 "PHA"
*MEAS_COND_AXIS_NAME_INTERNAL-0 "TwoThetaTheta"
*MEAS_COND_AXIS_NAME_INTERNAL-1 "Spin"
*MEAS_COND_AXIS_NAME_INTERNAL-2 "Change"
*MEAS_COND_AXIS_NAME_INTERNAL-3 "IncidentSollerSlit"
*MEAS_COND_AXIS_NAME_INTERNAL-4 "IncidentAxdSlit"
*MEAS_COND_AXIS_NAME_INTERNAL-5 "IncidentSlitBox"
*MEAS_COND_AXIS_NAME_INTERNAL-6 "ReceivingSlitBox1"
*MEAS_COND_AXIS_NAME_INTERNAL-7 "ReceivingSollerSlit"
*MEAS_COND_AXIS_NAME_INTERNAL-8 "ReceivingSlitBox2"
*MEAS_COND_AXIS_NAME_INTERNAL-9 "Filter"
*MEAS_COND_AXIS_NAME_INTERNAL-10 "CounterMonochromator"
*MEAS_COND_AXIS_NAME_INTERNAL-11 "PHA"
*MEAS_COND_AXIS_NAME_MAGICNO-0 "268632064.0000000000"
*MEAS_COND_AXIS_NAME_MAGICNO-1 "16842752.0000000000"
*MEAS_COND_AXIS_NAME_MAGICNO-2 "16842752.0000000000"
*MEAS_COND_AXIS_NAME_MAGICNO-3 "20971521.0000000000"
*MEAS_COND_AXIS_NAME_MAGICNO-4 "22020097.0000000000"
*MEAS_COND_AXIS_NAME_MAGICNO-5 "22020097.0000000000"
*MEAS_COND_AXIS_NAME_MAGICNO-6 "23068673.0000000000"
*MEAS_COND_AXIS_NAME_MAGICNO-7 "20971521.0000000000"
*MEAS_COND_AXIS_NAME_MAGICNO-8 "23068673.0000000000"
*MEAS_COND_AXIS_NAME_MAGICNO-9 "20971521.0000000000"
*MEAS_COND_AXIS_NAME_MAGICNO-10 "20971521.0000000000"
*MEAS_COND_AXIS_NAME_MAGICNO-11 "0.0000000000"
*MEAS_COND_AXIS_OFFSET-0 "0.0000000000"
*MEAS_COND_AXIS_OFFSET-1 "-"
*MEAS_COND_AXIS_OFFSET-2 "-"
*MEAS_COND_AXIS_OFFSET-3 "-"
*MEAS_COND_AXIS_OFFSET-4 "-"
*MEAS_COND_AXIS_OFFSET-5 "-"
*MEAS_COND_AXIS_OFFSET-6 "-"
*MEAS_COND_AXIS_OFFSET-7 "-"
*MEAS_COND_AXIS_OFFSET-8 "-"
*MEAS_COND_AXIS_OFFSET-9 "-"
*MEAS_COND_AXIS_OFFSET-10 "-"
*MEAS_COND_AXIS_OFFSET-11 "-"
*MEAS_COND_AXIS_POSITION-0 "92.5100000000"
*MEAS_COND_AXIS_POSITION-1 "0.0000000000"
*MEAS_COND_AXIS_POSITION-2 "4.0000000000"
*MEAS_COND_AXIS_POSITION-3 "2.5deg"
*MEAS_COND_AXIS_POSITION-4 "10.0mm"
*MEAS_COND_AXIS_POSITION-5 "0.625deg"
*MEAS_COND_AXIS_POSITION-6 "13.0mm"
*MEAS_COND_AXIS_POSITION-7 "2.5deg"
*MEAS_COND_AXIS_POSITION-8 "13.0mm"
*MEAS_COND_AXIS_POSITION-9 "K-beta(x1)"
*MEAS_COND_AXIS_POSITION-10 "None"
*MEAS_COND_AXIS_POSITION-11 "42.0000000000"
*MEAS_COND_AXIS_UNIT-0 "deg"
*MEAS_COND_AXIS_UNIT-1 ""
*MEAS_COND_AXIS_UNIT-2 ""
*MEAS_COND_AXIS_UNIT-3 ""
*MEAS_COND_AXIS_UNIT-4 ""
*MEAS_COND_AXIS_UNIT-5 ""
*MEAS_COND_AXIS_UNIT-6 ""
*MEAS_COND_AXIS_UNIT-7 ""
*MEAS_COND_AXIS_UNIT-8 ""
*MEAS_COND_AXIS_UNIT-9 ""
*MEAS_COND_AXIS_UNIT-10 ""
*MEAS_COND_AXIS_UNIT-11 "div"
*MEAS_COND_CORRECTION_SLIT_COUNTERMONO "None"
*MEAS_COND_CORRECTION_SLIT_DS "0.625deg"
*MEAS_COND_CORRECTION_SLIT_FILTER "None"
*MEAS_COND_CORRECTION_SLIT_IHS "10.0mm"
*MEAS_COND_CORRECTION_SLIT_RS "13.0mm"
*MEAS_COND_CORRECTION_SLIT_SOLLER_INC "2.5deg"
*MEAS_COND_CORRECTION_SLIT_SOLLER_REC "2.5deg"
*MEAS_COND_CORRECTION_SLIT_SS "13.0mm"
*MEAS_COND_COUNTER_CNTLOSS_CORR "0.0000000000"
*MEAS_COND_COUNTER_PHABASE "42.0000000000"
*MEAS_COND_COUNTER_PHAWINDOW "15.0000000000"
*MEAS_COND_COUNTER_PHA_UNIT "div"
*MEAS_COND_COUNTER_TAUDIFF "0.2500000000"
*MEAS_COND_COUNTER_TAUINT "0.7500000000"
*MEAS_COND_IRRADIATION_MODE "OFF"
*MEAS_COND_IRRADIATION_WIDTH ""
*MEAS_COND_OPT_ATTR " "
*MEAS_COND_OPT_NAME ""
*MEAS_COND_UNSYMMETRIC_MODE "OFF"
*MEAS_COND_XG_CURRENT "15.0000000000"
*MEAS_COND_XG_VOLTAGE "40.0000000000"
*MEAS_COND_XG_WAVE_TYPE "Ka"
*MEAS_DATA_COUNT "4251.0000000000"
*MEAS_SCAN_AXIS_X "Theta/2-Theta"
*MEAS_SCAN_AXIS_X_INTERNAL "TwoThetaTheta"
*MEAS_SCAN_END_TIME "03/04/19 15:43:56"
*MEAS_SCAN_MODE "CONTINUOUS"
*MEAS_SCAN_MONITOR "0"
*MEAS_SCAN_RESOLUTION_X "0.005"
*MEAS_SCAN_SPEED "10.000"
*MEAS_SCAN_SPEED_UNIT "deg/min"
*MEAS_SCAN_START "5.0000000000"
*MEAS_SCAN_START_TIME "03/04/19 15:34:31"
*MEAS_SCAN_STEP "0.0200000000"
*MEAS_SCAN_STOP "90.0000000000"
*MEAS_SCAN_UNIT_X "deg"
*MEAS_SCAN_UNIT_Y "counts"
*SLIT_SYSTEM "0"
*RAS_HEADER_END
*RAS_INT_START
5.000 555.000 1.000
5.060 576.000 1.000
5.120 520.000 1.000
5.180 506.000 1.000
5.240 470.000 1.000
5.300 447.000 1.000
5.360 491.000 1.000
5.420 446.000 1.000
5.480 448.000 1.000
5.540 406.000 1.000
5.600 390.000 1.000
5.660 421.000 1.000
5.720 387.000 1.000
5.780 402.000 1.000
5.840 376.000 1.000
5.900 362.000 1.000
5.960 351.000 1.000
6.020 330.000 1.000
6.080 350.000 1.000
6.140 315.000 1.000
6.200 351.000 1.000
6.260 321.000 1.000
6.320 338.000 1.000
6.380 299.000 1.000
6.440 286.000 1.000
6.500 289.000 1.000
6.560 276.000 1.000
6.620 293.000 1.000
6.680 277.000 1.000
6.740 245.000 1.000
6.800 251.000 1.000
6.860 276.000 1.000
6.920 262.000 1.000
6.980 262.000 1.000
7.040 255.000 1.000
7.100 229.000 1.000
7.160 250.000 1.000
7.220 243.000 1.000
7.280 231.000 1.000
7.340 225.000 1.000
7.400 231.000 1.000
7.460 225.000 1.000
7.520 212.000 1.000
7.580 222.000 1.000
7.640 220.000 1.000
7.700 200.000 1.000
7.760 202.000 1.000
7.820 221.000 1.000
7.880 193.000 1.000
7.940 201.000 1.000
8.000 193.000 1.000
8.060 202.000 1.000
8.120 212.000 1.000
8.180 201.000 1.000
8.240 180.000 1.000
8.300 199.000 1.000
8.360 181.000 1.000
8.420 174.000 1.000
8.480 194.000 1.000
8.540 182.000 1.000
8.600 173.000 1.000
8.660 178.000 1.000
8.720 179.000 1.000
8.780 180.000 1.000
8.840 162.000 1.000
8.900 158.000 1.000
8.960 166.000 1.000
9.020 165.000 1.000
9.080 171.000 1.000
9.140 167.000 1.000
9.200 175.000 1.000
9.260 162.000 1.000
9.320 168.000 1.000
9.380 173.000 1.000
9.440 171.000 1.000
9.500 165.000 1.000
9.560 161.000 1.000
9.620 167.000 1.000
9.680 157.000 1.000
9.740 162.000 1.000
9.800 172.000 1.000
9.860 157.000 1.000
9.920 168.000 1.000
9.980 153.000 1.000
10.040 166.000 1.000
10.100 163.000 1.000
10.160 156.000 1.000
10.220 146.000 1.000
10.280 151.000 1.000
10.340 156.000 1.000
10.400 146.000 1.000
10.460 159.000 1.000
10.520 164.000 1.000
10.580 142.000 1.000
10.640 145.000 1.000
10.700 159.000 1.000
10.760 139.000 1.000
10.820 140.000 1.000
10.880 147.000 1.000
10.940 142.000 1.000
11.000 138.000 1.000
11.060 151.000 1.000
11.120 145.000 1.000
11.180 144.000 1.000
11.240 153.000 1.000
11.300 155.000 1.000
11.360 155.000 1.000
11.420 141.000 1.000
11.480 134.000 1.000
11.540 143.000 1.000
11.600 156.000 1.000
11.660 152.000 1.000
11.720 154.000 1.000
11.780 166.000 1.000
11.840 143.000 1.000
11.900 141.000 1.000
11.960 143.000 1.000
12.020 150.000 1.000
12.080 153.000 1.000
12.140 152.000 1.000
12.200 150.000 1.000
12.260 159.000 1.000
12.320 155.000 1.000
12.380 138.000 1.000
12.440 129.000 1.000
12.500 151.000 1.000
12.560 136.000 1.000
12.620 137.000 1.000
12.680 149.000 1.000
12.740 123.000 1.000
12.800 143.000 1.000
12.860 137.000 1.000
12.920 125.000 1.000
12.980 148.000 1.000
13.040 144.000 1.000
13.100 143.000 1.000
13.160 128.000 1.000
13.220 150.000 1.000
13.280 148.000 1.000
13.340 139.000 1.000
13.400 146.000 1.000
13.460 151.000 1.000
13.520 143.000 1.000
13.580 152.000 1.000
13.640 156.000 1.000
13.700 157.000 1.000
13.760 157.000 1.000
13.820 157.000 1.000
13.880 169.000 1.000
13.940 155.000 1.000
14.000 152.000 1.000
14.060 166.000 1.000
14.120 155.000 1.000
14.180 157.000 1.000
14.240 159.000 1.000
14.300 153.000 1.000
14.360 169.000 1.000
14.420 156.000 1.000
14.480 175.000 1.000
14.540 152.000 1.000
14.600 165.000 1.000
14.660 152.000 1.000
14.720 150.000 1.000
14.780 166.000 1.000
14.840 158.000 1.000
14.900 162.000 1.000
14.960 144.000 1.000
15.020 158.000 1.000
15.080 146.000 1.000
15.140 149.000 1.000
15.200 166.000 1.000
15.260 144.000 1.000
15.320 156.000 1.000
15.380 164.000 1.000
15.440 141.000 1.000
15.500 138.000 1.000
15.560 135.000 1.000
15.620 130.000 1.000
15.680 140.000 1.000
15.740 138.000 1.000
15.800 131.000 1.000
15.860 148.000 1.000
15.920 123.000 1.000
15.980 129.000 1.000
16.040 137.000 1.000
16.100 134.000 1.000
16.160 129.000 1.000
16.220 129.000 1.000
16.280 125.000 1.000
16.340 129.000 1.000
16.400 128.000 1.000
16.460 113.000 1.000
16.520 134.000 1.000
16.580 143.000 1.000
16.640 127.000 1.000
16.700 135.000 1.000
16.760 113.000 1.000
16.820 120.000 1.000
16.880 123.000 1.000
16.940 114.000 1.000
17.000 107.000 1.000
17.060 129.000 1.000
17.120 126.000 1.000
17.180 124.000 1.000
17.240 129.000 1.000
17.300 115.000 1.000
17.360 116.000 1.000
17.420 113.000 1.000
17.480 111.000 1.000
17.540 115.000 1.000
17.600 126.000 1.000
17.660 125.000 1.000
17.720 126.000 1.000
17.780 132.000 1.000
17.840 118.000 1.000
17.900 116.000 1.000
17.960 110.000 1.000
18.020 115.000 1.000
18.080 115.000 1.000
18.140 113.000 1.000
18.200 105.000 1.000
18.260 116.000 1.000
18.320 113.000 1.000
18.380 112.000 1.000
18.440 113.000 1.000
18.500 108.000 1.000
18.560 105.000 1.000
18.620 110.000 1.000
18.680 106.000 1.000
18.740 113.000 1.000
18.800 107.000 1.000
18.860 113.000 1.000
18.920 105.000 1.000
18.980 105.000 1.000
19.040 106.000 1.000
19.100 108.000 1.000
19.160 110.000 1.000
19.220 102.000 1.000
19.280 108.000 1.000
19.340 113.000 1.000
19.400 109.000 1.000
19.460 107.000 1.000
19.520 122.000 1.000
19.580 121.000 1.000
19.640 106.000 1.000
19.700 108.000 1.000
19.760 96.000 1.000
19.820 113.000 1.000
19.880 113.000 1.000
19.940 121.000 1.000
20.000 101.000 1.000
20.060 94.000 1.000
20.120 97.000 1.000
20.180 109.000 1.000
20.240 96.000 1.000
20.300 101.000 1.000
20.360 108.000 1.000
20.420 101.000 1.000
20.480 108.000 1.000
20.540 121.000 1.000
20.600 96.000 1.000
20.660 102.000 1.000
20.720 104.000 1.000
20.780 103.000 1.000
20.840 102.000 1.000
20.900 98.000 1.000
20.960 98.000 1.000
21.020 92.000 1.000
21.080 102.000 1.000
21.140 103.000 1.000
21.200 110.000 1.000
21.260 105.000 1.000
21.320 101.000 1.000
21.380 114.000 1.000
21.440 105.000 1.000
21.500 104.000 1.000
21.560 105.000 1.000
21.620 100.000 1.000
21.680 108.000 1.000
21.740 94.000 1.000
21.800 105.000 1.000
21.860 108.000 1.000
21.920 101.000 1.000
21.980 116.000 1.000
22.040 115.000 1.000
22.100 101.000 1.000
22.160 109.000 1.000
22.220 114.000 1.000
22.280 109.000 1.000
22.340 108.000 1.000
22.400 106.000 1.000
22.460 108.000 1.000
22.520 116.000 1.000
22.580 115.000 1.000
22.640 115.000 1.000
22.700 111.000 1.000
22.760 122.000 1.000
22.820 129.000 1.000
22.880 120.000 1.000
22.940 124.000 1.000
23.000 119.000 1.000
23.060 133.000 1.000
23.120 134.000 1.000
23.180 127.000 1.000
23.240 150.000 1.000
23.300 126.000 1.000
23.360 141.000 1.000
23.420 131.000 1.000
23.480 143.000 1.000
23.540 140.000 1.000
23.600 157.000 1.000
23.660 167.000 1.000
23.720 169.000 1.000
23.780 162.000 1.000
23.840 165.000 1.000
23.900 171.000 1.000
23.960 158.000 1.000
24.020 179.000 1.000
24.080 183.000 1.000
24.140 197.000 1.000
24.200 171.000 1.000
24.260 187.000 1.000
24.320 189.000 1.000
24.380 199.000 1.000
24.440 204.000 1.000
24.500 209.000 1.000
24.560 202.000 1.000
24.620 201.000 1.000
24.680 211.000 1.000
24.740 221.000 1.000
24.800 220.000 1.000
24.860 238.000 1.000
24.920 226.000 1.000
24.980 237.000 1.000
25.040 243.000 1.000
25.100 251.000 1.000
25.160 216.000 1.000
25.220 254.000 1.000
25.280 240.000 1.000
25.340 234.000 1.000
25.400 237.000 1.000
25.460 256.000 1.000
25.520 241.000 1.000
25.580 234.000 1.000
25.640 240.000 1.000
25.700 257.000 1.000
25.760 248.000 1.000
25.820 244.000 1.000
25.880 229.000 1.000
25.940 219.000 1.000
26.000 238.000 1.000
26.060 231.000 1.000
26.120 210.000 1.000
26.180 219.000 1.000
26.240 247.000 1.000
26.300 230.000 1.000
26.360 230.000 1.000
26.420 234.000 1.000
26.480 237.000 1.000
26.540 242.000 1.000
26.600 241.000 1.000
26.660 271.000 1.000
26.720 271.000 1.000
26.780 272.000 1.000
26.840 314.000 1.000
26.900 326.000 1.000
26.960 375.000 1.000
27.020 459.000 1.000
27.080 558.000 1.000
27.140 721.000 1.000
27.200 985.000 1.000
27.260 1246.000 1.000
27.320 1493.000 1.000
27.380 1574.000 1.000
27.440 1395.000 1.000
27.500 1141.000 1.000
27.560 865.000 1.000
27.620 626.000 1.000
27.680 520.000 1.000
27.740 431.000 1.000
27.800 361.000 1.000
27.860 327.000 1.000
27.920 283.000 1.000
27.980 254.000 1.000
28.040 257.000 1.000
28.100 211.000 1.000
28.160 238.000 1.000
28.220 212.000 1.000
28.280 197.000 1.000
28.340 195.000 1.000
28.400 192.000 1.000
28.460 189.000 1.000
28.520 177.000 1.000
28.580 168.000 1.000
28.640 172.000 1.000
28.700 164.000 1.000
28.760 151.000 1.000
28.820 174.000 1.000
28.880 161.000 1.000
28.940 166.000 1.000
29.000 147.000 1.000
29.060 152.000 1.000
29.120 147.000 1.000
29.180 144.000 1.000
29.240 120.000 1.000
29.300 128.000 1.000
29.360 128.000 1.000
29.420 137.000 1.000
29.480 127.000 1.000
29.540 124.000 1.000
29.600 121.000 1.000
29.660 134.000 1.000
29.720 118.000 1.000
29.780 113.000 1.000
29.840 117.000 1.000
29.900 116.000 1.000
29.960 112.000 1.000
30.020 111.000 1.000
30.080 116.000 1.000
30.140 95.000 1.000
30.200 115.000 1.000
30.260 116.000 1.000
30.320 109.000 1.000
30.380 106.000 1.000
30.440 117.000 1.000
30.500 108.000 1.000
30.560 110.000 1.000
30.620 93.000 1.000
30.680 105.000 1.000
30.740 109.000 1.000
30.800 117.000 1.000
30.860 106.000 1.000
30.920 94.000 1.000
30.980 104.000 1.000
31.040 110.000 1.000
31.100 88.000 1.000
31.160 96.000 1.000
31.220 103.000 1.000
31.280 96.000 1.000
31.340 86.000 1.000
31.400 103.000 1.000
31.460 105.000 1.000
31.520 95.000 1.000
31.580 88.000 1.000
31.640 97.000 1.000
31.700 93.000 1.000
31.760 75.000 1.000
31.820 91.000 1.000
31.880 82.000 1.000
31.940 80.000 1.000
32.000 75.000 1.000
32.060 75.000 1.000
32.120 84.000 1.000
32.180 87.000 1.000
32.240 89.000 1.000
32.300 80.000 1.000
32.360 79.000 1.000
32.420 75.000 1.000
32.480 86.000 1.000
32.540 79.000 1.000
32.600 80.000 1.000
32.660 76.000 1.000
32.720 71.000 1.000
32.780 74.000 1.000
32.840 78.000 1.000
32.900 75.000 1.000
32.960 86.000 1.000
33.020 79.000 1.000
33.080 82.000 1.000
33.140 73.000 1.000
33.200 80.000 1.000
33.260 85.000 1.000
33.320 84.000 1.000
33.380 91.000 1.000
33.440 66.000 1.000
33.500 80.000 1.000
33.560 90.000 1.000
33.620 78.000 1.000
33.680 82.000 1.000
33.740 73.000 1.000
33.800 78.000 1.000
33.860 70.000 1.000
33.920 82.000 1.000
33.980 82.000 1.000
34.040 75.000 1.000
34.100 67.000 1.000
34.160 73.000 1.000
34.220 87.000 1.000
34.280 68.000 1.000
34.340 79.000 1.000
34.400 86.000 1.000
34.460 79.000 1.000
34.520 72.000 1.000
34.580 74.000 1.000
34.640 78.000 1.000
34.700 91.000 1.000
34.760 81.000 1.000
34.820 77.000 1.000
34.880 93.000 1.000
34.940 88.000 1.000
35.000 87.000 1.000
35.060 95.000 1.000
35.120 100.000 1.000
35.180 92.000 1.000
35.240 89.000 1.000
35.300 88.000 1.000
35.360 104.000 1.000
35.420 122.000 1.000
35.480 112.000 1.000
35.540 140.000 1.000
35.600 135.000 1.000
35.660 149.000 1.000
35.720 176.000 1.000
35.780 200.000 1.000
35.840 244.000 1.000
35.900 352.000 1.000
35.960 506.000 1.000
36.020 714.000 1.000
36.080 826.000 1.000
36.140 743.000 1.000
36.200 530.000 1.000
36.260 375.000 1.000
36.320 261.000 1.000
36.380 189.000 1.000
36.440 176.000 1.000
36.500 155.000 1.000
36.560 148.000 1.000
36.620 136.000 1.000
36.680 126.000 1.000
36.740 117.000 1.000
36.800 94.000 1.000
36.860 111.000 1.000
36.920 106.000 1.000
36.980 93.000 1.000
37.040 103.000 1.000
37.100 105.000 1.000
37.160 101.000 1.000
37.220 110.000 1.000
37.280 102.000 1.000
37.340 99.000 1.000
37.400 103.000 1.000
37.460 95.000 1.000
37.520 103.000 1.000
37.580 114.000 1.000
37.640 97.000 1.000
37.700 103.000 1.000
37.760 100.000 1.000
37.820 102.000 1.000
37.880 104.000 1.000
37.940 97.000 1.000
38.000 98.000 1.000
38.060 96.000 1.000
38.120 99.000 1.000
38.180 100.000 1.000
38.240 94.000 1.000
38.300 98.000 1.000
38.360 97.000 1.000
38.420 99.000 1.000
38.480 81.000 1.000
38.540 87.000 1.000
38.600 96.000 1.000
38.660 93.000 1.000
38.720 97.000 1.000
38.780 104.000 1.000
38.840 107.000 1.000
38.900 104.000 1.000
38.960 146.000 1.000
39.020 134.000 1.000
39.080 151.000 1.000
39.140 146.000 1.000
39.200 117.000 1.000
39.260 112.000 1.000
39.320 93.000 1.000
39.380 94.000 1.000
39.440 86.000 1.000
39.500 77.000 1.000
39.560 82.000 1.000
39.620 79.000 1.000
39.680 84.000 1.000
39.740 76.000 1.000
39.800 82.000 1.000
39.860 79.000 1.000
39.920 78.000 1.000
39.980 88.000 1.000
40.040 76.000 1.000
40.100 78.000 1.000
40.160 70.000 1.000
40.220 70.000 1.000
40.280 64.000 1.000
40.340 72.000 1.000
40.400 75.000 1.000
40.460 80.000 1.000
40.520 86.000 1.000
40.580 73.000 1.000
40.640 81.000 1.000
40.700 80.000 1.000
40.760 89.000 1.000
40.820 107.000 1.000
40.880 118.000 1.000
40.940 145.000 1.000
41.000 178.000 1.000
41.060 245.000 1.000
41.120 331.000 1.000
41.180 403.000 1.000
41.240 424.000 1.000
41.300 355.000 1.000
41.360 256.000 1.000
41.420 191.000 1.000
41.480 138.000 1.000
41.540 128.000 1.000
41.600 119.000 1.000
41.660 91.000 1.000
41.720 85.000 1.000
41.780 74.000 1.000
41.840 75.000 1.000
41.900 91.000 1.000
41.960 62.000 1.000
42.020 74.000 1.000
42.080 60.000 1.000
42.140 57.000 1.000
42.200 63.000 1.000
42.260 64.000 1.000
42.320 71.000 1.000
42.380 63.000 1.000
42.440 62.000 1.000
42.500 61.000 1.000
42.560 65.000 1.000
42.620 65.000 1.000
42.680 63.000 1.000
42.740 56.000 1.000
42.800 78.000 1.000
42.860 72.000 1.000
42.920 64.000 1.000
42.980 70.000 1.000
43.040 75.000 1.000
43.100 71.000 1.000
43.160 83.000 1.000
43.220 68.000 1.000
43.280 79.000 1.000
43.340 80.000 1.000
43.400 84.000 1.000
43.460 85.000 1.000
43.520 92.000 1.000
43.580 108.000 1.000
43.640 120.000 1.000
43.700 122.000 1.000
43.760 137.000 1.000
43.820 161.000 1.000
43.880 176.000 1.000
43.940 161.000 1.000
44.000 186.000 1.000
44.060 158.000 1.000
44.120 138.000 1.000
44.180 109.000 1.000
44.240 105.000 1.000
44.300 85.000 1.000
44.360 88.000 1.000
44.420 88.000 1.000
44.480 83.000 1.000
44.540 76.000 1.000
44.600 70.000 1.000
44.660 74.000 1.000
44.720 76.000 1.000
44.780 73.000 1.000
44.840 78.000 1.000
44.900 64.000 1.000
44.960 63.000 1.000
45.020 70.000 1.000
45.080 66.000 1.000
45.140 60.000 1.000
45.200 70.000 1.000
45.260 57.000 1.000
45.320 69.000 1.000
45.380 64.000 1.000
45.440 60.000 1.000
45.500 67.000 1.000
45.560 62.000 1.000
45.620 65.000 1.000
45.680 63.000 1.000
45.740 67.000 1.000
45.800 62.000 1.000
45.860 55.000 1.000
45.920 69.000 1.000
45.980 61.000 1.000
46.040 50.000 1.000
46.100 57.000 1.000
46.160 66.000 1.000
46.220 59.000 1.000
46.280 50.000 1.000
46.340 74.000 1.000
46.400 63.000 1.000
46.460 67.000 1.000
46.520 62.000 1.000
46.580 57.000 1.000
46.640 72.000 1.000
46.700 64.000 1.000
46.760 75.000 1.000
46.820 77.000 1.000
46.880 71.000 1.000
46.940 70.000 1.000
47.000 67.000 1.000
47.060 67.000 1.000
47.120 64.000 1.000
47.180 73.000 1.000
47.240 74.000 1.000
47.300 83.000 1.000
47.360 79.000 1.000
47.420 73.000 1.000
47.480 74.000 1.000
47.540 76.000 1.000
47.600 85.000 1.000
47.660 70.000 1.000
47.720 81.000 1.000
47.780 76.000 1.000
47.840 84.000 1.000
47.900 79.000 1.000
47.960 87.000 1.000
48.020 85.000 1.000
48.080 82.000 1.000
48.140 88.000 1.000
48.200 84.000 1.000
48.260 78.000 1.000
48.320 78.000 1.000
48.380 88.000 1.000
48.440 95.000 1.000
48.500 77.000 1.000
48.560 82.000 1.000
48.620 85.000 1.000
48.680 80.000 1.000
48.740 73.000 1.000
48.800 84.000 1.000
48.860 77.000 1.000
48.920 68.000 1.000
48.980 72.000 1.000
49.040 78.000 1.000
49.100 78.000 1.000
49.160 75.000 1.000
49.220 67.000 1.000
49.280 69.000 1.000
49.340 68.000 1.000
49.400 66.000 1.000
49.460 71.000 1.000
49.520 63.000 1.000
49.580 69.000 1.000
49.640 65.000 1.000
49.700 74.000 1.000
49.760 55.000 1.000
49.820 53.000 1.000
49.880 61.000 1.000
49.940 63.000 1.000
50.000 68.000 1.000
50.060 54.000 1.000
50.120 49.000 1.000
50.180 54.000 1.000
50.240 53.000 1.000
50.300 62.000 1.000
50.360 64.000 1.000
50.420 58.000 1.000
50.480 59.000 1.000
50.540 48.000 1.000
50.600 50.000 1.000
50.660 52.000 1.000
50.720 44.000 1.000
50.780 56.000 1.000
50.840 55.000 1.000
50.900 47.000 1.000
50.960 52.000 1.000
51.020 50.000 1.000
51.080 48.000 1.000
51.140 49.000 1.000
51.200 55.000 1.000
51.260 51.000 1.000
51.320 57.000 1.000
51.380 55.000 1.000
51.440 52.000 1.000
51.500 55.000 1.000
51.560 60.000 1.000
51.620 58.000 1.000
51.680 63.000 1.000
51.740 52.000 1.000
51.800 52.000 1.000
51.860 56.000 1.000
51.920 62.000 1.000
51.980 54.000 1.000
52.040 62.000 1.000
52.100 53.000 1.000
52.160 57.000 1.000
52.220 61.000 1.000
52.280 68.000 1.000
52.340 61.000 1.000
52.400 67.000 1.000
52.460 67.000 1.000
52.520 79.000 1.000
52.580 74.000 1.000
52.640 78.000 1.000
52.700 62.000 1.000
52.760 86.000 1.000
52.820 83.000 1.000
52.880 77.000 1.000
52.940 75.000 1.000
53.000 79.000 1.000
53.060 76.000 1.000
53.120 94.000 1.000
53.180 94.000 1.000
53.240 100.000 1.000
53.300 107.000 1.000
53.360 108.000 1.000
53.420 119.000 1.000
53.480 133.000 1.000
53.540 131.000 1.000
53.600 148.000 1.000
53.660 156.000 1.000
53.720 152.000 1.000
53.780 188.000 1.000
53.840 203.000 1.000
53.900 248.000 1.000
53.960 309.000 1.000
54.020 399.000 1.000
54.080 532.000 1.000
54.140 657.000 1.000
54.200 786.000 1.000
54.260 772.000 1.000
54.320 691.000 1.000
54.380 579.000 1.000
54.440 457.000 1.000
54.500 388.000 1.000
54.560 272.000 1.000
54.620 233.000 1.000
54.680 205.000 1.000
54.740 182.000 1.000
54.800 185.000 1.000
54.860 162.000 1.000
54.920 144.000 1.000
54.980 137.000 1.000
55.040 131.000 1.000
55.100 119.000 1.000
55.160 110.000 1.000
55.220 123.000 1.000
55.280 109.000 1.000
55.340 111.000 1.000
55.400 109.000 1.000
55.460 104.000 1.000
55.520 105.000 1.000
55.580 114.000 1.000
55.640 91.000 1.000
55.700 90.000 1.000
55.760 89.000 1.000
55.820 95.000 1.000
55.880 92.000 1.000
55.940 98.000 1.000
56.000 102.000 1.000
56.060 110.000 1.000
56.120 136.000 1.000
56.180 160.000 1.000
56.240 181.000 1.000
56.300 222.000 1.000
56.360 266.000 1.000
56.420 252.000 1.000
56.480 278.000 1.000
56.540 241.000 1.000
56.600 224.000 1.000
56.660 190.000 1.000
56.720 167.000 1.000
56.780 136.000 1.000
56.840 111.000 1.000
56.900 106.000 1.000
56.960 101.000 1.000
57.020 87.000 1.000
57.080 102.000 1.000
57.140 77.000 1.000
57.200 73.000 1.000
57.260 83.000 1.000
57.320 86.000 1.000
57.380 65.000 1.000
57.440 64.000 1.000
57.500 63.000 1.000
57.560 68.000 1.000
57.620 71.000 1.000
57.680 71.000 1.000
57.740 70.000 1.000
57.800 60.000 1.000
57.860 60.000 1.000
57.920 57.000 1.000
57.980 51.000 1.000
58.040 58.000 1.000
58.100 57.000 1.000
58.160 69.000 1.000
58.220 67.000 1.000
58.280 62.000 1.000
58.340 63.000 1.000
58.400 55.000 1.000
58.460 45.000 1.000
58.520 57.000 1.000
58.580 59.000 1.000
58.640 58.000 1.000
58.700 53.000 1.000
58.760 58.000 1.000
58.820 60.000 1.000
58.880 59.000 1.000
58.940 53.000 1.000
59.000 52.000 1.000
59.060 57.000 1.000
59.120 59.000 1.000
59.180 48.000 1.000
59.240 56.000 1.000
59.300 50.000 1.000
59.360 54.000 1.000
59.420 56.000 1.000
59.480 53.000 1.000
59.540 58.000 1.000
59.600 49.000 1.000
59.660 54.000 1.000
59.720 49.000 1.000
59.780 42.000 1.000
59.840 52.000 1.000
59.900 49.000 1.000
59.960 42.000 1.000
60.020 47.000 1.000
60.080 56.000 1.000
60.140 49.000 1.000
60.200 56.000 1.000
60.260 46.000 1.000
60.320 51.000 1.000
60.380 53.000 1.000
60.440 55.000 1.000
60.500 48.000 1.000
60.560 51.000 1.000
60.620 45.000 1.000
60.680 53.000 1.000
60.740 50.000 1.000
60.800 58.000 1.000
60.860 48.000 1.000
60.920 40.000 1.000
60.980 53.000 1.000
61.040 53.000 1.000
61.100 54.000 1.000
61.160 57.000 1.000
61.220 56.000 1.000
61.280 53.000 1.000
61.340 54.000 1.000
61.400 60.000 1.000
61.460 57.000 1.000
61.520 56.000 1.000
61.580 65.000 1.000
61.640 59.000 1.000
61.700 62.000 1.000
61.760 64.000 1.000
61.820 72.000 1.000
61.880 67.000 1.000
61.940 67.000 1.000
62.000 62.000 1.000
62.060 67.000 1.000
62.120 66.000 1.000
62.180 67.000 1.000
62.240 66.000 1.000
62.300 65.000 1.000
62.360 76.000 1.000
62.420 76.000 1.000
62.480 73.000 1.000
62.540 92.000 1.000
62.600 79.000 1.000
62.660 108.000 1.000
62.720 151.000 1.000
62.780 204.000 1.000
62.840 172.000 1.000
62.900 170.000 1.000
62.960 168.000 1.000
63.020 133.000 1.000
63.080 111.000 1.000
63.140 83.000 1.000
63.200 88.000 1.000
63.260 80.000 1.000
63.320 79.000 1.000
63.380 73.000 1.000
63.440 85.000 1.000
63.500 75.000 1.000
63.560 89.000 1.000
63.620 94.000 1.000
63.680 113.000 1.000
63.740 118.000 1.000
63.800 145.000 1.000
63.860 126.000 1.000
63.920 120.000 1.000
63.980 119.000 1.000
64.040 117.000 1.000
64.100 103.000 1.000
64.160 91.000 1.000
64.220 97.000 1.000
64.280 86.000 1.000
64.340 71.000 1.000
64.400 62.000 1.000
64.460 71.000 1.000
64.520 67.000 1.000
64.580 56.000 1.000
64.640 66.000 1.000
64.700 58.000 1.000
64.760 56.000 1.000
64.820 60.000 1.000
64.880 58.000 1.000
64.940 54.000 1.000
65.000 52.000 1.000
65.060 53.000 1.000
65.120 62.000 1.000
65.180 58.000 1.000
65.240 53.000 1.000
65.300 75.000 1.000
65.360 59.000 1.000
65.420 51.000 1.000
65.480 52.000 1.000
65.540 53.000 1.000
65.600 51.000 1.000
65.660 53.000 1.000
65.720 46.000 1.000
65.780 52.000 1.000
65.840 49.000 1.000
65.900 38.000 1.000
65.960 38.000 1.000
66.020 43.000 1.000
66.080 40.000 1.000
66.140 53.000 1.000
66.200 44.000 1.000
66.260 49.000 1.000
66.320 51.000 1.000
66.380 48.000 1.000
66.440 48.000 1.000
66.500 48.000 1.000
66.560 57.000 1.000
66.620 56.000 1.000
66.680 48.000 1.000
66.740 50.000 1.000
66.800 48.000 1.000
66.860 47.000 1.000
66.920 46.000 1.000
66.980 55.000 1.000
67.040 50.000 1.000
67.100 47.000 1.000
67.160 55.000 1.000
67.220 52.000 1.000
67.280 46.000 1.000
67.340 51.000 1.000
67.400 51.000 1.000
67.460 53.000 1.000
67.520 58.000 1.000
67.580 47.000 1.000
67.640 61.000 1.000
67.700 60.000 1.000
67.760 64.000 1.000
67.820 61.000 1.000
67.880 67.000 1.000
67.940 60.000 1.000
68.000 71.000 1.000
68.060 65.000 1.000
68.120 55.000 1.000
68.180 63.000 1.000
68.240 84.000 1.000
68.300 88.000 1.000
68.360 85.000 1.000
68.420 105.000 1.000
68.480 106.000 1.000
68.540 136.000 1.000
68.600 147.000 1.000
68.660 190.000 1.000
68.720 217.000 1.000
68.780 234.000 1.000
68.840 255.000 1.000
68.900 247.000 1.000
68.960 240.000 1.000
69.020 203.000 1.000
69.080 180.000 1.000
69.140 152.000 1.000
69.200 129.000 1.000
69.260 116.000 1.000
69.320 120.000 1.000
69.380 108.000 1.000
69.440 103.000 1.000
69.500 98.000 1.000
69.560 101.000 1.000
69.620 120.000 1.000
69.680 139.000 1.000
69.740 168.000 1.000
69.800 180.000 1.000
69.860 174.000 1.000
69.920 142.000 1.000
69.980 145.000 1.000
70.040 119.000 1.000
70.100 103.000 1.000
70.160 84.000 1.000
70.220 70.000 1.000
70.280 68.000 1.000
70.340 65.000 1.000
70.400 67.000 1.000
70.460 56.000 1.000
70.520 53.000 1.000
70.580 52.000 1.000
70.640 42.000 1.000
70.700 52.000 1.000
70.760 51.000 1.000
70.820 42.000 1.000
70.880 44.000 1.000
70.940 45.000 1.000
71.000 42.000 1.000
71.060 32.000 1.000
71.120 39.000 1.000
71.180 43.000 1.000
71.240 33.000 1.000
71.300 40.000 1.000
71.360 33.000 1.000
71.420 40.000 1.000
71.480 40.000 1.000
71.540 38.000 1.000
71.600 42.000 1.000
71.660 43.000 1.000
71.720 37.000 1.000
71.780 41.000 1.000
71.840 35.000 1.000
71.900 47.000 1.000
71.960 43.000 1.000
72.020 48.000 1.000
72.080 47.000 1.000
72.140 54.000 1.000
72.200 43.000 1.000
72.260 47.000 1.000
72.320 51.000 1.000
72.380 42.000 1.000
72.440 55.000 1.000
72.500 45.000 1.000
72.560 44.000 1.000
72.620 39.000 1.000
72.680 36.000 1.000
72.740 32.000 1.000
72.800 36.000 1.000
72.860 34.000 1.000
72.920 37.000 1.000
72.980 36.000 1.000
73.040 38.000 1.000
73.100 34.000 1.000
73.160 43.000 1.000
73.220 34.000 1.000
73.280 35.000 1.000
73.340 30.000 1.000
73.400 42.000 1.000
73.460 39.000 1.000
73.520 25.000 1.000
73.580 39.000 1.000
73.640 40.000 1.000
73.700 35.000 1.000
73.760 40.000 1.000
73.820 35.000 1.000
73.880 40.000 1.000
73.940 44.000 1.000
74.000 34.000 1.000
74.060 49.000 1.000
74.120 40.000 1.000
74.180 40.000 1.000
74.240 40.000 1.000
74.300 42.000 1.000
74.360 42.000 1.000
74.420 44.000 1.000
74.480 41.000 1.000
74.540 44.000 1.000
74.600 39.000 1.000
74.660 42.000 1.000
74.720 41.000 1.000
74.780 45.000 1.000
74.840 42.000 1.000
74.900 43.000 1.000
74.960 42.000 1.000
75.020 48.000 1.000
75.080 38.000 1.000
75.140 43.000 1.000
75.200 35.000 1.000
75.260 38.000 1.000
75.320 41.000 1.000
75.380 42.000 1.000
75.440 45.000 1.000
75.500 39.000 1.000
75.560 34.000 1.000
75.620 33.000 1.000
75.680 35.000 1.000
75.740 43.000 1.000
75.800 49.000 1.000
75.860 42.000 1.000
75.920 44.000 1.000
75.980 44.000 1.000
76.040 40.000 1.000
76.100 47.000 1.000
76.160 44.000 1.000
76.220 52.000 1.000
76.280 39.000 1.000
76.340 50.000 1.000
76.400 54.000 1.000
76.460 58.000 1.000
76.520 77.000 1.000
76.580 50.000 1.000
76.640 61.000 1.000
76.700 62.000 1.000
76.760 44.000 1.000
76.820 46.000 1.000
76.880 56.000 1.000
76.940 38.000 1.000
77.000 35.000 1.000
77.060 40.000 1.000
77.120 37.000 1.000
77.180 35.000 1.000
77.240 46.000 1.000
77.300 37.000 1.000
77.360 37.000 1.000
77.420 29.000 1.000
77.480 35.000 1.000
77.540 39.000 1.000
77.600 29.000 1.000
77.660 31.000 1.000
77.720 36.000 1.000
77.780 39.000 1.000
77.840 29.000 1.000
77.900 33.000 1.000
77.960 28.000 1.000
78.020 34.000 1.000
78.080 37.000 1.000
78.140 34.000 1.000
78.200 36.000 1.000
78.260 28.000 1.000
78.320 35.000 1.000
78.380 31.000 1.000
78.440 31.000 1.000
78.500 32.000 1.000
78.560 27.000 1.000
78.620 29.000 1.000
78.680 32.000 1.000
78.740 32.000 1.000
78.800 30.000 1.000
78.860 33.000 1.000
78.920 35.000 1.000
78.980 25.000 1.000
79.040 36.000 1.000
79.100 29.000 1.000
79.160 27.000 1.000
79.220 30.000 1.000
79.280 40.000 1.000
79.340 29.000 1.000
79.400 36.000 1.000
79.460 35.000 1.000
79.520 38.000 1.000
79.580 27.000 1.000
79.640 38.000 1.000
79.700 50.000 1.000
79.760 39.000 1.000
79.820 39.000 1.000
79.880 44.000 1.000
79.940 37.000 1.000
80.000 44.000 1.000
80.060 36.000 1.000
80.120 36.000 1.000
80.180 37.000 1.000
80.240 31.000 1.000
80.300 30.000 1.000
80.360 31.000 1.000
80.420 33.000 1.000
80.480 26.000 1.000
80.540 30.000 1.000
80.600 34.000 1.000
80.660 27.000 1.000
80.720 32.000 1.000
80.780 29.000 1.000
80.840 33.000 1.000
80.900 36.000 1.000
80.960 32.000 1.000
81.020 25.000 1.000
81.080 31.000 1.000
81.140 33.000 1.000
81.200 31.000 1.000
81.260 30.000 1.000
81.320 35.000 1.000
81.380 31.000 1.000
81.440 36.000 1.000
81.500 41.000 1.000
81.560 32.000 1.000
81.620 30.000 1.000
81.680 33.000 1.000
81.740 39.000 1.000
81.800 50.000 1.000
81.860 45.000 1.000
81.920 60.000 1.000
81.980 57.000 1.000
82.040 65.000 1.000
82.100 62.000 1.000
82.160 67.000 1.000
82.220 57.000 1.000
82.280 62.000 1.000
82.340 56.000 1.000
82.400 54.000 1.000
82.460 52.000 1.000
82.520 53.000 1.000
82.580 49.000 1.000
82.640 43.000 1.000
82.700 46.000 1.000
82.760 39.000 1.000
82.820 41.000 1.000
82.880 39.000 1.000
82.940 39.000 1.000
83.000 45.000 1.000
83.060 38.000 1.000
83.120 39.000 1.000
83.180 34.000 1.000
83.240 39.000 1.000
83.300 39.000 1.000
83.360 42.000 1.000
83.420 41.000 1.000
83.480 42.000 1.000
83.540 42.000 1.000
83.600 33.000 1.000
83.660 51.000 1.000
83.720 52.000 1.000
83.780 59.000 1.000
83.840 56.000 1.000
83.900 48.000 1.000
83.960 53.000 1.000
84.020 57.000 1.000
84.080 58.000 1.000
84.140 57.000 1.000
84.200 46.000 1.000
84.260 41.000 1.000
84.320 37.000 1.000
84.380 48.000 1.000
84.440 36.000 1.000
84.500 42.000 1.000
84.560 28.000 1.000
84.620 35.000 1.000
84.680 33.000 1.000
84.740 37.000 1.000
84.800 36.000 1.000
84.860 37.000 1.000
84.920 37.000 1.000
84.980 31.000 1.000
85.040 33.000 1.000
85.100 36.000 1.000
85.160 34.000 1.000
85.220 27.000 1.000
85.280 36.000 1.000
85.340 28.000 1.000
85.400 32.000 1.000
85.460 30.000 1.000
85.520 34.000 1.000
85.580 34.000 1.000
85.640 23.000 1.000
85.700 32.000 1.000
85.760 31.000 1.000
85.820 31.000 1.000
85.880 32.000 1.000
85.940 32.000 1.000
86.000 25.000 1.000
86.060 31.000 1.000
86.120 27.000 1.000
86.180 25.000 1.000
86.240 30.000 1.000
86.300 25.000 1.000
86.360 28.000 1.000
86.420 30.000 1.000
86.480 34.000 1.000
86.540 23.000 1.000
86.600 32.000 1.000
86.660 30.000 1.000
86.720 30.000 1.000
86.780 37.000 1.000
86.840 33.000 1.000
86.900 34.000 1.000
86.960 43.000 1.000
87.020 36.000 1.000
87.080 39.000 1.000
87.140 32.000 1.000
87.200 35.000 1.000
87.260 31.000 1.000
87.320 30.000 1.000
87.380 32.000 1.000
87.440 36.000 1.000
87.500 25.000 1.000
87.560 32.000 1.000
87.620 31.000 1.000
87.680 31.000 1.000
87.740 26.000 1.000
87.800 23.000 1.000
87.860 23.000 1.000
87.920 32.000 1.000
87.980 23.000 1.000
88.040 34.000 1.000
88.100 25.000 1.000
88.160 22.000 1.000
88.220 27.000 1.000
88.280 27.000 1.000
88.340 36.000 1.000
88.400 27.000 1.000
88.460 32.000 1.000
88.520 24.000 1.000
88.580 28.000 1.000
88.640 26.000 1.000
88.700 27.000 1.000
88.760 39.000 1.000
88.820 39.000 1.000
88.880 38.000 1.000
88.940 35.000 1.000
89.000 37.000 1.000
89.060 47.000 1.000
89.120 45.000 1.000
89.180 49.000 1.000
89.240 57.000 1.000
89.300 84.000 1.000
89.360 86.000 1.000
89.420 86.000 1.000
89.480 93.000 1.000
89.540 96.000 1.000
89.600 86.000 1.000
89.660 84.000 1.000
89.720 75.000 1.000
89.780 71.000 1.000
89.840 69.000 1.000
89.900 56.000 1.000
89.960 49.000 1.000
90.000 49.000 1.000
*RAS_INT_END
*RAS_DATA_END