File: ras_to_csv_convert_plot/example/ras/TiO2-1-6h.ras
*RAS_DATA_START
*RAS_HEADER_START
*CORR_POS_DB_NAME "correction_file_060219"
*CORR_POS_GONIO_RADIUS ""
*CORR_POS_NODE_INDEX01 ""
*CORR_POS_NODE_INDEX02 ""
*CORR_POS_NODE_INDEX03 ""
*CORR_POS_NODE_INDEX04 ""
*CORR_POS_NODE_INDEX05 ""
*CORR_POS_NODE_INDEX06 ""
*CORR_POS_NODE_INDEX07 ""
*CORR_POS_NODE_INDEX08 ""
*CORR_POS_NODE_INDEX09 ""
*CORR_POS_NODE_INDEX10 ""
*CORR_POS_NODE_INDEX11 ""
*CORR_POS_NODE_LABEL01 "Si(111)"
*CORR_POS_NODE_LABEL02 "Si(220)"
*CORR_POS_NODE_LABEL03 "Si(311)"
*CORR_POS_NODE_LABEL04 "Si(400)"
*CORR_POS_NODE_LABEL05 "Si(331)"
*CORR_POS_NODE_LABEL06 "Si(422)"
*CORR_POS_NODE_LABEL07 "Si(511)"
*CORR_POS_NODE_LABEL08 "Si(440)"
*CORR_POS_NODE_LABEL09 "Si(531)"
*CORR_POS_NODE_LABEL10 "Si(620)"
*CORR_POS_NODE_LABEL11 "Si(533)"
*CORR_POS_NODE_POS_CALC01 "28.4137"
*CORR_POS_NODE_POS_CALC02 "47.2707"
*CORR_POS_NODE_POS_CALC03 "56.0883"
*CORR_POS_NODE_POS_CALC04 "69.0934"
*CORR_POS_NODE_POS_CALC05 "76.3385"
*CORR_POS_NODE_POS_CALC06 "87.9915"
*CORR_POS_NODE_POS_CALC07 "94.9137"
*CORR_POS_NODE_POS_CALC08 "106.67"
*CORR_POS_NODE_POS_CALC09 "114.054"
*CORR_POS_NODE_POS_CALC10 "127.508"
*CORR_POS_NODE_POS_CALC11 "136.858"
*CORR_POS_NODE_POS_MEAS01 "28.4636"
*CORR_POS_NODE_POS_MEAS02 "47.3217"
*CORR_POS_NODE_POS_MEAS03 "56.1422"
*CORR_POS_NODE_POS_MEAS04 "69.1431"
*CORR_POS_NODE_POS_MEAS05 "76.3906"
*CORR_POS_NODE_POS_MEAS06 "88.0416"
*CORR_POS_NODE_POS_MEAS07 "94.9694"
*CORR_POS_NODE_POS_MEAS08 "106.719"
*CORR_POS_NODE_POS_MEAS09 "114.106"
*CORR_POS_NODE_POS_MEAS10 "127.554"
*CORR_POS_NODE_POS_MEAS11 "136.911"
*CORR_POS_OPT_ATTR "集中法"
*CORR_POS_PARAM_MU ""
*CORR_POS_PARAM_PL ""
*CORR_POS_SEMODEL_TYPE "0"
*CORR_POS_STANDARD_TYPE ""
*CORR_POS_VALUE_ANALYZER "None"
*CORR_POS_VALUE_CMONO "None"
*CORR_POS_VALUE_IMONO "None"
*CORR_POS_VALUE_IS "0.625deg"
*CORR_POS_VALUE_ISL "10.0mm"
*CORR_POS_VALUE_ISOLLER "2.5deg"
*CORR_POS_VALUE_RS1 "13.0mm"
*CORR_POS_VALUE_RS2 "13.0mm"
*CORR_POS_VALUE_RSOLLER "2.5deg"
*CORR_POS_XG_FOCUS_L ""
*CORR_POS_XG_WAVE_TYPE ""
*CORR_POS_XG_WAVE_VALUE ""
*DISP_FMT_X "%.2f"
*DISP_FMT_Y "%.0f"
*DISP_FULLSCALE "17040.0000000000"
*DISP_LINE_COLOR "255.0000000000"
*DISP_LINE_STYLE "0.0000000000"
*DISP_LINE_WIDTH "0.2500000000"
*DISP_NOTE "Collected Data-4"
*DISP_OFFSET_Y "0.0000000000"
*DISP_PEAKSEARCH_UNIT_Y "cps"
*DISP_RANGE_BOTTOM "0.0000000000"
*DISP_RANGE_LEFT "5.0000000000"
*DISP_RANGE_LOGCUTOFF "0.0100000000"
*DISP_RANGE_RIGHT "90.0000000000"
*DISP_RANGE_TOP "17040.0000000000"
*DISP_SCALE_MODE_Y "0.0000000000"
*DISP_TAB_NAME "Theta/2-Theta"
*DISP_TITLE_Y "Intensity"
*DISP_UNIT_Y "cps"
*DISP_WINDOW_NAME "MSG_MACROENGINE"
*FILE_COMMENT " "
*FILE_MD5 ""
*FILE_MEMO " "
*FILE_OPERATOR "sdu_rigaku"
*FILE_SAMPLE "TiO2-1-6h"
*FILE_TYPE "RAS_RAW"
*FILE_USERGROUP "System User"
*FILE_VERSION "1.0000000000"
*HW_ATTACHMENT_ID "ATT1031"
*HW_ATTACHMENT_NAME "6サンプルチェンジャ|ASC-6"
*HW_COUNTER_ID-0 "CUT0025"
*HW_COUNTER_ID-1 "CUT0020"
*HW_COUNTER_ID-2 "CUT0020"
*HW_COUNTER_ID-3 "CMC0021"
*HW_COUNTER_NAME-0 "D/teX Ultra|D/teX Ultra"
*HW_COUNTER_NAME-1 "None|None"
*HW_COUNTER_NAME-2 "None|None"
*HW_COUNTER_NAME-3 "検出器モノクロメータ|Detector monochromator"
*HW_COUNTER_SELECT_NAME "D/teX Ultra|D/teX Ultra"
*HW_GONIOMETER_ID "GON0070"
*HW_GONIOMETER_NAME "MiniFlex 300/600|MiniFlex 300/600"
*HW_GONIOMETER_RADIUS-0 "79.0"
*HW_GONIOMETER_RADIUS-1 "91.5"
*HW_GONIOMETER_RADIUS-2 "150.0"
*HW_GONIOMETER_RADIUS-3 "0"
*HW_GONIOMETER_RADIUS-4 "103.4"
*HW_GONIOMETER_RADIUS-5 "150.0"
*HW_GONIOMETER_RADIUS-6 "46.6"
*HW_GONIOMETER_RADIUS-7 "160.0"
*HW_I_OPT_ID-0 "ISL0021"
*HW_I_OPT_ID-1 "ISO0021"
*HW_I_OPT_NAME-0 "発散スリット|Divergence slit"
*HW_I_OPT_NAME-1 "入射平行スリット|Incident parallel slit"
*HW_R_ATTENUATER_AUTOMODE "0"
*HW_R_OPT_ID-0 "RSS0021"
*HW_R_OPT_ID-1 "RSO0021"
*HW_R_OPT_ID-2 "RRS0021"
*HW_R_OPT_NAME-0 "散乱スリット|Scattering slit"
*HW_R_OPT_NAME-1 "受光平行スリット|Receiving soller slit"
*HW_R_OPT_NAME-2 "受光スリット|Receiving slit"
*HW_SAMPLE_HOLDER_ID "SMP0000"
*HW_SAMPLE_HOLDER_NAME "無し|None"
*HW_XG_CURRENT_MAX "15"
*HW_XG_CURRENT_MIN "2"
*HW_XG_CURRENT_RESOLUTION "1"
*HW_XG_CURRENT_UNIT "mA"
*HW_XG_FOCUS "1mm x 10mm"
*HW_XG_FOCUS_TYPE "Normal"
*HW_XG_ID ""
*HW_XG_NAME "300W/600W 封入管-B|300W/600W Sealed tube-B"
*HW_XG_TARGET_ATOMIC_NUMBER "29.0000000000"
*HW_XG_TARGET_NAME "Cu"
*HW_XG_TYPE "Hermetic"
*HW_XG_VOLTAGE_MAX "40"
*HW_XG_VOLTAGE_MIN "20"
*HW_XG_VOLTAGE_RESOLUTION "1"
*HW_XG_VOLTAGE_UNIT "kV"
*HW_XG_WATT_MAX "1"
*HW_XG_WATT_UNIT "kW"
*HW_XG_WAVE_LENGTH_ALPHA1 "1.540593"
*HW_XG_WAVE_LENGTH_ALPHA2 "1.544414"
*HW_XG_WAVE_LENGTH_BETA "1.392250"
*MEAS_COND_AXIS_NAME-0 "Theta/2-Theta"
*MEAS_COND_AXIS_NAME-1 "Spin"
*MEAS_COND_AXIS_NAME-2 "Change"
*MEAS_COND_AXIS_NAME-3 "Soller(inc.)"
*MEAS_COND_AXIS_NAME-4 "IHS"
*MEAS_COND_AXIS_NAME-5 "DS"
*MEAS_COND_AXIS_NAME-6 "SS"
*MEAS_COND_AXIS_NAME-7 "Soller(rec.)"
*MEAS_COND_AXIS_NAME-8 "RS"
*MEAS_COND_AXIS_NAME-9 "Filter"
*MEAS_COND_AXIS_NAME-10 "Monochromator"
*MEAS_COND_AXIS_NAME-11 "PHA"
*MEAS_COND_AXIS_NAME_INTERNAL-0 "TwoThetaTheta"
*MEAS_COND_AXIS_NAME_INTERNAL-1 "Spin"
*MEAS_COND_AXIS_NAME_INTERNAL-2 "Change"
*MEAS_COND_AXIS_NAME_INTERNAL-3 "IncidentSollerSlit"
*MEAS_COND_AXIS_NAME_INTERNAL-4 "IncidentAxdSlit"
*MEAS_COND_AXIS_NAME_INTERNAL-5 "IncidentSlitBox"
*MEAS_COND_AXIS_NAME_INTERNAL-6 "ReceivingSlitBox1"
*MEAS_COND_AXIS_NAME_INTERNAL-7 "ReceivingSollerSlit"
*MEAS_COND_AXIS_NAME_INTERNAL-8 "ReceivingSlitBox2"
*MEAS_COND_AXIS_NAME_INTERNAL-9 "Filter"
*MEAS_COND_AXIS_NAME_INTERNAL-10 "CounterMonochromator"
*MEAS_COND_AXIS_NAME_INTERNAL-11 "PHA"
*MEAS_COND_AXIS_NAME_MAGICNO-0 "268632064.0000000000"
*MEAS_COND_AXIS_NAME_MAGICNO-1 "16842752.0000000000"
*MEAS_COND_AXIS_NAME_MAGICNO-2 "16842752.0000000000"
*MEAS_COND_AXIS_NAME_MAGICNO-3 "20971521.0000000000"
*MEAS_COND_AXIS_NAME_MAGICNO-4 "22020097.0000000000"
*MEAS_COND_AXIS_NAME_MAGICNO-5 "22020097.0000000000"
*MEAS_COND_AXIS_NAME_MAGICNO-6 "23068673.0000000000"
*MEAS_COND_AXIS_NAME_MAGICNO-7 "20971521.0000000000"
*MEAS_COND_AXIS_NAME_MAGICNO-8 "23068673.0000000000"
*MEAS_COND_AXIS_NAME_MAGICNO-9 "20971521.0000000000"
*MEAS_COND_AXIS_NAME_MAGICNO-10 "20971521.0000000000"
*MEAS_COND_AXIS_NAME_MAGICNO-11 "0.0000000000"
*MEAS_COND_AXIS_OFFSET-0 "0.0000000000"
*MEAS_COND_AXIS_OFFSET-1 "-"
*MEAS_COND_AXIS_OFFSET-2 "-"
*MEAS_COND_AXIS_OFFSET-3 "-"
*MEAS_COND_AXIS_OFFSET-4 "-"
*MEAS_COND_AXIS_OFFSET-5 "-"
*MEAS_COND_AXIS_OFFSET-6 "-"
*MEAS_COND_AXIS_OFFSET-7 "-"
*MEAS_COND_AXIS_OFFSET-8 "-"
*MEAS_COND_AXIS_OFFSET-9 "-"
*MEAS_COND_AXIS_OFFSET-10 "-"
*MEAS_COND_AXIS_OFFSET-11 "-"
*MEAS_COND_AXIS_POSITION-0 "92.5100000000"
*MEAS_COND_AXIS_POSITION-1 "0.0000000000"
*MEAS_COND_AXIS_POSITION-2 "4.0000000000"
*MEAS_COND_AXIS_POSITION-3 "2.5deg"
*MEAS_COND_AXIS_POSITION-4 "10.0mm"
*MEAS_COND_AXIS_POSITION-5 "0.625deg"
*MEAS_COND_AXIS_POSITION-6 "13.0mm"
*MEAS_COND_AXIS_POSITION-7 "2.5deg"
*MEAS_COND_AXIS_POSITION-8 "13.0mm"
*MEAS_COND_AXIS_POSITION-9 "K-beta(x1)"
*MEAS_COND_AXIS_POSITION-10 "None"
*MEAS_COND_AXIS_POSITION-11 "49.0000000000"
*MEAS_COND_AXIS_UNIT-0 "deg"
*MEAS_COND_AXIS_UNIT-1 ""
*MEAS_COND_AXIS_UNIT-2 ""
*MEAS_COND_AXIS_UNIT-3 ""
*MEAS_COND_AXIS_UNIT-4 ""
*MEAS_COND_AXIS_UNIT-5 ""
*MEAS_COND_AXIS_UNIT-6 ""
*MEAS_COND_AXIS_UNIT-7 ""
*MEAS_COND_AXIS_UNIT-8 ""
*MEAS_COND_AXIS_UNIT-9 ""
*MEAS_COND_AXIS_UNIT-10 ""
*MEAS_COND_AXIS_UNIT-11 "div"
*MEAS_COND_CORRECTION_SLIT_COUNTERMONO "None"
*MEAS_COND_CORRECTION_SLIT_DS "0.625deg"
*MEAS_COND_CORRECTION_SLIT_FILTER "None"
*MEAS_COND_CORRECTION_SLIT_IHS "10.0mm"
*MEAS_COND_CORRECTION_SLIT_RS "13.0mm"
*MEAS_COND_CORRECTION_SLIT_SOLLER_INC "2.5deg"
*MEAS_COND_CORRECTION_SLIT_SOLLER_REC "2.5deg"
*MEAS_COND_CORRECTION_SLIT_SS "13.0mm"
*MEAS_COND_COUNTER_CNTLOSS_CORR "0.0000000000"
*MEAS_COND_COUNTER_PHABASE "49.0000000000"
*MEAS_COND_COUNTER_PHAWINDOW "8.0000000000"
*MEAS_COND_COUNTER_PHA_UNIT "div"
*MEAS_COND_COUNTER_TAUDIFF "0.2500000000"
*MEAS_COND_COUNTER_TAUINT "0.7500000000"
*MEAS_COND_IRRADIATION_MODE "OFF"
*MEAS_COND_IRRADIATION_WIDTH ""
*MEAS_COND_OPT_ATTR " "
*MEAS_COND_OPT_NAME ""
*MEAS_COND_UNSYMMETRIC_MODE "OFF"
*MEAS_COND_XG_CURRENT "15.0000000000"
*MEAS_COND_XG_VOLTAGE "40.0000000000"
*MEAS_COND_XG_WAVE_TYPE "Ka"
*MEAS_DATA_COUNT "4251.0000000000"
*MEAS_SCAN_AXIS_X "Theta/2-Theta"
*MEAS_SCAN_AXIS_X_INTERNAL "TwoThetaTheta"
*MEAS_SCAN_END_TIME "02/18/19 13:24:59"
*MEAS_SCAN_MODE "CONTINUOUS"
*MEAS_SCAN_MONITOR "0"
*MEAS_SCAN_RESOLUTION_X "0.005"
*MEAS_SCAN_SPEED "5.000"
*MEAS_SCAN_SPEED_UNIT "deg/min"
*MEAS_SCAN_START "5.0000000000"
*MEAS_SCAN_START_TIME "02/18/19 13:06:36"
*MEAS_SCAN_STEP "0.0200000000"
*MEAS_SCAN_STOP "90.0000000000"
*MEAS_SCAN_UNIT_X "deg"
*MEAS_SCAN_UNIT_Y "counts"
*SLIT_SYSTEM "0"
*RAS_HEADER_END
*RAS_INT_START
5.000 398.000 1.000
5.060 419.000 1.000
5.120 390.000 1.000
5.180 377.000 1.000
5.240 374.000 1.000
5.300 375.000 1.000
5.360 336.000 1.000
5.420 332.000 1.000
5.480 361.000 1.000
5.540 344.000 1.000
5.600 335.000 1.000
5.660 335.000 1.000
5.720 320.000 1.000
5.780 300.000 1.000
5.840 277.000 1.000
5.900 294.000 1.000
5.960 299.000 1.000
6.020 304.000 1.000
6.080 261.000 1.000
6.140 269.000 1.000
6.200 270.000 1.000
6.260 266.000 1.000
6.320 267.000 1.000
6.380 243.000 1.000
6.440 251.000 1.000
6.500 257.000 1.000
6.560 262.000 1.000
6.620 231.000 1.000
6.680 250.000 1.000
6.740 242.000 1.000
6.800 244.000 1.000
6.860 260.000 1.000
6.920 232.000 1.000
6.980 246.000 1.000
7.040 231.000 1.000
7.100 214.000 1.000
7.160 220.000 1.000
7.220 212.000 1.000
7.280 208.000 1.000
7.340 214.000 1.000
7.400 221.000 1.000
7.460 220.000 1.000
7.520 204.000 1.000
7.580 222.000 1.000
7.640 227.000 1.000
7.700 217.000 1.000
7.760 214.000 1.000
7.820 196.000 1.000
7.880 207.000 1.000
7.940 218.000 1.000
8.000 197.000 1.000
8.060 180.000 1.000
8.120 199.000 1.000
8.180 216.000 1.000
8.240 204.000 1.000
8.300 190.000 1.000
8.360 201.000 1.000
8.420 169.000 1.000
8.480 215.000 1.000
8.540 185.000 1.000
8.600 193.000 1.000
8.660 180.000 1.000
8.720 185.000 1.000
8.780 175.000 1.000
8.840 173.000 1.000
8.900 195.000 1.000
8.960 182.000 1.000
9.020 184.000 1.000
9.080 181.000 1.000
9.140 170.000 1.000
9.200 190.000 1.000
9.260 183.000 1.000
9.320 181.000 1.000
9.380 198.000 1.000
9.440 187.000 1.000
9.500 191.000 1.000
9.560 182.000 1.000
9.620 185.000 1.000
9.680 186.000 1.000
9.740 179.000 1.000
9.800 170.000 1.000
9.860 163.000 1.000
9.920 181.000 1.000
9.980 160.000 1.000
10.040 166.000 1.000
10.100 183.000 1.000
10.160 174.000 1.000
10.220 172.000 1.000
10.280 177.000 1.000
10.340 162.000 1.000
10.400 161.000 1.000
10.460 175.000 1.000
10.520 170.000 1.000
10.580 167.000 1.000
10.640 176.000 1.000
10.700 183.000 1.000
10.760 173.000 1.000
10.820 174.000 1.000
10.880 185.000 1.000
10.940 175.000 1.000
11.000 187.000 1.000
11.060 183.000 1.000
11.120 174.000 1.000
11.180 167.000 1.000
11.240 176.000 1.000
11.300 171.000 1.000
11.360 168.000 1.000
11.420 167.000 1.000
11.480 155.000 1.000
11.540 162.000 1.000
11.600 164.000 1.000
11.660 174.000 1.000
11.720 171.000 1.000
11.780 155.000 1.000
11.840 164.000 1.000
11.900 166.000 1.000
11.960 178.000 1.000
12.020 175.000 1.000
12.080 162.000 1.000
12.140 155.000 1.000
12.200 182.000 1.000
12.260 164.000 1.000
12.320 172.000 1.000
12.380 169.000 1.000
12.440 165.000 1.000
12.500 161.000 1.000
12.560 169.000 1.000
12.620 169.000 1.000
12.680 159.000 1.000
12.740 165.000 1.000
12.800 166.000 1.000
12.860 155.000 1.000
12.920 155.000 1.000
12.980 164.000 1.000
13.040 158.000 1.000
13.100 161.000 1.000
13.160 146.000 1.000
13.220 147.000 1.000
13.280 147.000 1.000
13.340 154.000 1.000
13.400 162.000 1.000
13.460 155.000 1.000
13.520 168.000 1.000
13.580 145.000 1.000
13.640 169.000 1.000
13.700 154.000 1.000
13.760 139.000 1.000
13.820 153.000 1.000
13.880 154.000 1.000
13.940 158.000 1.000
14.000 145.000 1.000
14.060 163.000 1.000
14.120 155.000 1.000
14.180 148.000 1.000
14.240 163.000 1.000
14.300 138.000 1.000
14.360 152.000 1.000
14.420 149.000 1.000
14.480 159.000 1.000
14.540 162.000 1.000
14.600 151.000 1.000
14.660 139.000 1.000
14.720 141.000 1.000
14.780 150.000 1.000
14.840 158.000 1.000
14.900 152.000 1.000
14.960 152.000 1.000
15.020 157.000 1.000
15.080 144.000 1.000
15.140 139.000 1.000
15.200 154.000 1.000
15.260 141.000 1.000
15.320 151.000 1.000
15.380 152.000 1.000
15.440 147.000 1.000
15.500 143.000 1.000
15.560 132.000 1.000
15.620 136.000 1.000
15.680 140.000 1.000
15.740 155.000 1.000
15.800 140.000 1.000
15.860 143.000 1.000
15.920 139.000 1.000
15.980 144.000 1.000
16.040 140.000 1.000
16.100 131.000 1.000
16.160 131.000 1.000
16.220 139.000 1.000
16.280 124.000 1.000
16.340 126.000 1.000
16.400 117.000 1.000
16.460 137.000 1.000
16.520 138.000 1.000
16.580 144.000 1.000
16.640 141.000 1.000
16.700 144.000 1.000
16.760 139.000 1.000
16.820 131.000 1.000
16.880 136.000 1.000
16.940 130.000 1.000
17.000 141.000 1.000
17.060 134.000 1.000
17.120 132.000 1.000
17.180 125.000 1.000
17.240 118.000 1.000
17.300 139.000 1.000
17.360 139.000 1.000
17.420 121.000 1.000
17.480 128.000 1.000
17.540 131.000 1.000
17.600 131.000 1.000
17.660 140.000 1.000
17.720 134.000 1.000
17.780 128.000 1.000
17.840 122.000 1.000
17.900 119.000 1.000
17.960 122.000 1.000
18.020 119.000 1.000
18.080 125.000 1.000
18.140 125.000 1.000
18.200 118.000 1.000
18.260 134.000 1.000
18.320 127.000 1.000
18.380 128.000 1.000
18.440 111.000 1.000
18.500 125.000 1.000
18.560 129.000 1.000
18.620 120.000 1.000
18.680 130.000 1.000
18.740 119.000 1.000
18.800 118.000 1.000
18.860 115.000 1.000
18.920 124.000 1.000
18.980 123.000 1.000
19.040 122.000 1.000
19.100 113.000 1.000
19.160 126.000 1.000
19.220 123.000 1.000
19.280 114.000 1.000
19.340 107.000 1.000
19.400 123.000 1.000
19.460 119.000 1.000
19.520 116.000 1.000
19.580 111.000 1.000
19.640 109.000 1.000
19.700 121.000 1.000
19.760 111.000 1.000
19.820 123.000 1.000
19.880 127.000 1.000
19.940 111.000 1.000
20.000 104.000 1.000
20.060 105.000 1.000
20.120 114.000 1.000
20.180 115.000 1.000
20.240 126.000 1.000
20.300 114.000 1.000
20.360 114.000 1.000
20.420 113.000 1.000
20.480 118.000 1.000
20.540 118.000 1.000
20.600 111.000 1.000
20.660 106.000 1.000
20.720 120.000 1.000
20.780 103.000 1.000
20.840 98.000 1.000
20.900 124.000 1.000
20.960 109.000 1.000
21.020 103.000 1.000
21.080 112.000 1.000
21.140 116.000 1.000
21.200 117.000 1.000
21.260 106.000 1.000
21.320 111.000 1.000
21.380 114.000 1.000
21.440 107.000 1.000
21.500 114.000 1.000
21.560 123.000 1.000
21.620 121.000 1.000
21.680 101.000 1.000
21.740 121.000 1.000
21.800 109.000 1.000
21.860 120.000 1.000
21.920 108.000 1.000
21.980 130.000 1.000
22.040 107.000 1.000
22.100 97.000 1.000
22.160 113.000 1.000
22.220 115.000 1.000
22.280 113.000 1.000
22.340 103.000 1.000
22.400 112.000 1.000
22.460 96.000 1.000
22.520 111.000 1.000
22.580 109.000 1.000
22.640 106.000 1.000
22.700 116.000 1.000
22.760 113.000 1.000
22.820 123.000 1.000
22.880 110.000 1.000
22.940 113.000 1.000
23.000 123.000 1.000
23.060 107.000 1.000
23.120 111.000 1.000
23.180 110.000 1.000
23.240 107.000 1.000
23.300 122.000 1.000
23.360 102.000 1.000
23.420 106.000 1.000
23.480 110.000 1.000
23.540 117.000 1.000
23.600 120.000 1.000
23.660 107.000 1.000
23.720 107.000 1.000
23.780 124.000 1.000
23.840 112.000 1.000
23.900 99.000 1.000
23.960 100.000 1.000
24.020 106.000 1.000
24.080 117.000 1.000
24.140 117.000 1.000
24.200 117.000 1.000
24.260 122.000 1.000
24.320 130.000 1.000
24.380 124.000 1.000
24.440 140.000 1.000
24.500 132.000 1.000
24.560 131.000 1.000
24.620 139.000 1.000
24.680 145.000 1.000
24.740 182.000 1.000
24.800 185.000 1.000
24.860 151.000 1.000
24.920 182.000 1.000
24.980 191.000 1.000
25.040 178.000 1.000
25.100 196.000 1.000
25.160 183.000 1.000
25.220 192.000 1.000
25.280 193.000 1.000
25.340 173.000 1.000
25.400 191.000 1.000
25.460 195.000 1.000
25.520 206.000 1.000
25.580 227.000 1.000
25.640 201.000 1.000
25.700 209.000 1.000
25.760 216.000 1.000
25.820 206.000 1.000
25.880 195.000 1.000
25.940 203.000 1.000
26.000 185.000 1.000
26.060 179.000 1.000
26.120 184.000 1.000
26.180 191.000 1.000
26.240 221.000 1.000
26.300 197.000 1.000
26.360 198.000 1.000
26.420 207.000 1.000
26.480 220.000 1.000
26.540 231.000 1.000
26.600 223.000 1.000
26.660 258.000 1.000
26.720 255.000 1.000
26.780 317.000 1.000
26.840 336.000 1.000
26.900 378.000 1.000
26.960 448.000 1.000
27.020 530.000 1.000
27.080 667.000 1.000
27.140 882.000 1.000
27.200 1305.000 1.000
27.260 1937.000 1.000
27.320 2770.000 1.000
27.380 3251.000 1.000
27.440 3244.000 1.000
27.500 2745.000 1.000
27.560 2059.000 1.000
27.620 1432.000 1.000
27.680 968.000 1.000
27.740 740.000 1.000
27.800 556.000 1.000
27.860 453.000 1.000
27.920 372.000 1.000
27.980 317.000 1.000
28.040 306.000 1.000
28.100 275.000 1.000
28.160 218.000 1.000
28.220 213.000 1.000
28.280 182.000 1.000
28.340 199.000 1.000
28.400 188.000 1.000
28.460 168.000 1.000
28.520 153.000 1.000
28.580 157.000 1.000
28.640 145.000 1.000
28.700 128.000 1.000
28.760 124.000 1.000
28.820 137.000 1.000
28.880 124.000 1.000
28.940 139.000 1.000
29.000 124.000 1.000
29.060 121.000 1.000
29.120 116.000 1.000
29.180 118.000 1.000
29.240 106.000 1.000
29.300 106.000 1.000
29.360 107.000 1.000
29.420 105.000 1.000
29.480 103.000 1.000
29.540 101.000 1.000
29.600 112.000 1.000
29.660 92.000 1.000
29.720 99.000 1.000
29.780 109.000 1.000
29.840 99.000 1.000
29.900 98.000 1.000
29.960 100.000 1.000
30.020 105.000 1.000
30.080 100.000 1.000
30.140 114.000 1.000
30.200 112.000 1.000
30.260 118.000 1.000
30.320 108.000 1.000
30.380 111.000 1.000
30.440 102.000 1.000
30.500 111.000 1.000
30.560 110.000 1.000
30.620 111.000 1.000
30.680 126.000 1.000
30.740 118.000 1.000
30.800 121.000 1.000
30.860 131.000 1.000
30.920 111.000 1.000
30.980 118.000 1.000
31.040 127.000 1.000
31.100 101.000 1.000
31.160 99.000 1.000
31.220 99.000 1.000
31.280 103.000 1.000
31.340 113.000 1.000
31.400 99.000 1.000
31.460 102.000 1.000
31.520 90.000 1.000
31.580 100.000 1.000
31.640 90.000 1.000
31.700 85.000 1.000
31.760 71.000 1.000
31.820 78.000 1.000
31.880 89.000 1.000
31.940 77.000 1.000
32.000 76.000 1.000
32.060 84.000 1.000
32.120 69.000 1.000
32.180 78.000 1.000
32.240 83.000 1.000
32.300 77.000 1.000
32.360 77.000 1.000
32.420 85.000 1.000
32.480 70.000 1.000
32.540 76.000 1.000
32.600 76.000 1.000
32.660 69.000 1.000
32.720 74.000 1.000
32.780 67.000 1.000
32.840 74.000 1.000
32.900 75.000 1.000
32.960 76.000 1.000
33.020 82.000 1.000
33.080 73.000 1.000
33.140 81.000 1.000
33.200 61.000 1.000
33.260 67.000 1.000
33.320 70.000 1.000
33.380 72.000 1.000
33.440 71.000 1.000
33.500 65.000 1.000
33.560 75.000 1.000
33.620 76.000 1.000
33.680 70.000 1.000
33.740 62.000 1.000
33.800 70.000 1.000
33.860 76.000 1.000
33.920 71.000 1.000
33.980 79.000 1.000
34.040 63.000 1.000
34.100 81.000 1.000
34.160 55.000 1.000
34.220 76.000 1.000
34.280 67.000 1.000
34.340 64.000 1.000
34.400 73.000 1.000
34.460 76.000 1.000
34.520 70.000 1.000
34.580 76.000 1.000
34.640 86.000 1.000
34.700 72.000 1.000
34.760 80.000 1.000
34.820 80.000 1.000
34.880 91.000 1.000
34.940 91.000 1.000
35.000 94.000 1.000
35.060 84.000 1.000
35.120 99.000 1.000
35.180 115.000 1.000
35.240 109.000 1.000
35.300 117.000 1.000
35.360 109.000 1.000
35.420 110.000 1.000
35.480 143.000 1.000
35.540 146.000 1.000
35.600 169.000 1.000
35.660 183.000 1.000
35.720 221.000 1.000
35.780 268.000 1.000
35.840 344.000 1.000
35.900 471.000 1.000
35.960 758.000 1.000
36.020 1242.000 1.000
36.080 1706.000 1.000
36.140 1655.000 1.000
36.200 1181.000 1.000
36.260 749.000 1.000
36.320 490.000 1.000
36.380 317.000 1.000
36.440 245.000 1.000
36.500 215.000 1.000
36.560 188.000 1.000
36.620 156.000 1.000
36.680 125.000 1.000
36.740 127.000 1.000
36.800 114.000 1.000
36.860 118.000 1.000
36.920 101.000 1.000
36.980 105.000 1.000
37.040 115.000 1.000
37.100 105.000 1.000
37.160 102.000 1.000
37.220 98.000 1.000
37.280 81.000 1.000
37.340 90.000 1.000
37.400 96.000 1.000
37.460 94.000 1.000
37.520 85.000 1.000
37.580 81.000 1.000
37.640 84.000 1.000
37.700 97.000 1.000
37.760 85.000 1.000
37.820 91.000 1.000
37.880 73.000 1.000
37.940 82.000 1.000
38.000 79.000 1.000
38.060 79.000 1.000
38.120 80.000 1.000
38.180 85.000 1.000
38.240 75.000 1.000
38.300 77.000 1.000
38.360 71.000 1.000
38.420 78.000 1.000
38.480 83.000 1.000
38.540 81.000 1.000
38.600 86.000 1.000
38.660 94.000 1.000
38.720 93.000 1.000
38.780 96.000 1.000
38.840 120.000 1.000
38.900 123.000 1.000
38.960 141.000 1.000
39.020 172.000 1.000
39.080 225.000 1.000
39.140 230.000 1.000
39.200 222.000 1.000
39.260 177.000 1.000
39.320 153.000 1.000
39.380 127.000 1.000
39.440 119.000 1.000
39.500 108.000 1.000
39.560 89.000 1.000
39.620 97.000 1.000
39.680 99.000 1.000
39.740 88.000 1.000
39.800 80.000 1.000
39.860 97.000 1.000
39.920 88.000 1.000
39.980 80.000 1.000
40.040 78.000 1.000
40.100 83.000 1.000
40.160 88.000 1.000
40.220 89.000 1.000
40.280 84.000 1.000
40.340 94.000 1.000
40.400 89.000 1.000
40.460 77.000 1.000
40.520 77.000 1.000
40.580 94.000 1.000
40.640 86.000 1.000
40.700 102.000 1.000
40.760 123.000 1.000
40.820 116.000 1.000
40.880 138.000 1.000
40.940 149.000 1.000
41.000 209.000 1.000
41.060 309.000 1.000
41.120 538.000 1.000
41.180 767.000 1.000
41.240 879.000 1.000
41.300 778.000 1.000
41.360 595.000 1.000
41.420 375.000 1.000
41.480 265.000 1.000
41.540 182.000 1.000
41.600 147.000 1.000
41.660 111.000 1.000
41.720 94.000 1.000
41.780 98.000 1.000
41.840 90.000 1.000
41.900 71.000 1.000
41.960 72.000 1.000
42.020 80.000 1.000
42.080 70.000 1.000
42.140 65.000 1.000
42.200 62.000 1.000
42.260 66.000 1.000
42.320 79.000 1.000
42.380 73.000 1.000
42.440 64.000 1.000
42.500 73.000 1.000
42.560 68.000 1.000
42.620 75.000 1.000
42.680 72.000 1.000
42.740 70.000 1.000
42.800 68.000 1.000
42.860 51.000 1.000
42.920 69.000 1.000
42.980 74.000 1.000
43.040 62.000 1.000
43.100 67.000 1.000
43.160 54.000 1.000
43.220 67.000 1.000
43.280 62.000 1.000
43.340 66.000 1.000
43.400 65.000 1.000
43.460 80.000 1.000
43.520 83.000 1.000
43.580 79.000 1.000
43.640 106.000 1.000
43.700 122.000 1.000
43.760 142.000 1.000
43.820 191.000 1.000
43.880 244.000 1.000
43.940 259.000 1.000
44.000 266.000 1.000
44.060 253.000 1.000
44.120 208.000 1.000
44.180 156.000 1.000
44.240 128.000 1.000
44.300 108.000 1.000
44.360 91.000 1.000
44.420 78.000 1.000
44.480 63.000 1.000
44.540 64.000 1.000
44.600 62.000 1.000
44.660 70.000 1.000
44.720 59.000 1.000
44.780 62.000 1.000
44.840 55.000 1.000
44.900 49.000 1.000
44.960 58.000 1.000
45.020 52.000 1.000
45.080 54.000 1.000
45.140 53.000 1.000
45.200 54.000 1.000
45.260 51.000 1.000
45.320 55.000 1.000
45.380 53.000 1.000
45.440 47.000 1.000
45.500 60.000 1.000
45.560 52.000 1.000
45.620 61.000 1.000
45.680 54.000 1.000
45.740 60.000 1.000
45.800 53.000 1.000
45.860 61.000 1.000
45.920 49.000 1.000
45.980 56.000 1.000
46.040 61.000 1.000
46.100 59.000 1.000
46.160 48.000 1.000
46.220 62.000 1.000
46.280 59.000 1.000
46.340 52.000 1.000
46.400 53.000 1.000
46.460 53.000 1.000
46.520 52.000 1.000
46.580 57.000 1.000
46.640 50.000 1.000
46.700 48.000 1.000
46.760 52.000 1.000
46.820 53.000 1.000
46.880 55.000 1.000
46.940 46.000 1.000
47.000 46.000 1.000
47.060 59.000 1.000
47.120 43.000 1.000
47.180 51.000 1.000
47.240 59.000 1.000
47.300 59.000 1.000
47.360 54.000 1.000
47.420 62.000 1.000
47.480 62.000 1.000
47.540 60.000 1.000
47.600 53.000 1.000
47.660 64.000 1.000
47.720 58.000 1.000
47.780 56.000 1.000
47.840 57.000 1.000
47.900 64.000 1.000
47.960 69.000 1.000
48.020 69.000 1.000
48.080 57.000 1.000
48.140 63.000 1.000
48.200 61.000 1.000
48.260 65.000 1.000
48.320 53.000 1.000
48.380 55.000 1.000
48.440 65.000 1.000
48.500 55.000 1.000
48.560 52.000 1.000
48.620 58.000 1.000
48.680 75.000 1.000
48.740 54.000 1.000
48.800 52.000 1.000
48.860 72.000 1.000
48.920 70.000 1.000
48.980 65.000 1.000
49.040 52.000 1.000
49.100 55.000 1.000
49.160 50.000 1.000
49.220 56.000 1.000
49.280 64.000 1.000
49.340 58.000 1.000
49.400 58.000 1.000
49.460 52.000 1.000
49.520 50.000 1.000
49.580 59.000 1.000
49.640 44.000 1.000
49.700 58.000 1.000
49.760 49.000 1.000
49.820 46.000 1.000
49.880 45.000 1.000
49.940 48.000 1.000
50.000 46.000 1.000
50.060 46.000 1.000
50.120 50.000 1.000
50.180 43.000 1.000
50.240 44.000 1.000
50.300 46.000 1.000
50.360 45.000 1.000
50.420 51.000 1.000
50.480 44.000 1.000
50.540 40.000 1.000
50.600 52.000 1.000
50.660 44.000 1.000
50.720 41.000 1.000
50.780 48.000 1.000
50.840 42.000 1.000
50.900 35.000 1.000
50.960 41.000 1.000
51.020 47.000 1.000
51.080 49.000 1.000
51.140 43.000 1.000
51.200 44.000 1.000
51.260 51.000 1.000
51.320 49.000 1.000
51.380 55.000 1.000
51.440 45.000 1.000
51.500 45.000 1.000
51.560 42.000 1.000
51.620 55.000 1.000
51.680 42.000 1.000
51.740 54.000 1.000
51.800 48.000 1.000
51.860 47.000 1.000
51.920 51.000 1.000
51.980 56.000 1.000
52.040 62.000 1.000
52.100 56.000 1.000
52.160 50.000 1.000
52.220 65.000 1.000
52.280 60.000 1.000
52.340 64.000 1.000
52.400 58.000 1.000
52.460 69.000 1.000
52.520 60.000 1.000
52.580 71.000 1.000
52.640 70.000 1.000
52.700 68.000 1.000
52.760 73.000 1.000
52.820 63.000 1.000
52.880 72.000 1.000
52.940 76.000 1.000
53.000 84.000 1.000
53.060 70.000 1.000
53.120 89.000 1.000
53.180 91.000 1.000
53.240 95.000 1.000
53.300 102.000 1.000
53.360 120.000 1.000
53.420 119.000 1.000
53.480 120.000 1.000
53.540 134.000 1.000
53.600 140.000 1.000
53.660 167.000 1.000
53.720 185.000 1.000
53.780 189.000 1.000
53.840 251.000 1.000
53.900 298.000 1.000
53.960 379.000 1.000
54.020 517.000 1.000
54.080 754.000 1.000
54.140 1075.000 1.000
54.200 1460.000 1.000
54.260 1612.000 1.000
54.320 1612.000 1.000
54.380 1395.000 1.000
54.440 1099.000 1.000
54.500 842.000 1.000
54.560 603.000 1.000
54.620 446.000 1.000
54.680 352.000 1.000
54.740 301.000 1.000
54.800 257.000 1.000
54.860 202.000 1.000
54.920 198.000 1.000
54.980 163.000 1.000
55.040 158.000 1.000
55.100 156.000 1.000
55.160 123.000 1.000
55.220 135.000 1.000
55.280 128.000 1.000
55.340 124.000 1.000
55.400 112.000 1.000
55.460 109.000 1.000
55.520 104.000 1.000
55.580 111.000 1.000
55.640 108.000 1.000
55.700 105.000 1.000
55.760 104.000 1.000
55.820 98.000 1.000
55.880 104.000 1.000
55.940 116.000 1.000
56.000 114.000 1.000
56.060 124.000 1.000
56.120 145.000 1.000
56.180 137.000 1.000
56.240 220.000 1.000
56.300 259.000 1.000
56.360 356.000 1.000
56.420 441.000 1.000
56.480 501.000 1.000
56.540 539.000 1.000
56.600 517.000 1.000
56.660 404.000 1.000
56.720 340.000 1.000
56.780 272.000 1.000
56.840 202.000 1.000
56.900 163.000 1.000
56.960 138.000 1.000
57.020 114.000 1.000
57.080 107.000 1.000
57.140 94.000 1.000
57.200 95.000 1.000
57.260 103.000 1.000
57.320 85.000 1.000
57.380 75.000 1.000
57.440 69.000 1.000
57.500 67.000 1.000
57.560 68.000 1.000
57.620 79.000 1.000
57.680 65.000 1.000
57.740 65.000 1.000
57.800 66.000 1.000
57.860 51.000 1.000
57.920 56.000 1.000
57.980 54.000 1.000
58.040 57.000 1.000
58.100 57.000 1.000
58.160 57.000 1.000
58.220 50.000 1.000
58.280 52.000 1.000
58.340 50.000 1.000
58.400 45.000 1.000
58.460 51.000 1.000
58.520 45.000 1.000
58.580 51.000 1.000
58.640 46.000 1.000
58.700 50.000 1.000
58.760 47.000 1.000
58.820 42.000 1.000
58.880 40.000 1.000
58.940 47.000 1.000
59.000 51.000 1.000
59.060 44.000 1.000
59.120 44.000 1.000
59.180 50.000 1.000
59.240 57.000 1.000
59.300 39.000 1.000
59.360 42.000 1.000
59.420 47.000 1.000
59.480 48.000 1.000
59.540 43.000 1.000
59.600 40.000 1.000
59.660 40.000 1.000
59.720 47.000 1.000
59.780 46.000 1.000
59.840 41.000 1.000
59.900 44.000 1.000
59.960 45.000 1.000
60.020 44.000 1.000
60.080 43.000 1.000
60.140 46.000 1.000
60.200 49.000 1.000
60.260 42.000 1.000
60.320 49.000 1.000
60.380 48.000 1.000
60.440 44.000 1.000
60.500 42.000 1.000
60.560 44.000 1.000
60.620 44.000 1.000
60.680 46.000 1.000
60.740 47.000 1.000
60.800 38.000 1.000
60.860 40.000 1.000
60.920 46.000 1.000
60.980 45.000 1.000
61.040 46.000 1.000
61.100 41.000 1.000
61.160 45.000 1.000
61.220 44.000 1.000
61.280 49.000 1.000
61.340 42.000 1.000
61.400 43.000 1.000
61.460 51.000 1.000
61.520 53.000 1.000
61.580 47.000 1.000
61.640 48.000 1.000
61.700 54.000 1.000
61.760 52.000 1.000
61.820 37.000 1.000
61.880 53.000 1.000
61.940 49.000 1.000
62.000 56.000 1.000
62.060 60.000 1.000
62.120 44.000 1.000
62.180 52.000 1.000
62.240 62.000 1.000
62.300 52.000 1.000
62.360 66.000 1.000
62.420 69.000 1.000
62.480 66.000 1.000
62.540 82.000 1.000
62.600 110.000 1.000
62.660 139.000 1.000
62.720 226.000 1.000
62.780 390.000 1.000
62.840 354.000 1.000
62.900 250.000 1.000
62.960 267.000 1.000
63.020 211.000 1.000
63.080 148.000 1.000
63.140 100.000 1.000
63.200 86.000 1.000
63.260 86.000 1.000
63.320 84.000 1.000
63.380 76.000 1.000
63.440 86.000 1.000
63.500 89.000 1.000
63.560 97.000 1.000
63.620 106.000 1.000
63.680 132.000 1.000
63.740 137.000 1.000
63.800 190.000 1.000
63.860 212.000 1.000
63.920 246.000 1.000
63.980 243.000 1.000
64.040 218.000 1.000
64.100 202.000 1.000
64.160 184.000 1.000
64.220 148.000 1.000
64.280 124.000 1.000
64.340 103.000 1.000
64.400 90.000 1.000
64.460 80.000 1.000
64.520 72.000 1.000
64.580 81.000 1.000
64.640 74.000 1.000
64.700 66.000 1.000
64.760 56.000 1.000
64.820 66.000 1.000
64.880 63.000 1.000
64.940 63.000 1.000
65.000 65.000 1.000
65.060 59.000 1.000
65.120 54.000 1.000
65.180 62.000 1.000
65.240 60.000 1.000
65.300 62.000 1.000
65.360 53.000 1.000
65.420 66.000 1.000
65.480 67.000 1.000
65.540 62.000 1.000
65.600 48.000 1.000
65.660 65.000 1.000
65.720 56.000 1.000
65.780 43.000 1.000
65.840 53.000 1.000
65.900 53.000 1.000
65.960 51.000 1.000
66.020 52.000 1.000
66.080 46.000 1.000
66.140 51.000 1.000
66.200 50.000 1.000
66.260 45.000 1.000
66.320 46.000 1.000
66.380 41.000 1.000
66.440 43.000 1.000
66.500 52.000 1.000
66.560 40.000 1.000
66.620 44.000 1.000
66.680 45.000 1.000
66.740 40.000 1.000
66.800 47.000 1.000
66.860 41.000 1.000
66.920 39.000 1.000
66.980 45.000 1.000
67.040 51.000 1.000
67.100 46.000 1.000
67.160 42.000 1.000
67.220 45.000 1.000
67.280 41.000 1.000
67.340 42.000 1.000
67.400 55.000 1.000
67.460 56.000 1.000
67.520 58.000 1.000
67.580 52.000 1.000
67.640 48.000 1.000
67.700 57.000 1.000
67.760 53.000 1.000
67.820 62.000 1.000
67.880 56.000 1.000
67.940 59.000 1.000
68.000 55.000 1.000
68.060 57.000 1.000
68.120 71.000 1.000
68.180 81.000 1.000
68.240 96.000 1.000
68.300 75.000 1.000
68.360 98.000 1.000
68.420 115.000 1.000
68.480 124.000 1.000
68.540 166.000 1.000
68.600 188.000 1.000
68.660 210.000 1.000
68.720 303.000 1.000
68.780 396.000 1.000
68.840 457.000 1.000
68.900 513.000 1.000
68.960 464.000 1.000
69.020 423.000 1.000
69.080 411.000 1.000
69.140 351.000 1.000
69.200 273.000 1.000
69.260 204.000 1.000
69.320 190.000 1.000
69.380 165.000 1.000
69.440 148.000 1.000
69.500 139.000 1.000
69.560 143.000 1.000
69.620 181.000 1.000
69.680 214.000 1.000
69.740 293.000 1.000
69.800 357.000 1.000
69.860 319.000 1.000
69.920 301.000 1.000
69.980 246.000 1.000
70.040 233.000 1.000
70.100 165.000 1.000
70.160 127.000 1.000
70.220 103.000 1.000
70.280 89.000 1.000
70.340 73.000 1.000
70.400 69.000 1.000
70.460 63.000 1.000
70.520 60.000 1.000
70.580 61.000 1.000
70.640 55.000 1.000
70.700 61.000 1.000
70.760 47.000 1.000
70.820 52.000 1.000
70.880 48.000 1.000
70.940 49.000 1.000
71.000 42.000 1.000
71.060 48.000 1.000
71.120 44.000 1.000
71.180 44.000 1.000
71.240 40.000 1.000
71.300 44.000 1.000
71.360 39.000 1.000
71.420 45.000 1.000
71.480 37.000 1.000
71.540 44.000 1.000
71.600 42.000 1.000
71.660 42.000 1.000
71.720 45.000 1.000
71.780 44.000 1.000
71.840 41.000 1.000
71.900 44.000 1.000
71.960 52.000 1.000
72.020 49.000 1.000
72.080 48.000 1.000
72.140 58.000 1.000
72.200 49.000 1.000
72.260 53.000 1.000
72.320 69.000 1.000
72.380 61.000 1.000
72.440 60.000 1.000
72.500 61.000 1.000
72.560 46.000 1.000
72.620 46.000 1.000
72.680 44.000 1.000
72.740 40.000 1.000
72.800 34.000 1.000
72.860 40.000 1.000
72.920 37.000 1.000
72.980 38.000 1.000
73.040 30.000 1.000
73.100 36.000 1.000
73.160 39.000 1.000
73.220 38.000 1.000
73.280 34.000 1.000
73.340 30.000 1.000
73.400 35.000 1.000
73.460 33.000 1.000
73.520 32.000 1.000
73.580 32.000 1.000
73.640 35.000 1.000
73.700 35.000 1.000
73.760 30.000 1.000
73.820 37.000 1.000
73.880 37.000 1.000
73.940 34.000 1.000
74.000 32.000 1.000
74.060 38.000 1.000
74.120 35.000 1.000
74.180 37.000 1.000
74.240 41.000 1.000
74.300 37.000 1.000
74.360 41.000 1.000
74.420 42.000 1.000
74.480 32.000 1.000
74.540 37.000 1.000
74.600 29.000 1.000
74.660 36.000 1.000
74.720 29.000 1.000
74.780 32.000 1.000
74.840 34.000 1.000
74.900 32.000 1.000
74.960 33.000 1.000
75.020 31.000 1.000
75.080 32.000 1.000
75.140 29.000 1.000
75.200 34.000 1.000
75.260 33.000 1.000
75.320 38.000 1.000
75.380 32.000 1.000
75.440 38.000 1.000
75.500 28.000 1.000
75.560 43.000 1.000
75.620 38.000 1.000
75.680 33.000 1.000
75.740 31.000 1.000
75.800 35.000 1.000
75.860 37.000 1.000
75.920 30.000 1.000
75.980 31.000 1.000
76.040 34.000 1.000
76.100 42.000 1.000
76.160 40.000 1.000
76.220 36.000 1.000
76.280 47.000 1.000
76.340 49.000 1.000
76.400 63.000 1.000
76.460 71.000 1.000
76.520 80.000 1.000
76.580 83.000 1.000
76.640 76.000 1.000
76.700 75.000 1.000
76.760 64.000 1.000
76.820 62.000 1.000
76.880 47.000 1.000
76.940 52.000 1.000
77.000 40.000 1.000
77.060 34.000 1.000
77.120 40.000 1.000
77.180 27.000 1.000
77.240 34.000 1.000
77.300 32.000 1.000
77.360 30.000 1.000
77.420 29.000 1.000
77.480 29.000 1.000
77.540 25.000 1.000
77.600 27.000 1.000
77.660 31.000 1.000
77.720 31.000 1.000
77.780 27.000 1.000
77.840 32.000 1.000
77.900 32.000 1.000
77.960 33.000 1.000
78.020 32.000 1.000
78.080 25.000 1.000
78.140 35.000 1.000
78.200 31.000 1.000
78.260 29.000 1.000
78.320 37.000 1.000
78.380 30.000 1.000
78.440 28.000 1.000
78.500 24.000 1.000
78.560 26.000 1.000
78.620 30.000 1.000
78.680 23.000 1.000
78.740 31.000 1.000
78.800 25.000 1.000
78.860 37.000 1.000
78.920 31.000 1.000
78.980 31.000 1.000
79.040 27.000 1.000
79.100 28.000 1.000
79.160 26.000 1.000
79.220 32.000 1.000
79.280 38.000 1.000
79.340 29.000 1.000
79.400 33.000 1.000
79.460 38.000 1.000
79.520 33.000 1.000
79.580 41.000 1.000
79.640 49.000 1.000
79.700 44.000 1.000
79.760 60.000 1.000
79.820 56.000 1.000
79.880 51.000 1.000
79.940 54.000 1.000
80.000 51.000 1.000
80.060 51.000 1.000
80.120 36.000 1.000
80.180 40.000 1.000
80.240 35.000 1.000
80.300 31.000 1.000
80.360 32.000 1.000
80.420 38.000 1.000
80.480 36.000 1.000
80.540 34.000 1.000
80.600 31.000 1.000
80.660 36.000 1.000
80.720 35.000 1.000
80.780 35.000 1.000
80.840 37.000 1.000
80.900 34.000 1.000
80.960 35.000 1.000
81.020 30.000 1.000
81.080 31.000 1.000
81.140 30.000 1.000
81.200 30.000 1.000
81.260 41.000 1.000
81.320 31.000 1.000
81.380 35.000 1.000
81.440 29.000 1.000
81.500 33.000 1.000
81.560 33.000 1.000
81.620 40.000 1.000
81.680 41.000 1.000
81.740 43.000 1.000
81.800 45.000 1.000
81.860 53.000 1.000
81.920 57.000 1.000
81.980 80.000 1.000
82.040 89.000 1.000
82.100 100.000 1.000
82.160 105.000 1.000
82.220 117.000 1.000
82.280 110.000 1.000
82.340 110.000 1.000
82.400 95.000 1.000
82.460 88.000 1.000
82.520 75.000 1.000
82.580 57.000 1.000
82.640 55.000 1.000
82.700 56.000 1.000
82.760 55.000 1.000
82.820 45.000 1.000
82.880 47.000 1.000
82.940 41.000 1.000
83.000 43.000 1.000
83.060 49.000 1.000
83.120 40.000 1.000
83.180 46.000 1.000
83.240 46.000 1.000
83.300 44.000 1.000
83.360 44.000 1.000
83.420 46.000 1.000
83.480 41.000 1.000
83.540 52.000 1.000
83.600 39.000 1.000
83.660 47.000 1.000
83.720 53.000 1.000
83.780 56.000 1.000
83.840 58.000 1.000
83.900 81.000 1.000
83.960 77.000 1.000
84.020 90.000 1.000
84.080 79.000 1.000
84.140 83.000 1.000
84.200 70.000 1.000
84.260 82.000 1.000
84.320 65.000 1.000
84.380 62.000 1.000
84.440 67.000 1.000
84.500 47.000 1.000
84.560 50.000 1.000
84.620 44.000 1.000
84.680 44.000 1.000
84.740 39.000 1.000
84.800 37.000 1.000
84.860 34.000 1.000
84.920 30.000 1.000
84.980 49.000 1.000
85.040 30.000 1.000
85.100 38.000 1.000
85.160 32.000 1.000
85.220 36.000 1.000
85.280 35.000 1.000
85.340 38.000 1.000
85.400 34.000 1.000
85.460 27.000 1.000
85.520 32.000 1.000
85.580 31.000 1.000
85.640 37.000 1.000
85.700 30.000 1.000
85.760 37.000 1.000
85.820 28.000 1.000
85.880 40.000 1.000
85.940 29.000 1.000
86.000 31.000 1.000
86.060 32.000 1.000
86.120 36.000 1.000
86.180 29.000 1.000
86.240 32.000 1.000
86.300 31.000 1.000
86.360 31.000 1.000
86.420 29.000 1.000
86.480 34.000 1.000
86.540 35.000 1.000
86.600 41.000 1.000
86.660 29.000 1.000
86.720 38.000 1.000
86.780 34.000 1.000
86.840 33.000 1.000
86.900 40.000 1.000
86.960 31.000 1.000
87.020 44.000 1.000
87.080 36.000 1.000
87.140 49.000 1.000
87.200 49.000 1.000
87.260 53.000 1.000
87.320 52.000 1.000
87.380 55.000 1.000
87.440 43.000 1.000
87.500 47.000 1.000
87.560 48.000 1.000
87.620 47.000 1.000
87.680 44.000 1.000
87.740 44.000 1.000
87.800 36.000 1.000
87.860 35.000 1.000
87.920 33.000 1.000
87.980 36.000 1.000
88.040 27.000 1.000
88.100 30.000 1.000
88.160 28.000 1.000
88.220 33.000 1.000
88.280 36.000 1.000
88.340 35.000 1.000
88.400 36.000 1.000
88.460 36.000 1.000
88.520 38.000 1.000
88.580 35.000 1.000
88.640 39.000 1.000
88.700 33.000 1.000
88.760 44.000 1.000
88.820 39.000 1.000
88.880 39.000 1.000
88.940 41.000 1.000
89.000 36.000 1.000
89.060 57.000 1.000
89.120 56.000 1.000
89.180 72.000 1.000
89.240 84.000 1.000
89.300 105.000 1.000
89.360 134.000 1.000
89.420 161.000 1.000
89.480 177.000 1.000
89.540 181.000 1.000
89.600 154.000 1.000
89.660 149.000 1.000
89.720 138.000 1.000
89.780 124.000 1.000
89.840 117.000 1.000
89.900 103.000 1.000
89.960 67.000 1.000
90.000 67.000 1.000
*RAS_INT_END
*RAS_DATA_END