File: ras-to-csv_converter_plotter/example/ras/TiO2-1-12h_20-02-2019.ras
*RAS_DATA_START
*RAS_HEADER_START
*CORR_POS_DB_NAME "correction_file_060219"
*CORR_POS_GONIO_RADIUS ""
*CORR_POS_NODE_INDEX01 ""
*CORR_POS_NODE_INDEX02 ""
*CORR_POS_NODE_INDEX03 ""
*CORR_POS_NODE_INDEX04 ""
*CORR_POS_NODE_INDEX05 ""
*CORR_POS_NODE_INDEX06 ""
*CORR_POS_NODE_INDEX07 ""
*CORR_POS_NODE_INDEX08 ""
*CORR_POS_NODE_INDEX09 ""
*CORR_POS_NODE_INDEX10 ""
*CORR_POS_NODE_INDEX11 ""
*CORR_POS_NODE_LABEL01 "Si(111)"
*CORR_POS_NODE_LABEL02 "Si(220)"
*CORR_POS_NODE_LABEL03 "Si(311)"
*CORR_POS_NODE_LABEL04 "Si(400)"
*CORR_POS_NODE_LABEL05 "Si(331)"
*CORR_POS_NODE_LABEL06 "Si(422)"
*CORR_POS_NODE_LABEL07 "Si(511)"
*CORR_POS_NODE_LABEL08 "Si(440)"
*CORR_POS_NODE_LABEL09 "Si(531)"
*CORR_POS_NODE_LABEL10 "Si(620)"
*CORR_POS_NODE_LABEL11 "Si(533)"
*CORR_POS_NODE_POS_CALC01 "28.4137"
*CORR_POS_NODE_POS_CALC02 "47.2707"
*CORR_POS_NODE_POS_CALC03 "56.0883"
*CORR_POS_NODE_POS_CALC04 "69.0934"
*CORR_POS_NODE_POS_CALC05 "76.3385"
*CORR_POS_NODE_POS_CALC06 "87.9915"
*CORR_POS_NODE_POS_CALC07 "94.9137"
*CORR_POS_NODE_POS_CALC08 "106.67"
*CORR_POS_NODE_POS_CALC09 "114.054"
*CORR_POS_NODE_POS_CALC10 "127.508"
*CORR_POS_NODE_POS_CALC11 "136.858"
*CORR_POS_NODE_POS_MEAS01 "28.4636"
*CORR_POS_NODE_POS_MEAS02 "47.3217"
*CORR_POS_NODE_POS_MEAS03 "56.1422"
*CORR_POS_NODE_POS_MEAS04 "69.1431"
*CORR_POS_NODE_POS_MEAS05 "76.3906"
*CORR_POS_NODE_POS_MEAS06 "88.0416"
*CORR_POS_NODE_POS_MEAS07 "94.9694"
*CORR_POS_NODE_POS_MEAS08 "106.719"
*CORR_POS_NODE_POS_MEAS09 "114.106"
*CORR_POS_NODE_POS_MEAS10 "127.554"
*CORR_POS_NODE_POS_MEAS11 "136.911"
*CORR_POS_OPT_ATTR "集中法"
*CORR_POS_PARAM_MU ""
*CORR_POS_PARAM_PL ""
*CORR_POS_SEMODEL_TYPE "0"
*CORR_POS_STANDARD_TYPE ""
*CORR_POS_VALUE_ANALYZER "None"
*CORR_POS_VALUE_CMONO "None"
*CORR_POS_VALUE_IMONO "None"
*CORR_POS_VALUE_IS "0.625deg"
*CORR_POS_VALUE_ISL "10.0mm"
*CORR_POS_VALUE_ISOLLER "2.5deg"
*CORR_POS_VALUE_RS1 "13.0mm"
*CORR_POS_VALUE_RS2 "13.0mm"
*CORR_POS_VALUE_RSOLLER "2.5deg"
*CORR_POS_XG_FOCUS_L ""
*CORR_POS_XG_WAVE_TYPE ""
*CORR_POS_XG_WAVE_VALUE ""
*DISP_FMT_X "%.2f"
*DISP_FMT_Y "%.0f"
*DISP_FULLSCALE "35210.0000000000"
*DISP_LINE_COLOR "255.0000000000"
*DISP_LINE_STYLE "0.0000000000"
*DISP_LINE_WIDTH "0.2500000000"
*DISP_NOTE "Collected Data-2"
*DISP_OFFSET_Y "0.0000000000"
*DISP_PEAKSEARCH_UNIT_Y "cps"
*DISP_RANGE_BOTTOM "0.0000000000"
*DISP_RANGE_LEFT "5.0000000000"
*DISP_RANGE_LOGCUTOFF "0.0100000000"
*DISP_RANGE_RIGHT "90.0000000000"
*DISP_RANGE_TOP "35210.0000000000"
*DISP_SCALE_MODE_Y "0.0000000000"
*DISP_TAB_NAME "Theta/2-Theta"
*DISP_TITLE_Y "Intensity"
*DISP_UNIT_Y "cps"
*DISP_WINDOW_NAME "MSG_MACROENGINE"
*FILE_COMMENT " "
*FILE_MD5 ""
*FILE_MEMO " "
*FILE_OPERATOR "SDU_RIGAKU"
*FILE_SAMPLE "TiO2-1-12h_20-02-2019"
*FILE_TYPE "RAS_RAW"
*FILE_USERGROUP "System User"
*FILE_VERSION "1.0000000000"
*HW_ATTACHMENT_ID "ATT1031"
*HW_ATTACHMENT_NAME "6サンプルチェンジャ|ASC-6"
*HW_COUNTER_ID-0 "CUT0025"
*HW_COUNTER_ID-1 "CUT0020"
*HW_COUNTER_ID-2 "CUT0020"
*HW_COUNTER_ID-3 "CMC0021"
*HW_COUNTER_NAME-0 "D/teX Ultra|D/teX Ultra"
*HW_COUNTER_NAME-1 "None|None"
*HW_COUNTER_NAME-2 "None|None"
*HW_COUNTER_NAME-3 "検出器モノクロメータ|Detector monochromator"
*HW_COUNTER_SELECT_NAME "D/teX Ultra|D/teX Ultra"
*HW_GONIOMETER_ID "GON0070"
*HW_GONIOMETER_NAME "MiniFlex 300/600|MiniFlex 300/600"
*HW_GONIOMETER_RADIUS-0 "79.0"
*HW_GONIOMETER_RADIUS-1 "91.5"
*HW_GONIOMETER_RADIUS-2 "150.0"
*HW_GONIOMETER_RADIUS-3 "0"
*HW_GONIOMETER_RADIUS-4 "103.4"
*HW_GONIOMETER_RADIUS-5 "150.0"
*HW_GONIOMETER_RADIUS-6 "46.6"
*HW_GONIOMETER_RADIUS-7 "160.0"
*HW_I_OPT_ID-0 "ISL0021"
*HW_I_OPT_ID-1 "ISO0021"
*HW_I_OPT_NAME-0 "発散スリット|Divergence slit"
*HW_I_OPT_NAME-1 "入射平行スリット|Incident parallel slit"
*HW_R_ATTENUATER_AUTOMODE "0"
*HW_R_OPT_ID-0 "RSS0021"
*HW_R_OPT_ID-1 "RSO0021"
*HW_R_OPT_ID-2 "RRS0021"
*HW_R_OPT_NAME-0 "散乱スリット|Scattering slit"
*HW_R_OPT_NAME-1 "受光平行スリット|Receiving soller slit"
*HW_R_OPT_NAME-2 "受光スリット|Receiving slit"
*HW_SAMPLE_HOLDER_ID "SMP0000"
*HW_SAMPLE_HOLDER_NAME "無し|None"
*HW_XG_CURRENT_MAX "15"
*HW_XG_CURRENT_MIN "2"
*HW_XG_CURRENT_RESOLUTION "1"
*HW_XG_CURRENT_UNIT "mA"
*HW_XG_FOCUS "1mm x 10mm"
*HW_XG_FOCUS_TYPE "Normal"
*HW_XG_ID ""
*HW_XG_NAME "300W/600W 封入管-B|300W/600W Sealed tube-B"
*HW_XG_TARGET_ATOMIC_NUMBER "29.0000000000"
*HW_XG_TARGET_NAME "Cu"
*HW_XG_TYPE "Hermetic"
*HW_XG_VOLTAGE_MAX "40"
*HW_XG_VOLTAGE_MIN "20"
*HW_XG_VOLTAGE_RESOLUTION "1"
*HW_XG_VOLTAGE_UNIT "kV"
*HW_XG_WATT_MAX "1"
*HW_XG_WATT_UNIT "kW"
*HW_XG_WAVE_LENGTH_ALPHA1 "1.540593"
*HW_XG_WAVE_LENGTH_ALPHA2 "1.544414"
*HW_XG_WAVE_LENGTH_BETA "1.392250"
*MEAS_COND_AXIS_NAME-0 "Theta/2-Theta"
*MEAS_COND_AXIS_NAME-1 "Spin"
*MEAS_COND_AXIS_NAME-2 "Change"
*MEAS_COND_AXIS_NAME-3 "Soller(inc.)"
*MEAS_COND_AXIS_NAME-4 "IHS"
*MEAS_COND_AXIS_NAME-5 "DS"
*MEAS_COND_AXIS_NAME-6 "SS"
*MEAS_COND_AXIS_NAME-7 "Soller(rec.)"
*MEAS_COND_AXIS_NAME-8 "RS"
*MEAS_COND_AXIS_NAME-9 "Filter"
*MEAS_COND_AXIS_NAME-10 "Monochromator"
*MEAS_COND_AXIS_NAME-11 "PHA"
*MEAS_COND_AXIS_NAME_INTERNAL-0 "TwoThetaTheta"
*MEAS_COND_AXIS_NAME_INTERNAL-1 "Spin"
*MEAS_COND_AXIS_NAME_INTERNAL-2 "Change"
*MEAS_COND_AXIS_NAME_INTERNAL-3 "IncidentSollerSlit"
*MEAS_COND_AXIS_NAME_INTERNAL-4 "IncidentAxdSlit"
*MEAS_COND_AXIS_NAME_INTERNAL-5 "IncidentSlitBox"
*MEAS_COND_AXIS_NAME_INTERNAL-6 "ReceivingSlitBox1"
*MEAS_COND_AXIS_NAME_INTERNAL-7 "ReceivingSollerSlit"
*MEAS_COND_AXIS_NAME_INTERNAL-8 "ReceivingSlitBox2"
*MEAS_COND_AXIS_NAME_INTERNAL-9 "Filter"
*MEAS_COND_AXIS_NAME_INTERNAL-10 "CounterMonochromator"
*MEAS_COND_AXIS_NAME_INTERNAL-11 "PHA"
*MEAS_COND_AXIS_NAME_MAGICNO-0 "268632064.0000000000"
*MEAS_COND_AXIS_NAME_MAGICNO-1 "16842752.0000000000"
*MEAS_COND_AXIS_NAME_MAGICNO-2 "16842752.0000000000"
*MEAS_COND_AXIS_NAME_MAGICNO-3 "20971521.0000000000"
*MEAS_COND_AXIS_NAME_MAGICNO-4 "22020097.0000000000"
*MEAS_COND_AXIS_NAME_MAGICNO-5 "22020097.0000000000"
*MEAS_COND_AXIS_NAME_MAGICNO-6 "23068673.0000000000"
*MEAS_COND_AXIS_NAME_MAGICNO-7 "20971521.0000000000"
*MEAS_COND_AXIS_NAME_MAGICNO-8 "23068673.0000000000"
*MEAS_COND_AXIS_NAME_MAGICNO-9 "20971521.0000000000"
*MEAS_COND_AXIS_NAME_MAGICNO-10 "20971521.0000000000"
*MEAS_COND_AXIS_NAME_MAGICNO-11 "0.0000000000"
*MEAS_COND_AXIS_OFFSET-0 "0.0000000000"
*MEAS_COND_AXIS_OFFSET-1 "-"
*MEAS_COND_AXIS_OFFSET-2 "-"
*MEAS_COND_AXIS_OFFSET-3 "-"
*MEAS_COND_AXIS_OFFSET-4 "-"
*MEAS_COND_AXIS_OFFSET-5 "-"
*MEAS_COND_AXIS_OFFSET-6 "-"
*MEAS_COND_AXIS_OFFSET-7 "-"
*MEAS_COND_AXIS_OFFSET-8 "-"
*MEAS_COND_AXIS_OFFSET-9 "-"
*MEAS_COND_AXIS_OFFSET-10 "-"
*MEAS_COND_AXIS_OFFSET-11 "-"
*MEAS_COND_AXIS_POSITION-0 "92.5100000000"
*MEAS_COND_AXIS_POSITION-1 "0.0000000000"
*MEAS_COND_AXIS_POSITION-2 "4.0000000000"
*MEAS_COND_AXIS_POSITION-3 "2.5deg"
*MEAS_COND_AXIS_POSITION-4 "10.0mm"
*MEAS_COND_AXIS_POSITION-5 "0.625deg"
*MEAS_COND_AXIS_POSITION-6 "13.0mm"
*MEAS_COND_AXIS_POSITION-7 "2.5deg"
*MEAS_COND_AXIS_POSITION-8 "13.0mm"
*MEAS_COND_AXIS_POSITION-9 "K-beta(x1)"
*MEAS_COND_AXIS_POSITION-10 "None"
*MEAS_COND_AXIS_POSITION-11 "42.0000000000"
*MEAS_COND_AXIS_UNIT-0 "deg"
*MEAS_COND_AXIS_UNIT-1 ""
*MEAS_COND_AXIS_UNIT-2 ""
*MEAS_COND_AXIS_UNIT-3 ""
*MEAS_COND_AXIS_UNIT-4 ""
*MEAS_COND_AXIS_UNIT-5 ""
*MEAS_COND_AXIS_UNIT-6 ""
*MEAS_COND_AXIS_UNIT-7 ""
*MEAS_COND_AXIS_UNIT-8 ""
*MEAS_COND_AXIS_UNIT-9 ""
*MEAS_COND_AXIS_UNIT-10 ""
*MEAS_COND_AXIS_UNIT-11 "div"
*MEAS_COND_CORRECTION_SLIT_COUNTERMONO "None"
*MEAS_COND_CORRECTION_SLIT_DS "0.625deg"
*MEAS_COND_CORRECTION_SLIT_FILTER "None"
*MEAS_COND_CORRECTION_SLIT_IHS "10.0mm"
*MEAS_COND_CORRECTION_SLIT_RS "13.0mm"
*MEAS_COND_CORRECTION_SLIT_SOLLER_INC "2.5deg"
*MEAS_COND_CORRECTION_SLIT_SOLLER_REC "2.5deg"
*MEAS_COND_CORRECTION_SLIT_SS "13.0mm"
*MEAS_COND_COUNTER_CNTLOSS_CORR "0.0000000000"
*MEAS_COND_COUNTER_PHABASE "42.0000000000"
*MEAS_COND_COUNTER_PHAWINDOW "15.0000000000"
*MEAS_COND_COUNTER_PHA_UNIT "div"
*MEAS_COND_COUNTER_TAUDIFF "0.2500000000"
*MEAS_COND_COUNTER_TAUINT "0.7500000000"
*MEAS_COND_IRRADIATION_MODE "OFF"
*MEAS_COND_IRRADIATION_WIDTH ""
*MEAS_COND_OPT_ATTR " "
*MEAS_COND_OPT_NAME ""
*MEAS_COND_UNSYMMETRIC_MODE "OFF"
*MEAS_COND_XG_CURRENT "15.0000000000"
*MEAS_COND_XG_VOLTAGE "40.0000000000"
*MEAS_COND_XG_WAVE_TYPE "Ka"
*MEAS_DATA_COUNT "4251.0000000000"
*MEAS_SCAN_AXIS_X "Theta/2-Theta"
*MEAS_SCAN_AXIS_X_INTERNAL "TwoThetaTheta"
*MEAS_SCAN_END_TIME "02/20/19 11:35:32"
*MEAS_SCAN_MODE "CONTINUOUS"
*MEAS_SCAN_MONITOR "0"
*MEAS_SCAN_RESOLUTION_X "0.005"
*MEAS_SCAN_SPEED "5.000"
*MEAS_SCAN_SPEED_UNIT "deg/min"
*MEAS_SCAN_START "5.0000000000"
*MEAS_SCAN_START_TIME "02/20/19 11:17:06"
*MEAS_SCAN_STEP "0.0200000000"
*MEAS_SCAN_STOP "90.0000000000"
*MEAS_SCAN_UNIT_X "deg"
*MEAS_SCAN_UNIT_Y "counts"
*SLIT_SYSTEM "0"
*RAS_HEADER_END
*RAS_INT_START
5.000 583.000 1.000
5.060 572.000 1.000
5.120 602.000 1.000
5.180 543.000 1.000
5.240 495.000 1.000
5.300 530.000 1.000
5.360 493.000 1.000
5.420 494.000 1.000
5.480 472.000 1.000
5.540 479.000 1.000
5.600 482.000 1.000
5.660 467.000 1.000
5.720 459.000 1.000
5.780 456.000 1.000
5.840 400.000 1.000
5.900 437.000 1.000
5.960 429.000 1.000
6.020 411.000 1.000
6.080 430.000 1.000
6.140 405.000 1.000
6.200 367.000 1.000
6.260 392.000 1.000
6.320 363.000 1.000
6.380 372.000 1.000
6.440 373.000 1.000
6.500 404.000 1.000
6.560 359.000 1.000
6.620 333.000 1.000
6.680 338.000 1.000
6.740 331.000 1.000
6.800 335.000 1.000
6.860 344.000 1.000
6.920 321.000 1.000
6.980 313.000 1.000
7.040 332.000 1.000
7.100 324.000 1.000
7.160 335.000 1.000
7.220 326.000 1.000
7.280 331.000 1.000
7.340 324.000 1.000
7.400 290.000 1.000
7.460 307.000 1.000
7.520 320.000 1.000
7.580 311.000 1.000
7.640 295.000 1.000
7.700 300.000 1.000
7.760 302.000 1.000
7.820 275.000 1.000
7.880 312.000 1.000
7.940 285.000 1.000
8.000 313.000 1.000
8.060 282.000 1.000
8.120 299.000 1.000
8.180 289.000 1.000
8.240 296.000 1.000
8.300 304.000 1.000
8.360 311.000 1.000
8.420 271.000 1.000
8.480 294.000 1.000
8.540 277.000 1.000
8.600 270.000 1.000
8.660 277.000 1.000
8.720 270.000 1.000
8.780 289.000 1.000
8.840 270.000 1.000
8.900 266.000 1.000
8.960 250.000 1.000
9.020 259.000 1.000
9.080 262.000 1.000
9.140 260.000 1.000
9.200 279.000 1.000
9.260 268.000 1.000
9.320 254.000 1.000
9.380 277.000 1.000
9.440 256.000 1.000
9.500 260.000 1.000
9.560 262.000 1.000
9.620 256.000 1.000
9.680 246.000 1.000
9.740 269.000 1.000
9.800 264.000 1.000
9.860 264.000 1.000
9.920 274.000 1.000
9.980 241.000 1.000
10.040 261.000 1.000
10.100 259.000 1.000
10.160 241.000 1.000
10.220 259.000 1.000
10.280 250.000 1.000
10.340 254.000 1.000
10.400 243.000 1.000
10.460 235.000 1.000
10.520 253.000 1.000
10.580 247.000 1.000
10.640 258.000 1.000
10.700 270.000 1.000
10.760 251.000 1.000
10.820 263.000 1.000
10.880 272.000 1.000
10.940 266.000 1.000
11.000 268.000 1.000
11.060 264.000 1.000
11.120 259.000 1.000
11.180 255.000 1.000
11.240 283.000 1.000
11.300 254.000 1.000
11.360 251.000 1.000
11.420 255.000 1.000
11.480 257.000 1.000
11.540 242.000 1.000
11.600 228.000 1.000
11.660 253.000 1.000
11.720 264.000 1.000
11.780 260.000 1.000
11.840 244.000 1.000
11.900 260.000 1.000
11.960 244.000 1.000
12.020 245.000 1.000
12.080 263.000 1.000
12.140 248.000 1.000
12.200 244.000 1.000
12.260 243.000 1.000
12.320 247.000 1.000
12.380 243.000 1.000
12.440 239.000 1.000
12.500 255.000 1.000
12.560 240.000 1.000
12.620 244.000 1.000
12.680 243.000 1.000
12.740 233.000 1.000
12.800 238.000 1.000
12.860 247.000 1.000
12.920 236.000 1.000
12.980 262.000 1.000
13.040 232.000 1.000
13.100 234.000 1.000
13.160 247.000 1.000
13.220 243.000 1.000
13.280 242.000 1.000
13.340 232.000 1.000
13.400 226.000 1.000
13.460 214.000 1.000
13.520 227.000 1.000
13.580 212.000 1.000
13.640 226.000 1.000
13.700 206.000 1.000
13.760 233.000 1.000
13.820 241.000 1.000
13.880 258.000 1.000
13.940 215.000 1.000
14.000 225.000 1.000
14.060 245.000 1.000
14.120 217.000 1.000
14.180 238.000 1.000
14.240 219.000 1.000
14.300 232.000 1.000
14.360 238.000 1.000
14.420 219.000 1.000
14.480 238.000 1.000
14.540 214.000 1.000
14.600 221.000 1.000
14.660 217.000 1.000
14.720 225.000 1.000
14.780 226.000 1.000
14.840 222.000 1.000
14.900 218.000 1.000
14.960 234.000 1.000
15.020 224.000 1.000
15.080 212.000 1.000
15.140 202.000 1.000
15.200 223.000 1.000
15.260 224.000 1.000
15.320 225.000 1.000
15.380 215.000 1.000
15.440 198.000 1.000
15.500 220.000 1.000
15.560 234.000 1.000
15.620 209.000 1.000
15.680 229.000 1.000
15.740 197.000 1.000
15.800 201.000 1.000
15.860 219.000 1.000
15.920 226.000 1.000
15.980 216.000 1.000
16.040 200.000 1.000
16.100 216.000 1.000
16.160 203.000 1.000
16.220 219.000 1.000
16.280 208.000 1.000
16.340 212.000 1.000
16.400 220.000 1.000
16.460 208.000 1.000
16.520 201.000 1.000
16.580 207.000 1.000
16.640 199.000 1.000
16.700 198.000 1.000
16.760 212.000 1.000
16.820 200.000 1.000
16.880 197.000 1.000
16.940 199.000 1.000
17.000 216.000 1.000
17.060 195.000 1.000
17.120 192.000 1.000
17.180 218.000 1.000
17.240 206.000 1.000
17.300 200.000 1.000
17.360 189.000 1.000
17.420 204.000 1.000
17.480 196.000 1.000
17.540 190.000 1.000
17.600 181.000 1.000
17.660 187.000 1.000
17.720 184.000 1.000
17.780 188.000 1.000
17.840 182.000 1.000
17.900 196.000 1.000
17.960 186.000 1.000
18.020 192.000 1.000
18.080 175.000 1.000
18.140 170.000 1.000
18.200 193.000 1.000
18.260 189.000 1.000
18.320 213.000 1.000
18.380 183.000 1.000
18.440 180.000 1.000
18.500 189.000 1.000
18.560 193.000 1.000
18.620 192.000 1.000
18.680 180.000 1.000
18.740 192.000 1.000
18.800 183.000 1.000
18.860 178.000 1.000
18.920 198.000 1.000
18.980 179.000 1.000
19.040 175.000 1.000
19.100 193.000 1.000
19.160 179.000 1.000
19.220 184.000 1.000
19.280 190.000 1.000
19.340 183.000 1.000
19.400 182.000 1.000
19.460 195.000 1.000
19.520 193.000 1.000
19.580 184.000 1.000
19.640 160.000 1.000
19.700 163.000 1.000
19.760 162.000 1.000
19.820 176.000 1.000
19.880 170.000 1.000
19.940 183.000 1.000
20.000 188.000 1.000
20.060 177.000 1.000
20.120 174.000 1.000
20.180 166.000 1.000
20.240 173.000 1.000
20.300 169.000 1.000
20.360 177.000 1.000
20.420 181.000 1.000
20.480 173.000 1.000
20.540 160.000 1.000
20.600 156.000 1.000
20.660 165.000 1.000
20.720 166.000 1.000
20.780 176.000 1.000
20.840 181.000 1.000
20.900 182.000 1.000
20.960 157.000 1.000
21.020 170.000 1.000
21.080 179.000 1.000
21.140 158.000 1.000
21.200 155.000 1.000
21.260 155.000 1.000
21.320 164.000 1.000
21.380 163.000 1.000
21.440 163.000 1.000
21.500 154.000 1.000
21.560 157.000 1.000
21.620 155.000 1.000
21.680 158.000 1.000
21.740 168.000 1.000
21.800 158.000 1.000
21.860 168.000 1.000
21.920 173.000 1.000
21.980 156.000 1.000
22.040 152.000 1.000
22.100 164.000 1.000
22.160 166.000 1.000
22.220 148.000 1.000
22.280 162.000 1.000
22.340 173.000 1.000
22.400 150.000 1.000
22.460 157.000 1.000
22.520 170.000 1.000
22.580 168.000 1.000
22.640 152.000 1.000
22.700 164.000 1.000
22.760 158.000 1.000
22.820 153.000 1.000
22.880 152.000 1.000
22.940 162.000 1.000
23.000 172.000 1.000
23.060 144.000 1.000
23.120 154.000 1.000
23.180 140.000 1.000
23.240 151.000 1.000
23.300 154.000 1.000
23.360 152.000 1.000
23.420 153.000 1.000
23.480 143.000 1.000
23.540 149.000 1.000
23.600 158.000 1.000
23.660 148.000 1.000
23.720 159.000 1.000
23.780 159.000 1.000
23.840 167.000 1.000
23.900 133.000 1.000
23.960 156.000 1.000
24.020 154.000 1.000
24.080 172.000 1.000
24.140 180.000 1.000
24.200 145.000 1.000
24.260 159.000 1.000
24.320 155.000 1.000
24.380 163.000 1.000
24.440 165.000 1.000
24.500 163.000 1.000
24.560 145.000 1.000
24.620 159.000 1.000
24.680 160.000 1.000
24.740 167.000 1.000
24.800 151.000 1.000
24.860 174.000 1.000
24.920 157.000 1.000
24.980 150.000 1.000
25.040 156.000 1.000
25.100 172.000 1.000
25.160 155.000 1.000
25.220 170.000 1.000
25.280 169.000 1.000
25.340 153.000 1.000
25.400 170.000 1.000
25.460 177.000 1.000
25.520 182.000 1.000
25.580 169.000 1.000
25.640 178.000 1.000
25.700 183.000 1.000
25.760 173.000 1.000
25.820 181.000 1.000
25.880 195.000 1.000
25.940 183.000 1.000
26.000 208.000 1.000
26.060 193.000 1.000
26.120 204.000 1.000
26.180 216.000 1.000
26.240 220.000 1.000
26.300 208.000 1.000
26.360 228.000 1.000
26.420 229.000 1.000
26.480 259.000 1.000
26.540 287.000 1.000
26.600 290.000 1.000
26.660 365.000 1.000
26.720 374.000 1.000
26.780 401.000 1.000
26.840 443.000 1.000
26.900 472.000 1.000
26.960 594.000 1.000
27.020 667.000 1.000
27.080 840.000 1.000
27.140 1104.000 1.000
27.200 1619.000 1.000
27.260 2516.000 1.000
27.320 3963.000 1.000
27.380 5671.000 1.000
27.440 6801.000 1.000
27.500 6785.000 1.000
27.560 5507.000 1.000
27.620 3890.000 1.000
27.680 2491.000 1.000
27.740 1713.000 1.000
27.800 1184.000 1.000
27.860 886.000 1.000
27.920 698.000 1.000
27.980 565.000 1.000
28.040 489.000 1.000
28.100 447.000 1.000
28.160 390.000 1.000
28.220 347.000 1.000
28.280 329.000 1.000
28.340 300.000 1.000
28.400 293.000 1.000
28.460 295.000 1.000
28.520 218.000 1.000
28.580 240.000 1.000
28.640 235.000 1.000
28.700 220.000 1.000
28.760 218.000 1.000
28.820 226.000 1.000
28.880 217.000 1.000
28.940 186.000 1.000
29.000 200.000 1.000
29.060 187.000 1.000
29.120 174.000 1.000
29.180 170.000 1.000
29.240 174.000 1.000
29.300 181.000 1.000
29.360 169.000 1.000
29.420 177.000 1.000
29.480 153.000 1.000
29.540 158.000 1.000
29.600 153.000 1.000
29.660 148.000 1.000
29.720 151.000 1.000
29.780 156.000 1.000
29.840 151.000 1.000
29.900 156.000 1.000
29.960 153.000 1.000
30.020 149.000 1.000
30.080 161.000 1.000
30.140 148.000 1.000
30.200 144.000 1.000
30.260 156.000 1.000
30.320 156.000 1.000
30.380 144.000 1.000
30.440 138.000 1.000
30.500 132.000 1.000
30.560 132.000 1.000
30.620 141.000 1.000
30.680 139.000 1.000
30.740 127.000 1.000
30.800 141.000 1.000
30.860 126.000 1.000
30.920 137.000 1.000
30.980 134.000 1.000
31.040 129.000 1.000
31.100 116.000 1.000
31.160 118.000 1.000
31.220 130.000 1.000
31.280 101.000 1.000
31.340 113.000 1.000
31.400 126.000 1.000
31.460 133.000 1.000
31.520 116.000 1.000
31.580 118.000 1.000
31.640 123.000 1.000
31.700 116.000 1.000
31.760 134.000 1.000
31.820 115.000 1.000
31.880 113.000 1.000
31.940 110.000 1.000
32.000 102.000 1.000
32.060 125.000 1.000
32.120 117.000 1.000
32.180 112.000 1.000
32.240 111.000 1.000
32.300 121.000 1.000
32.360 120.000 1.000
32.420 124.000 1.000
32.480 114.000 1.000
32.540 108.000 1.000
32.600 116.000 1.000
32.660 109.000 1.000
32.720 112.000 1.000
32.780 114.000 1.000
32.840 93.000 1.000
32.900 102.000 1.000
32.960 104.000 1.000
33.020 105.000 1.000
33.080 116.000 1.000
33.140 117.000 1.000
33.200 102.000 1.000
33.260 106.000 1.000
33.320 110.000 1.000
33.380 101.000 1.000
33.440 126.000 1.000
33.500 108.000 1.000
33.560 104.000 1.000
33.620 113.000 1.000
33.680 100.000 1.000
33.740 113.000 1.000
33.800 112.000 1.000
33.860 114.000 1.000
33.920 98.000 1.000
33.980 97.000 1.000
34.040 102.000 1.000
34.100 105.000 1.000
34.160 111.000 1.000
34.220 111.000 1.000
34.280 108.000 1.000
34.340 121.000 1.000
34.400 98.000 1.000
34.460 95.000 1.000
34.520 100.000 1.000
34.580 111.000 1.000
34.640 123.000 1.000
34.700 113.000 1.000
34.760 111.000 1.000
34.820 115.000 1.000
34.880 115.000 1.000
34.940 135.000 1.000
35.000 122.000 1.000
35.060 121.000 1.000
35.120 124.000 1.000
35.180 147.000 1.000
35.240 145.000 1.000
35.300 155.000 1.000
35.360 160.000 1.000
35.420 161.000 1.000
35.480 173.000 1.000
35.540 193.000 1.000
35.600 205.000 1.000
35.660 239.000 1.000
35.720 275.000 1.000
35.780 314.000 1.000
35.840 384.000 1.000
35.900 521.000 1.000
35.960 791.000 1.000
36.020 1376.000 1.000
36.080 2458.000 1.000
36.140 3127.000 1.000
36.200 2730.000 1.000
36.260 1895.000 1.000
36.320 1095.000 1.000
36.380 660.000 1.000
36.440 440.000 1.000
36.500 338.000 1.000
36.560 258.000 1.000
36.620 223.000 1.000
36.680 204.000 1.000
36.740 171.000 1.000
36.800 172.000 1.000
36.860 163.000 1.000
36.920 156.000 1.000
36.980 135.000 1.000
37.040 139.000 1.000
37.100 138.000 1.000
37.160 121.000 1.000
37.220 108.000 1.000
37.280 127.000 1.000
37.340 128.000 1.000
37.400 111.000 1.000
37.460 117.000 1.000
37.520 110.000 1.000
37.580 113.000 1.000
37.640 115.000 1.000
37.700 107.000 1.000
37.760 110.000 1.000
37.820 103.000 1.000
37.880 99.000 1.000
37.940 103.000 1.000
38.000 102.000 1.000
38.060 107.000 1.000
38.120 115.000 1.000
38.180 98.000 1.000
38.240 113.000 1.000
38.300 101.000 1.000
38.360 112.000 1.000
38.420 108.000 1.000
38.480 119.000 1.000
38.540 102.000 1.000
38.600 109.000 1.000
38.660 116.000 1.000
38.720 128.000 1.000
38.780 115.000 1.000
38.840 130.000 1.000
38.900 175.000 1.000
38.960 207.000 1.000
39.020 246.000 1.000
39.080 344.000 1.000
39.140 403.000 1.000
39.200 441.000 1.000
39.260 409.000 1.000
39.320 323.000 1.000
39.380 236.000 1.000
39.440 199.000 1.000
39.500 169.000 1.000
39.560 147.000 1.000
39.620 131.000 1.000
39.680 112.000 1.000
39.740 135.000 1.000
39.800 108.000 1.000
39.860 110.000 1.000
39.920 116.000 1.000
39.980 112.000 1.000
40.040 114.000 1.000
40.100 98.000 1.000
40.160 100.000 1.000
40.220 111.000 1.000
40.280 95.000 1.000
40.340 111.000 1.000
40.400 111.000 1.000
40.460 113.000 1.000
40.520 121.000 1.000
40.580 109.000 1.000
40.640 133.000 1.000
40.700 122.000 1.000
40.760 144.000 1.000
40.820 159.000 1.000
40.880 165.000 1.000
40.940 193.000 1.000
41.000 236.000 1.000
41.060 317.000 1.000
41.120 559.000 1.000
41.180 970.000 1.000
41.240 1406.000 1.000
41.300 1601.000 1.000
41.360 1352.000 1.000
41.420 940.000 1.000
41.480 559.000 1.000
41.540 391.000 1.000
41.600 238.000 1.000
41.660 199.000 1.000
41.720 172.000 1.000
41.780 152.000 1.000
41.840 117.000 1.000
41.900 122.000 1.000
41.960 122.000 1.000
42.020 109.000 1.000
42.080 93.000 1.000
42.140 100.000 1.000
42.200 108.000 1.000
42.260 101.000 1.000
42.320 85.000 1.000
42.380 102.000 1.000
42.440 84.000 1.000
42.500 91.000 1.000
42.560 96.000 1.000
42.620 91.000 1.000
42.680 91.000 1.000
42.740 100.000 1.000
42.800 93.000 1.000
42.860 99.000 1.000
42.920 94.000 1.000
42.980 95.000 1.000
43.040 84.000 1.000
43.100 85.000 1.000
43.160 94.000 1.000
43.220 89.000 1.000
43.280 95.000 1.000
43.340 95.000 1.000
43.400 91.000 1.000
43.460 102.000 1.000
43.520 104.000 1.000
43.580 110.000 1.000
43.640 127.000 1.000
43.700 151.000 1.000
43.760 189.000 1.000
43.820 239.000 1.000
43.880 315.000 1.000
43.940 433.000 1.000
44.000 530.000 1.000
44.060 499.000 1.000
44.120 492.000 1.000
44.180 387.000 1.000
44.240 291.000 1.000
44.300 212.000 1.000
44.360 173.000 1.000
44.420 141.000 1.000
44.480 116.000 1.000
44.540 108.000 1.000
44.600 96.000 1.000
44.660 92.000 1.000
44.720 83.000 1.000
44.780 76.000 1.000
44.840 89.000 1.000
44.900 81.000 1.000
44.960 75.000 1.000
45.020 72.000 1.000
45.080 79.000 1.000
45.140 82.000 1.000
45.200 72.000 1.000
45.260 71.000 1.000
45.320 78.000 1.000
45.380 75.000 1.000
45.440 84.000 1.000
45.500 71.000 1.000
45.560 63.000 1.000
45.620 64.000 1.000
45.680 70.000 1.000
45.740 73.000 1.000
45.800 71.000 1.000
45.860 57.000 1.000
45.920 73.000 1.000
45.980 68.000 1.000
46.040 74.000 1.000
46.100 76.000 1.000
46.160 61.000 1.000
46.220 64.000 1.000
46.280 64.000 1.000
46.340 63.000 1.000
46.400 67.000 1.000
46.460 65.000 1.000
46.520 78.000 1.000
46.580 66.000 1.000
46.640 65.000 1.000
46.700 57.000 1.000
46.760 70.000 1.000
46.820 72.000 1.000
46.880 72.000 1.000
46.940 63.000 1.000
47.000 61.000 1.000
47.060 62.000 1.000
47.120 62.000 1.000
47.180 64.000 1.000
47.240 65.000 1.000
47.300 62.000 1.000
47.360 71.000 1.000
47.420 66.000 1.000
47.480 60.000 1.000
47.540 67.000 1.000
47.600 53.000 1.000
47.660 66.000 1.000
47.720 65.000 1.000
47.780 74.000 1.000
47.840 60.000 1.000
47.900 57.000 1.000
47.960 61.000 1.000
48.020 67.000 1.000
48.080 64.000 1.000
48.140 59.000 1.000
48.200 65.000 1.000
48.260 58.000 1.000
48.320 66.000 1.000
48.380 59.000 1.000
48.440 65.000 1.000
48.500 67.000 1.000
48.560 63.000 1.000
48.620 69.000 1.000
48.680 61.000 1.000
48.740 61.000 1.000
48.800 69.000 1.000
48.860 59.000 1.000
48.920 58.000 1.000
48.980 62.000 1.000
49.040 70.000 1.000
49.100 62.000 1.000
49.160 69.000 1.000
49.220 66.000 1.000
49.280 60.000 1.000
49.340 62.000 1.000
49.400 58.000 1.000
49.460 65.000 1.000
49.520 59.000 1.000
49.580 65.000 1.000
49.640 67.000 1.000
49.700 63.000 1.000
49.760 64.000 1.000
49.820 60.000 1.000
49.880 56.000 1.000
49.940 64.000 1.000
50.000 65.000 1.000
50.060 56.000 1.000
50.120 53.000 1.000
50.180 73.000 1.000
50.240 64.000 1.000
50.300 57.000 1.000
50.360 63.000 1.000
50.420 58.000 1.000
50.480 66.000 1.000
50.540 71.000 1.000
50.600 66.000 1.000
50.660 51.000 1.000
50.720 62.000 1.000
50.780 61.000 1.000
50.840 60.000 1.000
50.900 57.000 1.000
50.960 67.000 1.000
51.020 58.000 1.000
51.080 55.000 1.000
51.140 72.000 1.000
51.200 59.000 1.000
51.260 61.000 1.000
51.320 67.000 1.000
51.380 63.000 1.000
51.440 67.000 1.000
51.500 62.000 1.000
51.560 72.000 1.000
51.620 64.000 1.000
51.680 65.000 1.000
51.740 72.000 1.000
51.800 75.000 1.000
51.860 70.000 1.000
51.920 72.000 1.000
51.980 64.000 1.000
52.040 73.000 1.000
52.100 66.000 1.000
52.160 79.000 1.000
52.220 76.000 1.000
52.280 84.000 1.000
52.340 87.000 1.000
52.400 82.000 1.000
52.460 99.000 1.000
52.520 97.000 1.000
52.580 100.000 1.000
52.640 105.000 1.000
52.700 92.000 1.000
52.760 109.000 1.000
52.820 94.000 1.000
52.880 103.000 1.000
52.940 109.000 1.000
53.000 106.000 1.000
53.060 115.000 1.000
53.120 110.000 1.000
53.180 120.000 1.000
53.240 117.000 1.000
53.300 122.000 1.000
53.360 130.000 1.000
53.420 144.000 1.000
53.480 161.000 1.000
53.540 176.000 1.000
53.600 173.000 1.000
53.660 185.000 1.000
53.720 220.000 1.000
53.780 259.000 1.000
53.840 290.000 1.000
53.900 353.000 1.000
53.960 435.000 1.000
54.020 590.000 1.000
54.080 864.000 1.000
54.140 1276.000 1.000
54.200 1934.000 1.000
54.260 2699.000 1.000
54.320 3093.000 1.000
54.380 2957.000 1.000
54.440 2462.000 1.000
54.500 2025.000 1.000
54.560 1420.000 1.000
54.620 932.000 1.000
54.680 706.000 1.000
54.740 486.000 1.000
54.800 379.000 1.000
54.860 329.000 1.000
54.920 264.000 1.000
54.980 227.000 1.000
55.040 227.000 1.000
55.100 203.000 1.000
55.160 194.000 1.000
55.220 168.000 1.000
55.280 176.000 1.000
55.340 147.000 1.000
55.400 135.000 1.000
55.460 147.000 1.000
55.520 122.000 1.000
55.580 133.000 1.000
55.640 132.000 1.000
55.700 131.000 1.000
55.760 133.000 1.000
55.820 124.000 1.000
55.880 139.000 1.000
55.940 133.000 1.000
56.000 133.000 1.000
56.060 157.000 1.000
56.120 164.000 1.000
56.180 167.000 1.000
56.240 233.000 1.000
56.300 287.000 1.000
56.360 395.000 1.000
56.420 572.000 1.000
56.480 828.000 1.000
56.540 969.000 1.000
56.600 1017.000 1.000
56.660 947.000 1.000
56.720 772.000 1.000
56.780 620.000 1.000
56.840 456.000 1.000
56.900 343.000 1.000
56.960 238.000 1.000
57.020 197.000 1.000
57.080 157.000 1.000
57.140 141.000 1.000
57.200 137.000 1.000
57.260 124.000 1.000
57.320 115.000 1.000
57.380 109.000 1.000
57.440 102.000 1.000
57.500 104.000 1.000
57.560 107.000 1.000
57.620 99.000 1.000
57.680 86.000 1.000
57.740 82.000 1.000
57.800 84.000 1.000
57.860 75.000 1.000
57.920 88.000 1.000
57.980 73.000 1.000
58.040 69.000 1.000
58.100 76.000 1.000
58.160 76.000 1.000
58.220 66.000 1.000
58.280 73.000 1.000
58.340 56.000 1.000
58.400 79.000 1.000
58.460 79.000 1.000
58.520 73.000 1.000
58.580 75.000 1.000
58.640 74.000 1.000
58.700 70.000 1.000
58.760 72.000 1.000
58.820 70.000 1.000
58.880 69.000 1.000
58.940 80.000 1.000
59.000 67.000 1.000
59.060 63.000 1.000
59.120 58.000 1.000
59.180 69.000 1.000
59.240 61.000 1.000
59.300 75.000 1.000
59.360 66.000 1.000
59.420 61.000 1.000
59.480 69.000 1.000
59.540 65.000 1.000
59.600 57.000 1.000
59.660 60.000 1.000
59.720 71.000 1.000
59.780 73.000 1.000
59.840 59.000 1.000
59.900 62.000 1.000
59.960 59.000 1.000
60.020 62.000 1.000
60.080 56.000 1.000
60.140 64.000 1.000
60.200 65.000 1.000
60.260 52.000 1.000
60.320 67.000 1.000
60.380 48.000 1.000
60.440 61.000 1.000
60.500 59.000 1.000
60.560 66.000 1.000
60.620 63.000 1.000
60.680 62.000 1.000
60.740 68.000 1.000
60.800 54.000 1.000
60.860 65.000 1.000
60.920 60.000 1.000
60.980 59.000 1.000
61.040 73.000 1.000
61.100 60.000 1.000
61.160 53.000 1.000
61.220 60.000 1.000
61.280 58.000 1.000
61.340 60.000 1.000
61.400 58.000 1.000
61.460 66.000 1.000
61.520 64.000 1.000
61.580 54.000 1.000
61.640 61.000 1.000
61.700 72.000 1.000
61.760 62.000 1.000
61.820 64.000 1.000
61.880 68.000 1.000
61.940 65.000 1.000
62.000 68.000 1.000
62.060 74.000 1.000
62.120 67.000 1.000
62.180 69.000 1.000
62.240 62.000 1.000
62.300 76.000 1.000
62.360 73.000 1.000
62.420 81.000 1.000
62.480 82.000 1.000
62.540 91.000 1.000
62.600 111.000 1.000
62.660 143.000 1.000
62.720 244.000 1.000
62.780 457.000 1.000
62.840 673.000 1.000
62.900 462.000 1.000
62.960 405.000 1.000
63.020 421.000 1.000
63.080 247.000 1.000
63.140 167.000 1.000
63.200 119.000 1.000
63.260 118.000 1.000
63.320 103.000 1.000
63.380 99.000 1.000
63.440 97.000 1.000
63.500 104.000 1.000
63.560 113.000 1.000
63.620 132.000 1.000
63.680 150.000 1.000
63.740 177.000 1.000
63.800 244.000 1.000
63.860 319.000 1.000
63.920 358.000 1.000
63.980 406.000 1.000
64.040 392.000 1.000
64.100 365.000 1.000
64.160 325.000 1.000
64.220 284.000 1.000
64.280 237.000 1.000
64.340 173.000 1.000
64.400 134.000 1.000
64.460 131.000 1.000
64.520 112.000 1.000
64.580 109.000 1.000
64.640 119.000 1.000
64.700 80.000 1.000
64.760 85.000 1.000
64.820 78.000 1.000
64.880 76.000 1.000
64.940 83.000 1.000
65.000 73.000 1.000
65.060 72.000 1.000
65.120 75.000 1.000
65.180 69.000 1.000
65.240 74.000 1.000
65.300 82.000 1.000
65.360 93.000 1.000
65.420 88.000 1.000
65.480 93.000 1.000
65.540 100.000 1.000
65.600 87.000 1.000
65.660 89.000 1.000
65.720 78.000 1.000
65.780 68.000 1.000
65.840 68.000 1.000
65.900 60.000 1.000
65.960 61.000 1.000
66.020 60.000 1.000
66.080 57.000 1.000
66.140 56.000 1.000
66.200 66.000 1.000
66.260 59.000 1.000
66.320 58.000 1.000
66.380 63.000 1.000
66.440 60.000 1.000
66.500 61.000 1.000
66.560 62.000 1.000
66.620 62.000 1.000
66.680 70.000 1.000
66.740 64.000 1.000
66.800 53.000 1.000
66.860 61.000 1.000
66.920 56.000 1.000
66.980 61.000 1.000
67.040 70.000 1.000
67.100 71.000 1.000
67.160 80.000 1.000
67.220 74.000 1.000
67.280 61.000 1.000
67.340 69.000 1.000
67.400 68.000 1.000
67.460 70.000 1.000
67.520 62.000 1.000
67.580 82.000 1.000
67.640 62.000 1.000
67.700 71.000 1.000
67.760 72.000 1.000
67.820 66.000 1.000
67.880 83.000 1.000
67.940 79.000 1.000
68.000 83.000 1.000
68.060 87.000 1.000
68.120 96.000 1.000
68.180 95.000 1.000
68.240 107.000 1.000
68.300 128.000 1.000
68.360 123.000 1.000
68.420 145.000 1.000
68.480 157.000 1.000
68.540 186.000 1.000
68.600 226.000 1.000
68.660 262.000 1.000
68.720 365.000 1.000
68.780 498.000 1.000
68.840 679.000 1.000
68.900 831.000 1.000
68.960 957.000 1.000
69.020 911.000 1.000
69.080 814.000 1.000
69.140 713.000 1.000
69.200 585.000 1.000
69.260 480.000 1.000
69.320 375.000 1.000
69.380 282.000 1.000
69.440 263.000 1.000
69.500 225.000 1.000
69.560 226.000 1.000
69.620 233.000 1.000
69.680 252.000 1.000
69.740 391.000 1.000
69.800 560.000 1.000
69.860 605.000 1.000
69.920 536.000 1.000
69.980 441.000 1.000
70.040 453.000 1.000
70.100 343.000 1.000
70.160 252.000 1.000
70.220 167.000 1.000
70.280 146.000 1.000
70.340 120.000 1.000
70.400 102.000 1.000
70.460 82.000 1.000
70.520 75.000 1.000
70.580 83.000 1.000
70.640 80.000 1.000
70.700 75.000 1.000
70.760 68.000 1.000
70.820 66.000 1.000
70.880 60.000 1.000
70.940 70.000 1.000
71.000 52.000 1.000
71.060 74.000 1.000
71.120 65.000 1.000
71.180 67.000 1.000
71.240 54.000 1.000
71.300 58.000 1.000
71.360 57.000 1.000
71.420 57.000 1.000
71.480 59.000 1.000
71.540 64.000 1.000
71.600 51.000 1.000
71.660 65.000 1.000
71.720 56.000 1.000
71.780 54.000 1.000
71.840 54.000 1.000
71.900 49.000 1.000
71.960 62.000 1.000
72.020 58.000 1.000
72.080 72.000 1.000
72.140 78.000 1.000
72.200 76.000 1.000
72.260 106.000 1.000
72.320 104.000 1.000
72.380 106.000 1.000
72.440 107.000 1.000
72.500 92.000 1.000
72.560 84.000 1.000
72.620 75.000 1.000
72.680 77.000 1.000
72.740 63.000 1.000
72.800 54.000 1.000
72.860 63.000 1.000
72.920 63.000 1.000
72.980 57.000 1.000
73.040 39.000 1.000
73.100 62.000 1.000
73.160 55.000 1.000
73.220 52.000 1.000
73.280 48.000 1.000
73.340 48.000 1.000
73.400 47.000 1.000
73.460 51.000 1.000
73.520 51.000 1.000
73.580 51.000 1.000
73.640 53.000 1.000
73.700 46.000 1.000
73.760 43.000 1.000
73.820 53.000 1.000
73.880 53.000 1.000
73.940 51.000 1.000
74.000 52.000 1.000
74.060 54.000 1.000
74.120 58.000 1.000
74.180 45.000 1.000
74.240 58.000 1.000
74.300 60.000 1.000
74.360 59.000 1.000
74.420 73.000 1.000
74.480 56.000 1.000
74.540 49.000 1.000
74.600 58.000 1.000
74.660 47.000 1.000
74.720 50.000 1.000
74.780 47.000 1.000
74.840 53.000 1.000
74.900 54.000 1.000
74.960 42.000 1.000
75.020 46.000 1.000
75.080 53.000 1.000
75.140 50.000 1.000
75.200 38.000 1.000
75.260 44.000 1.000
75.320 43.000 1.000
75.380 50.000 1.000
75.440 50.000 1.000
75.500 38.000 1.000
75.560 45.000 1.000
75.620 51.000 1.000
75.680 41.000 1.000
75.740 48.000 1.000
75.800 59.000 1.000
75.860 55.000 1.000
75.920 50.000 1.000
75.980 51.000 1.000
76.040 46.000 1.000
76.100 55.000 1.000
76.160 53.000 1.000
76.220 59.000 1.000
76.280 64.000 1.000
76.340 72.000 1.000
76.400 77.000 1.000
76.460 105.000 1.000
76.520 133.000 1.000
76.580 127.000 1.000
76.640 117.000 1.000
76.700 118.000 1.000
76.760 107.000 1.000
76.820 95.000 1.000
76.880 71.000 1.000
76.940 81.000 1.000
77.000 64.000 1.000
77.060 64.000 1.000
77.120 49.000 1.000
77.180 58.000 1.000
77.240 49.000 1.000
77.300 47.000 1.000
77.360 48.000 1.000
77.420 46.000 1.000
77.480 46.000 1.000
77.540 40.000 1.000
77.600 40.000 1.000
77.660 44.000 1.000
77.720 38.000 1.000
77.780 43.000 1.000
77.840 46.000 1.000
77.900 41.000 1.000
77.960 48.000 1.000
78.020 45.000 1.000
78.080 41.000 1.000
78.140 39.000 1.000
78.200 43.000 1.000
78.260 47.000 1.000
78.320 41.000 1.000
78.380 39.000 1.000
78.440 45.000 1.000
78.500 44.000 1.000
78.560 34.000 1.000
78.620 42.000 1.000
78.680 42.000 1.000
78.740 48.000 1.000
78.800 40.000 1.000
78.860 38.000 1.000
78.920 38.000 1.000
78.980 47.000 1.000
79.040 40.000 1.000
79.100 47.000 1.000
79.160 42.000 1.000
79.220 41.000 1.000
79.280 46.000 1.000
79.340 51.000 1.000
79.400 54.000 1.000
79.460 57.000 1.000
79.520 51.000 1.000
79.580 54.000 1.000
79.640 58.000 1.000
79.700 61.000 1.000
79.760 82.000 1.000
79.820 97.000 1.000
79.880 96.000 1.000
79.940 82.000 1.000
80.000 88.000 1.000
80.060 82.000 1.000
80.120 68.000 1.000
80.180 64.000 1.000
80.240 53.000 1.000
80.300 60.000 1.000
80.360 59.000 1.000
80.420 49.000 1.000
80.480 46.000 1.000
80.540 44.000 1.000
80.600 42.000 1.000
80.660 41.000 1.000
80.720 49.000 1.000
80.780 42.000 1.000
80.840 49.000 1.000
80.900 40.000 1.000
80.960 47.000 1.000
81.020 52.000 1.000
81.080 48.000 1.000
81.140 43.000 1.000
81.200 49.000 1.000
81.260 54.000 1.000
81.320 47.000 1.000
81.380 48.000 1.000
81.440 46.000 1.000
81.500 43.000 1.000
81.560 59.000 1.000
81.620 43.000 1.000
81.680 55.000 1.000
81.740 60.000 1.000
81.800 58.000 1.000
81.860 70.000 1.000
81.920 78.000 1.000
81.980 100.000 1.000
82.040 108.000 1.000
82.100 148.000 1.000
82.160 169.000 1.000
82.220 202.000 1.000
82.280 202.000 1.000
82.340 188.000 1.000
82.400 175.000 1.000
82.460 151.000 1.000
82.520 143.000 1.000
82.580 125.000 1.000
82.640 108.000 1.000
82.700 92.000 1.000
82.760 81.000 1.000
82.820 64.000 1.000
82.880 70.000 1.000
82.940 72.000 1.000
83.000 54.000 1.000
83.060 63.000 1.000
83.120 56.000 1.000
83.180 51.000 1.000
83.240 58.000 1.000
83.300 55.000 1.000
83.360 47.000 1.000
83.420 46.000 1.000
83.480 56.000 1.000
83.540 64.000 1.000
83.600 58.000 1.000
83.660 67.000 1.000
83.720 82.000 1.000
83.780 77.000 1.000
83.840 78.000 1.000
83.900 101.000 1.000
83.960 106.000 1.000
84.020 133.000 1.000
84.080 134.000 1.000
84.140 143.000 1.000
84.200 147.000 1.000
84.260 137.000 1.000
84.320 109.000 1.000
84.380 116.000 1.000
84.440 96.000 1.000
84.500 99.000 1.000
84.560 78.000 1.000
84.620 74.000 1.000
84.680 65.000 1.000
84.740 61.000 1.000
84.800 56.000 1.000
84.860 63.000 1.000
84.920 54.000 1.000
84.980 48.000 1.000
85.040 57.000 1.000
85.100 47.000 1.000
85.160 49.000 1.000
85.220 48.000 1.000
85.280 43.000 1.000
85.340 59.000 1.000
85.400 46.000 1.000
85.460 48.000 1.000
85.520 54.000 1.000
85.580 47.000 1.000
85.640 51.000 1.000
85.700 53.000 1.000
85.760 48.000 1.000
85.820 46.000 1.000
85.880 51.000 1.000
85.940 48.000 1.000
86.000 42.000 1.000
86.060 46.000 1.000
86.120 43.000 1.000
86.180 42.000 1.000
86.240 46.000 1.000
86.300 48.000 1.000
86.360 44.000 1.000
86.420 40.000 1.000
86.480 43.000 1.000
86.540 43.000 1.000
86.600 48.000 1.000
86.660 49.000 1.000
86.720 40.000 1.000
86.780 57.000 1.000
86.840 47.000 1.000
86.900 52.000 1.000
86.960 52.000 1.000
87.020 58.000 1.000
87.080 68.000 1.000
87.140 65.000 1.000
87.200 76.000 1.000
87.260 87.000 1.000
87.320 93.000 1.000
87.380 78.000 1.000
87.440 74.000 1.000
87.500 83.000 1.000
87.560 73.000 1.000
87.620 68.000 1.000
87.680 66.000 1.000
87.740 56.000 1.000
87.800 46.000 1.000
87.860 54.000 1.000
87.920 55.000 1.000
87.980 54.000 1.000
88.040 39.000 1.000
88.100 46.000 1.000
88.160 43.000 1.000
88.220 49.000 1.000
88.280 46.000 1.000
88.340 51.000 1.000
88.400 52.000 1.000
88.460 52.000 1.000
88.520 52.000 1.000
88.580 52.000 1.000
88.640 50.000 1.000
88.700 60.000 1.000
88.760 55.000 1.000
88.820 61.000 1.000
88.880 64.000 1.000
88.940 66.000 1.000
89.000 69.000 1.000
89.060 64.000 1.000
89.120 94.000 1.000
89.180 86.000 1.000
89.240 107.000 1.000
89.300 144.000 1.000
89.360 185.000 1.000
89.420 235.000 1.000
89.480 315.000 1.000
89.540 365.000 1.000
89.600 303.000 1.000
89.660 271.000 1.000
89.720 251.000 1.000
89.780 243.000 1.000
89.840 230.000 1.000
89.900 179.000 1.000
89.960 149.000 1.000
90.000 149.000 1.000
*RAS_INT_END
*RAS_DATA_END