File: ras-to-csv_converter_plotter/example/ras/TiO2-3-3h-BET.ras
*RAS_DATA_START
*RAS_HEADER_START
*CORR_POS_DB_NAME "correction_file_020419"
*CORR_POS_GONIO_RADIUS ""
*CORR_POS_NODE_INDEX01 ""
*CORR_POS_NODE_INDEX02 ""
*CORR_POS_NODE_INDEX03 ""
*CORR_POS_NODE_INDEX04 ""
*CORR_POS_NODE_INDEX05 ""
*CORR_POS_NODE_INDEX06 ""
*CORR_POS_NODE_INDEX07 ""
*CORR_POS_NODE_INDEX08 ""
*CORR_POS_NODE_INDEX09 ""
*CORR_POS_NODE_INDEX10 ""
*CORR_POS_NODE_INDEX11 ""
*CORR_POS_NODE_LABEL01 "Si(111)"
*CORR_POS_NODE_LABEL02 "Si(220)"
*CORR_POS_NODE_LABEL03 "Si(311)"
*CORR_POS_NODE_LABEL04 "Si(400)"
*CORR_POS_NODE_LABEL05 "Si(331)"
*CORR_POS_NODE_LABEL06 "Si(422)"
*CORR_POS_NODE_LABEL07 "Si(511)"
*CORR_POS_NODE_LABEL08 "Si(440)"
*CORR_POS_NODE_LABEL09 "Si(531)"
*CORR_POS_NODE_LABEL10 "Si(620)"
*CORR_POS_NODE_LABEL11 "Si(533)"
*CORR_POS_NODE_POS_CALC01 "28.4137"
*CORR_POS_NODE_POS_CALC02 "47.2707"
*CORR_POS_NODE_POS_CALC03 "56.0883"
*CORR_POS_NODE_POS_CALC04 "69.0934"
*CORR_POS_NODE_POS_CALC05 "76.3385"
*CORR_POS_NODE_POS_CALC06 "87.9915"
*CORR_POS_NODE_POS_CALC07 "94.9137"
*CORR_POS_NODE_POS_CALC08 "106.67"
*CORR_POS_NODE_POS_CALC09 "114.054"
*CORR_POS_NODE_POS_CALC10 "127.508"
*CORR_POS_NODE_POS_CALC11 "136.858"
*CORR_POS_NODE_POS_MEAS01 "28.463"
*CORR_POS_NODE_POS_MEAS02 "47.3124"
*CORR_POS_NODE_POS_MEAS03 "56.1276"
*CORR_POS_NODE_POS_MEAS04 "69.1418"
*CORR_POS_NODE_POS_MEAS05 "76.3865"
*CORR_POS_NODE_POS_MEAS06 "88.0411"
*CORR_POS_NODE_POS_MEAS07 "94.9598"
*CORR_POS_NODE_POS_MEAS08 "106.713"
*CORR_POS_NODE_POS_MEAS09 "114.102"
*CORR_POS_NODE_POS_MEAS10 "127.558"
*CORR_POS_NODE_POS_MEAS11 "136.911"
*CORR_POS_OPT_ATTR "集中法"
*CORR_POS_PARAM_MU ""
*CORR_POS_PARAM_PL ""
*CORR_POS_SEMODEL_TYPE "0"
*CORR_POS_STANDARD_TYPE ""
*CORR_POS_VALUE_ANALYZER "None"
*CORR_POS_VALUE_CMONO "None"
*CORR_POS_VALUE_IMONO "None"
*CORR_POS_VALUE_IS "0.625deg"
*CORR_POS_VALUE_ISL "10.0mm"
*CORR_POS_VALUE_ISOLLER "2.5deg"
*CORR_POS_VALUE_RS1 "13.0mm"
*CORR_POS_VALUE_RS2 "13.0mm"
*CORR_POS_VALUE_RSOLLER "2.5deg"
*CORR_POS_XG_FOCUS_L ""
*CORR_POS_XG_WAVE_TYPE ""
*CORR_POS_XG_WAVE_VALUE ""
*DISP_FMT_X "%.2f"
*DISP_FMT_Y "%.0f"
*DISP_FULLSCALE "17390.0000000000"
*DISP_LINE_COLOR "255.0000000000"
*DISP_LINE_STYLE "0.0000000000"
*DISP_LINE_WIDTH "0.2500000000"
*DISP_NOTE "Collected Data-1"
*DISP_OFFSET_Y "0.0000000000"
*DISP_PEAKSEARCH_UNIT_Y "cps"
*DISP_RANGE_BOTTOM "0.0000000000"
*DISP_RANGE_LEFT "5.0000000000"
*DISP_RANGE_LOGCUTOFF "0.0100000000"
*DISP_RANGE_RIGHT "90.0000000000"
*DISP_RANGE_TOP "17390.0000000000"
*DISP_SCALE_MODE_Y "0.0000000000"
*DISP_TAB_NAME "Theta/2-Theta"
*DISP_TITLE_Y "Intensity"
*DISP_UNIT_Y "cps"
*DISP_WINDOW_NAME "MSG_MACROENGINE"
*FILE_COMMENT " "
*FILE_MD5 ""
*FILE_MEMO " "
*FILE_OPERATOR "SDU_RIGAKU"
*FILE_SAMPLE "TiO2-3-3h-BET"
*FILE_TYPE "RAS_RAW"
*FILE_USERGROUP "System User"
*FILE_VERSION "1.0000000000"
*HW_ATTACHMENT_ID "ATT1031"
*HW_ATTACHMENT_NAME "6サンプルチェンジャ|ASC-6"
*HW_COUNTER_ID-0 "CUT0025"
*HW_COUNTER_ID-1 "CUT0020"
*HW_COUNTER_ID-2 "CUT0020"
*HW_COUNTER_ID-3 "CMC0021"
*HW_COUNTER_NAME-0 "D/teX Ultra|D/teX Ultra"
*HW_COUNTER_NAME-1 "None|None"
*HW_COUNTER_NAME-2 "None|None"
*HW_COUNTER_NAME-3 "検出器モノクロメータ|Detector monochromator"
*HW_COUNTER_SELECT_NAME "D/teX Ultra|D/teX Ultra"
*HW_GONIOMETER_ID "GON0070"
*HW_GONIOMETER_NAME "MiniFlex 300/600|MiniFlex 300/600"
*HW_GONIOMETER_RADIUS-0 "79.0"
*HW_GONIOMETER_RADIUS-1 "91.5"
*HW_GONIOMETER_RADIUS-2 "150.0"
*HW_GONIOMETER_RADIUS-3 "0"
*HW_GONIOMETER_RADIUS-4 "103.4"
*HW_GONIOMETER_RADIUS-5 "150.0"
*HW_GONIOMETER_RADIUS-6 "46.6"
*HW_GONIOMETER_RADIUS-7 "160.0"
*HW_I_OPT_ID-0 "ISL0021"
*HW_I_OPT_ID-1 "ISO0021"
*HW_I_OPT_NAME-0 "発散スリット|Divergence slit"
*HW_I_OPT_NAME-1 "入射平行スリット|Incident parallel slit"
*HW_R_ATTENUATER_AUTOMODE "0"
*HW_R_OPT_ID-0 "RSS0021"
*HW_R_OPT_ID-1 "RSO0021"
*HW_R_OPT_ID-2 "RRS0021"
*HW_R_OPT_NAME-0 "散乱スリット|Scattering slit"
*HW_R_OPT_NAME-1 "受光平行スリット|Receiving soller slit"
*HW_R_OPT_NAME-2 "受光スリット|Receiving slit"
*HW_SAMPLE_HOLDER_ID "SMP0000"
*HW_SAMPLE_HOLDER_NAME "無し|None"
*HW_XG_CURRENT_MAX "15"
*HW_XG_CURRENT_MIN "2"
*HW_XG_CURRENT_RESOLUTION "1"
*HW_XG_CURRENT_UNIT "mA"
*HW_XG_FOCUS "1mm x 10mm"
*HW_XG_FOCUS_TYPE "Normal"
*HW_XG_ID ""
*HW_XG_NAME "300W/600W 封入管-B|300W/600W Sealed tube-B"
*HW_XG_TARGET_ATOMIC_NUMBER "29.0000000000"
*HW_XG_TARGET_NAME "Cu"
*HW_XG_TYPE "Hermetic"
*HW_XG_VOLTAGE_MAX "40"
*HW_XG_VOLTAGE_MIN "20"
*HW_XG_VOLTAGE_RESOLUTION "1"
*HW_XG_VOLTAGE_UNIT "kV"
*HW_XG_WATT_MAX "1"
*HW_XG_WATT_UNIT "kW"
*HW_XG_WAVE_LENGTH_ALPHA1 "1.540593"
*HW_XG_WAVE_LENGTH_ALPHA2 "1.544414"
*HW_XG_WAVE_LENGTH_BETA "1.392250"
*MEAS_COND_AXIS_NAME-0 "Theta/2-Theta"
*MEAS_COND_AXIS_NAME-1 "Spin"
*MEAS_COND_AXIS_NAME-2 "Change"
*MEAS_COND_AXIS_NAME-3 "Soller(inc.)"
*MEAS_COND_AXIS_NAME-4 "IHS"
*MEAS_COND_AXIS_NAME-5 "DS"
*MEAS_COND_AXIS_NAME-6 "SS"
*MEAS_COND_AXIS_NAME-7 "Soller(rec.)"
*MEAS_COND_AXIS_NAME-8 "RS"
*MEAS_COND_AXIS_NAME-9 "Filter"
*MEAS_COND_AXIS_NAME-10 "Monochromator"
*MEAS_COND_AXIS_NAME-11 "PHA"
*MEAS_COND_AXIS_NAME_INTERNAL-0 "TwoThetaTheta"
*MEAS_COND_AXIS_NAME_INTERNAL-1 "Spin"
*MEAS_COND_AXIS_NAME_INTERNAL-2 "Change"
*MEAS_COND_AXIS_NAME_INTERNAL-3 "IncidentSollerSlit"
*MEAS_COND_AXIS_NAME_INTERNAL-4 "IncidentAxdSlit"
*MEAS_COND_AXIS_NAME_INTERNAL-5 "IncidentSlitBox"
*MEAS_COND_AXIS_NAME_INTERNAL-6 "ReceivingSlitBox1"
*MEAS_COND_AXIS_NAME_INTERNAL-7 "ReceivingSollerSlit"
*MEAS_COND_AXIS_NAME_INTERNAL-8 "ReceivingSlitBox2"
*MEAS_COND_AXIS_NAME_INTERNAL-9 "Filter"
*MEAS_COND_AXIS_NAME_INTERNAL-10 "CounterMonochromator"
*MEAS_COND_AXIS_NAME_INTERNAL-11 "PHA"
*MEAS_COND_AXIS_NAME_MAGICNO-0 "268632064.0000000000"
*MEAS_COND_AXIS_NAME_MAGICNO-1 "16842752.0000000000"
*MEAS_COND_AXIS_NAME_MAGICNO-2 "16842752.0000000000"
*MEAS_COND_AXIS_NAME_MAGICNO-3 "20971521.0000000000"
*MEAS_COND_AXIS_NAME_MAGICNO-4 "22020097.0000000000"
*MEAS_COND_AXIS_NAME_MAGICNO-5 "22020097.0000000000"
*MEAS_COND_AXIS_NAME_MAGICNO-6 "23068673.0000000000"
*MEAS_COND_AXIS_NAME_MAGICNO-7 "20971521.0000000000"
*MEAS_COND_AXIS_NAME_MAGICNO-8 "23068673.0000000000"
*MEAS_COND_AXIS_NAME_MAGICNO-9 "20971521.0000000000"
*MEAS_COND_AXIS_NAME_MAGICNO-10 "20971521.0000000000"
*MEAS_COND_AXIS_NAME_MAGICNO-11 "0.0000000000"
*MEAS_COND_AXIS_OFFSET-0 "0.0000000000"
*MEAS_COND_AXIS_OFFSET-1 "-"
*MEAS_COND_AXIS_OFFSET-2 "-"
*MEAS_COND_AXIS_OFFSET-3 "-"
*MEAS_COND_AXIS_OFFSET-4 "-"
*MEAS_COND_AXIS_OFFSET-5 "-"
*MEAS_COND_AXIS_OFFSET-6 "-"
*MEAS_COND_AXIS_OFFSET-7 "-"
*MEAS_COND_AXIS_OFFSET-8 "-"
*MEAS_COND_AXIS_OFFSET-9 "-"
*MEAS_COND_AXIS_OFFSET-10 "-"
*MEAS_COND_AXIS_OFFSET-11 "-"
*MEAS_COND_AXIS_POSITION-0 "10.0000000000"
*MEAS_COND_AXIS_POSITION-1 "0.0000000000"
*MEAS_COND_AXIS_POSITION-2 "3.0000000000"
*MEAS_COND_AXIS_POSITION-3 "2.5deg"
*MEAS_COND_AXIS_POSITION-4 "10.0mm"
*MEAS_COND_AXIS_POSITION-5 "0.625deg"
*MEAS_COND_AXIS_POSITION-6 "13.0mm"
*MEAS_COND_AXIS_POSITION-7 "2.5deg"
*MEAS_COND_AXIS_POSITION-8 "13.0mm"
*MEAS_COND_AXIS_POSITION-9 "K-beta(x1)"
*MEAS_COND_AXIS_POSITION-10 "None"
*MEAS_COND_AXIS_POSITION-11 "42.0000000000"
*MEAS_COND_AXIS_UNIT-0 "deg"
*MEAS_COND_AXIS_UNIT-1 ""
*MEAS_COND_AXIS_UNIT-2 ""
*MEAS_COND_AXIS_UNIT-3 ""
*MEAS_COND_AXIS_UNIT-4 ""
*MEAS_COND_AXIS_UNIT-5 ""
*MEAS_COND_AXIS_UNIT-6 ""
*MEAS_COND_AXIS_UNIT-7 ""
*MEAS_COND_AXIS_UNIT-8 ""
*MEAS_COND_AXIS_UNIT-9 ""
*MEAS_COND_AXIS_UNIT-10 ""
*MEAS_COND_AXIS_UNIT-11 "div"
*MEAS_COND_CORRECTION_SLIT_COUNTERMONO "None"
*MEAS_COND_CORRECTION_SLIT_DS "0.625deg"
*MEAS_COND_CORRECTION_SLIT_FILTER "None"
*MEAS_COND_CORRECTION_SLIT_IHS "10.0mm"
*MEAS_COND_CORRECTION_SLIT_RS "13.0mm"
*MEAS_COND_CORRECTION_SLIT_SOLLER_INC "2.5deg"
*MEAS_COND_CORRECTION_SLIT_SOLLER_REC "2.5deg"
*MEAS_COND_CORRECTION_SLIT_SS "13.0mm"
*MEAS_COND_COUNTER_CNTLOSS_CORR "0.0000000000"
*MEAS_COND_COUNTER_PHABASE "42.0000000000"
*MEAS_COND_COUNTER_PHAWINDOW "15.0000000000"
*MEAS_COND_COUNTER_PHA_UNIT "div"
*MEAS_COND_COUNTER_TAUDIFF "0.2500000000"
*MEAS_COND_COUNTER_TAUINT "0.7500000000"
*MEAS_COND_IRRADIATION_MODE "OFF"
*MEAS_COND_IRRADIATION_WIDTH ""
*MEAS_COND_OPT_ATTR " "
*MEAS_COND_OPT_NAME ""
*MEAS_COND_UNSYMMETRIC_MODE "OFF"
*MEAS_COND_XG_CURRENT "15.0000000000"
*MEAS_COND_XG_VOLTAGE "40.0000000000"
*MEAS_COND_XG_WAVE_TYPE "Ka"
*MEAS_DATA_COUNT "4251.0000000000"
*MEAS_SCAN_AXIS_X "Theta/2-Theta"
*MEAS_SCAN_AXIS_X_INTERNAL "TwoThetaTheta"
*MEAS_SCAN_END_TIME "04/16/19 11:52:37"
*MEAS_SCAN_MODE "CONTINUOUS"
*MEAS_SCAN_MONITOR "0"
*MEAS_SCAN_RESOLUTION_X "0.005"
*MEAS_SCAN_SPEED "10.000"
*MEAS_SCAN_SPEED_UNIT "deg/min"
*MEAS_SCAN_START "5.0000000000"
*MEAS_SCAN_START_TIME "04/16/19 11:43:21"
*MEAS_SCAN_STEP "0.0200000000"
*MEAS_SCAN_STOP "90.0000000000"
*MEAS_SCAN_UNIT_X "deg"
*MEAS_SCAN_UNIT_Y "counts"
*SLIT_SYSTEM "0"
*RAS_HEADER_END
*RAS_INT_START
5.000 527.000 1.000
5.060 524.000 1.000
5.120 584.000 1.000
5.180 476.000 1.000
5.240 483.000 1.000
5.300 439.000 1.000
5.360 451.000 1.000
5.420 396.000 1.000
5.480 441.000 1.000
5.540 388.000 1.000
5.600 414.000 1.000
5.660 412.000 1.000
5.720 393.000 1.000
5.780 355.000 1.000
5.840 336.000 1.000
5.900 350.000 1.000
5.960 340.000 1.000
6.020 344.000 1.000
6.080 358.000 1.000
6.140 345.000 1.000
6.200 328.000 1.000
6.260 319.000 1.000
6.320 296.000 1.000
6.380 297.000 1.000
6.440 296.000 1.000
6.500 302.000 1.000
6.560 266.000 1.000
6.620 269.000 1.000
6.680 288.000 1.000
6.740 254.000 1.000
6.800 257.000 1.000
6.860 261.000 1.000
6.920 269.000 1.000
6.980 246.000 1.000
7.040 232.000 1.000
7.100 238.000 1.000
7.160 247.000 1.000
7.220 254.000 1.000
7.280 232.000 1.000
7.340 221.000 1.000
7.400 220.000 1.000
7.460 223.000 1.000
7.520 202.000 1.000
7.580 229.000 1.000
7.640 223.000 1.000
7.700 227.000 1.000
7.760 219.000 1.000
7.820 205.000 1.000
7.880 226.000 1.000
7.940 204.000 1.000
8.000 189.000 1.000
8.060 212.000 1.000
8.120 214.000 1.000
8.180 208.000 1.000
8.240 177.000 1.000
8.300 189.000 1.000
8.360 192.000 1.000
8.420 190.000 1.000
8.480 192.000 1.000
8.540 182.000 1.000
8.600 190.000 1.000
8.660 196.000 1.000
8.720 207.000 1.000
8.780 175.000 1.000
8.840 190.000 1.000
8.900 174.000 1.000
8.960 183.000 1.000
9.020 190.000 1.000
9.080 171.000 1.000
9.140 156.000 1.000
9.200 173.000 1.000
9.260 203.000 1.000
9.320 165.000 1.000
9.380 172.000 1.000
9.440 171.000 1.000
9.500 174.000 1.000
9.560 188.000 1.000
9.620 157.000 1.000
9.680 173.000 1.000
9.740 177.000 1.000
9.800 161.000 1.000
9.860 164.000 1.000
9.920 163.000 1.000
9.980 170.000 1.000
10.040 166.000 1.000
10.100 153.000 1.000
10.160 156.000 1.000
10.220 145.000 1.000
10.280 160.000 1.000
10.340 160.000 1.000
10.400 153.000 1.000
10.460 162.000 1.000
10.520 169.000 1.000
10.580 175.000 1.000
10.640 161.000 1.000
10.700 153.000 1.000
10.760 153.000 1.000
10.820 178.000 1.000
10.880 157.000 1.000
10.940 170.000 1.000
11.000 153.000 1.000
11.060 156.000 1.000
11.120 158.000 1.000
11.180 151.000 1.000
11.240 156.000 1.000
11.300 163.000 1.000
11.360 160.000 1.000
11.420 159.000 1.000
11.480 170.000 1.000
11.540 171.000 1.000
11.600 163.000 1.000
11.660 137.000 1.000
11.720 151.000 1.000
11.780 146.000 1.000
11.840 157.000 1.000
11.900 160.000 1.000
11.960 148.000 1.000
12.020 145.000 1.000
12.080 146.000 1.000
12.140 144.000 1.000
12.200 151.000 1.000
12.260 145.000 1.000
12.320 145.000 1.000
12.380 155.000 1.000
12.440 149.000 1.000
12.500 150.000 1.000
12.560 129.000 1.000
12.620 159.000 1.000
12.680 139.000 1.000
12.740 155.000 1.000
12.800 155.000 1.000
12.860 136.000 1.000
12.920 137.000 1.000
12.980 147.000 1.000
13.040 154.000 1.000
13.100 149.000 1.000
13.160 140.000 1.000
13.220 145.000 1.000
13.280 141.000 1.000
13.340 147.000 1.000
13.400 149.000 1.000
13.460 133.000 1.000
13.520 148.000 1.000
13.580 152.000 1.000
13.640 141.000 1.000
13.700 164.000 1.000
13.760 154.000 1.000
13.820 158.000 1.000
13.880 151.000 1.000
13.940 171.000 1.000
14.000 169.000 1.000
14.060 173.000 1.000
14.120 147.000 1.000
14.180 172.000 1.000
14.240 165.000 1.000
14.300 170.000 1.000
14.360 176.000 1.000
14.420 173.000 1.000
14.480 153.000 1.000
14.540 173.000 1.000
14.600 144.000 1.000
14.660 167.000 1.000
14.720 154.000 1.000
14.780 143.000 1.000
14.840 152.000 1.000
14.900 156.000 1.000
14.960 145.000 1.000
15.020 156.000 1.000
15.080 148.000 1.000
15.140 153.000 1.000
15.200 148.000 1.000
15.260 162.000 1.000
15.320 141.000 1.000
15.380 152.000 1.000
15.440 155.000 1.000
15.500 158.000 1.000
15.560 137.000 1.000
15.620 146.000 1.000
15.680 134.000 1.000
15.740 141.000 1.000
15.800 138.000 1.000
15.860 144.000 1.000
15.920 141.000 1.000
15.980 117.000 1.000
16.040 121.000 1.000
16.100 129.000 1.000
16.160 139.000 1.000
16.220 125.000 1.000
16.280 127.000 1.000
16.340 115.000 1.000
16.400 126.000 1.000
16.460 143.000 1.000
16.520 122.000 1.000
16.580 125.000 1.000
16.640 118.000 1.000
16.700 124.000 1.000
16.760 121.000 1.000
16.820 112.000 1.000
16.880 136.000 1.000
16.940 129.000 1.000
17.000 115.000 1.000
17.060 129.000 1.000
17.120 110.000 1.000
17.180 119.000 1.000
17.240 123.000 1.000
17.300 134.000 1.000
17.360 127.000 1.000
17.420 128.000 1.000
17.480 118.000 1.000
17.540 131.000 1.000
17.600 115.000 1.000
17.660 108.000 1.000
17.720 111.000 1.000
17.780 117.000 1.000
17.840 114.000 1.000
17.900 109.000 1.000
17.960 106.000 1.000
18.020 112.000 1.000
18.080 116.000 1.000
18.140 124.000 1.000
18.200 109.000 1.000
18.260 126.000 1.000
18.320 117.000 1.000
18.380 113.000 1.000
18.440 112.000 1.000
18.500 111.000 1.000
18.560 112.000 1.000
18.620 109.000 1.000
18.680 109.000 1.000
18.740 101.000 1.000
18.800 124.000 1.000
18.860 113.000 1.000
18.920 114.000 1.000
18.980 106.000 1.000
19.040 119.000 1.000
19.100 118.000 1.000
19.160 102.000 1.000
19.220 109.000 1.000
19.280 112.000 1.000
19.340 114.000 1.000
19.400 103.000 1.000
19.460 99.000 1.000
19.520 105.000 1.000
19.580 101.000 1.000
19.640 113.000 1.000
19.700 111.000 1.000
19.760 108.000 1.000
19.820 108.000 1.000
19.880 109.000 1.000
19.940 90.000 1.000
20.000 112.000 1.000
20.060 108.000 1.000
20.120 109.000 1.000
20.180 104.000 1.000
20.240 84.000 1.000
20.300 101.000 1.000
20.360 93.000 1.000
20.420 98.000 1.000
20.480 118.000 1.000
20.540 102.000 1.000
20.600 112.000 1.000
20.660 104.000 1.000
20.720 109.000 1.000
20.780 112.000 1.000
20.840 112.000 1.000
20.900 104.000 1.000
20.960 99.000 1.000
21.020 109.000 1.000
21.080 116.000 1.000
21.140 104.000 1.000
21.200 105.000 1.000
21.260 105.000 1.000
21.320 103.000 1.000
21.380 99.000 1.000
21.440 115.000 1.000
21.500 109.000 1.000
21.560 118.000 1.000
21.620 99.000 1.000
21.680 94.000 1.000
21.740 111.000 1.000
21.800 115.000 1.000
21.860 101.000 1.000
21.920 105.000 1.000
21.980 97.000 1.000
22.040 105.000 1.000
22.100 112.000 1.000
22.160 108.000 1.000
22.220 109.000 1.000
22.280 118.000 1.000
22.340 103.000 1.000
22.400 112.000 1.000
22.460 109.000 1.000
22.520 112.000 1.000
22.580 107.000 1.000
22.640 114.000 1.000
22.700 123.000 1.000
22.760 121.000 1.000
22.820 117.000 1.000
22.880 115.000 1.000
22.940 110.000 1.000
23.000 142.000 1.000
23.060 124.000 1.000
23.120 133.000 1.000
23.180 130.000 1.000
23.240 124.000 1.000
23.300 132.000 1.000
23.360 130.000 1.000
23.420 135.000 1.000
23.480 153.000 1.000
23.540 149.000 1.000
23.600 139.000 1.000
23.660 155.000 1.000
23.720 159.000 1.000
23.780 153.000 1.000
23.840 161.000 1.000
23.900 149.000 1.000
23.960 165.000 1.000
24.020 164.000 1.000
24.080 155.000 1.000
24.140 174.000 1.000
24.200 188.000 1.000
24.260 164.000 1.000
24.320 171.000 1.000
24.380 189.000 1.000
24.440 183.000 1.000
24.500 192.000 1.000
24.560 208.000 1.000
24.620 202.000 1.000
24.680 196.000 1.000
24.740 208.000 1.000
24.800 204.000 1.000
24.860 209.000 1.000
24.920 207.000 1.000
24.980 208.000 1.000
25.040 217.000 1.000
25.100 224.000 1.000
25.160 212.000 1.000
25.220 215.000 1.000
25.280 241.000 1.000
25.340 221.000 1.000
25.400 213.000 1.000
25.460 223.000 1.000
25.520 233.000 1.000
25.580 209.000 1.000
25.640 230.000 1.000
25.700 234.000 1.000
25.760 210.000 1.000
25.820 225.000 1.000
25.880 225.000 1.000
25.940 204.000 1.000
26.000 221.000 1.000
26.060 219.000 1.000
26.120 207.000 1.000
26.180 208.000 1.000
26.240 209.000 1.000
26.300 208.000 1.000
26.360 218.000 1.000
26.420 214.000 1.000
26.480 218.000 1.000
26.540 219.000 1.000
26.600 238.000 1.000
26.660 257.000 1.000
26.720 263.000 1.000
26.780 290.000 1.000
26.840 299.000 1.000
26.900 326.000 1.000
26.960 409.000 1.000
27.020 475.000 1.000
27.080 592.000 1.000
27.140 756.000 1.000
27.200 1034.000 1.000
27.260 1354.000 1.000
27.320 1632.000 1.000
27.380 1739.000 1.000
27.440 1527.000 1.000
27.500 1260.000 1.000
27.560 915.000 1.000
27.620 706.000 1.000
27.680 522.000 1.000
27.740 440.000 1.000
27.800 357.000 1.000
27.860 322.000 1.000
27.920 257.000 1.000
27.980 265.000 1.000
28.040 228.000 1.000
28.100 231.000 1.000
28.160 226.000 1.000
28.220 205.000 1.000
28.280 200.000 1.000
28.340 176.000 1.000
28.400 183.000 1.000
28.460 180.000 1.000
28.520 173.000 1.000
28.580 164.000 1.000
28.640 165.000 1.000
28.700 161.000 1.000
28.760 149.000 1.000
28.820 154.000 1.000
28.880 147.000 1.000
28.940 155.000 1.000
29.000 130.000 1.000
29.060 142.000 1.000
29.120 129.000 1.000
29.180 137.000 1.000
29.240 142.000 1.000
29.300 130.000 1.000
29.360 132.000 1.000
29.420 120.000 1.000
29.480 127.000 1.000
29.540 104.000 1.000
29.600 115.000 1.000
29.660 114.000 1.000
29.720 123.000 1.000
29.780 127.000 1.000
29.840 111.000 1.000
29.900 125.000 1.000
29.960 113.000 1.000
30.020 121.000 1.000
30.080 122.000 1.000
30.140 111.000 1.000
30.200 113.000 1.000
30.260 118.000 1.000
30.320 109.000 1.000
30.380 107.000 1.000
30.440 100.000 1.000
30.500 106.000 1.000
30.560 98.000 1.000
30.620 92.000 1.000
30.680 111.000 1.000
30.740 102.000 1.000
30.800 105.000 1.000
30.860 90.000 1.000
30.920 98.000 1.000
30.980 89.000 1.000
31.040 95.000 1.000
31.100 94.000 1.000
31.160 87.000 1.000
31.220 87.000 1.000
31.280 94.000 1.000
31.340 94.000 1.000
31.400 88.000 1.000
31.460 96.000 1.000
31.520 93.000 1.000
31.580 78.000 1.000
31.640 81.000 1.000
31.700 86.000 1.000
31.760 72.000 1.000
31.820 77.000 1.000
31.880 74.000 1.000
31.940 75.000 1.000
32.000 85.000 1.000
32.060 77.000 1.000
32.120 80.000 1.000
32.180 75.000 1.000
32.240 76.000 1.000
32.300 69.000 1.000
32.360 81.000 1.000
32.420 79.000 1.000
32.480 71.000 1.000
32.540 77.000 1.000
32.600 84.000 1.000
32.660 71.000 1.000
32.720 81.000 1.000
32.780 75.000 1.000
32.840 77.000 1.000
32.900 74.000 1.000
32.960 73.000 1.000
33.020 82.000 1.000
33.080 82.000 1.000
33.140 76.000 1.000
33.200 76.000 1.000
33.260 72.000 1.000
33.320 75.000 1.000
33.380 74.000 1.000
33.440 77.000 1.000
33.500 78.000 1.000
33.560 77.000 1.000
33.620 70.000 1.000
33.680 68.000 1.000
33.740 64.000 1.000
33.800 70.000 1.000
33.860 74.000 1.000
33.920 77.000 1.000
33.980 64.000 1.000
34.040 72.000 1.000
34.100 74.000 1.000
34.160 68.000 1.000
34.220 84.000 1.000
34.280 68.000 1.000
34.340 77.000 1.000
34.400 68.000 1.000
34.460 78.000 1.000
34.520 67.000 1.000
34.580 66.000 1.000
34.640 79.000 1.000
34.700 89.000 1.000
34.760 81.000 1.000
34.820 82.000 1.000
34.880 86.000 1.000
34.940 75.000 1.000
35.000 80.000 1.000
35.060 86.000 1.000
35.120 81.000 1.000
35.180 95.000 1.000
35.240 91.000 1.000
35.300 102.000 1.000
35.360 106.000 1.000
35.420 117.000 1.000
35.480 111.000 1.000
35.540 122.000 1.000
35.600 134.000 1.000
35.660 150.000 1.000
35.720 170.000 1.000
35.780 179.000 1.000
35.840 254.000 1.000
35.900 319.000 1.000
35.960 494.000 1.000
36.020 778.000 1.000
36.080 896.000 1.000
36.140 796.000 1.000
36.200 586.000 1.000
36.260 377.000 1.000
36.320 284.000 1.000
36.380 198.000 1.000
36.440 169.000 1.000
36.500 169.000 1.000
36.560 126.000 1.000
36.620 121.000 1.000
36.680 121.000 1.000
36.740 103.000 1.000
36.800 113.000 1.000
36.860 106.000 1.000
36.920 102.000 1.000
36.980 114.000 1.000
37.040 95.000 1.000
37.100 98.000 1.000
37.160 95.000 1.000
37.220 96.000 1.000
37.280 98.000 1.000
37.340 97.000 1.000
37.400 92.000 1.000
37.460 87.000 1.000
37.520 102.000 1.000
37.580 91.000 1.000
37.640 90.000 1.000
37.700 79.000 1.000
37.760 83.000 1.000
37.820 93.000 1.000
37.880 102.000 1.000
37.940 84.000 1.000
38.000 82.000 1.000
38.060 84.000 1.000
38.120 86.000 1.000
38.180 88.000 1.000
38.240 83.000 1.000
38.300 80.000 1.000
38.360 81.000 1.000
38.420 78.000 1.000
38.480 92.000 1.000
38.540 88.000 1.000
38.600 87.000 1.000
38.660 87.000 1.000
38.720 79.000 1.000
38.780 87.000 1.000
38.840 99.000 1.000
38.900 111.000 1.000
38.960 114.000 1.000
39.020 127.000 1.000
39.080 141.000 1.000
39.140 134.000 1.000
39.200 134.000 1.000
39.260 120.000 1.000
39.320 97.000 1.000
39.380 95.000 1.000
39.440 87.000 1.000
39.500 87.000 1.000
39.560 76.000 1.000
39.620 76.000 1.000
39.680 67.000 1.000
39.740 65.000 1.000
39.800 70.000 1.000
39.860 68.000 1.000
39.920 63.000 1.000
39.980 77.000 1.000
40.040 68.000 1.000
40.100 75.000 1.000
40.160 79.000 1.000
40.220 73.000 1.000
40.280 68.000 1.000
40.340 68.000 1.000
40.400 77.000 1.000
40.460 75.000 1.000
40.520 71.000 1.000
40.580 62.000 1.000
40.640 77.000 1.000
40.700 82.000 1.000
40.760 86.000 1.000
40.820 90.000 1.000
40.880 101.000 1.000
40.940 146.000 1.000
41.000 159.000 1.000
41.060 237.000 1.000
41.120 357.000 1.000
41.180 427.000 1.000
41.240 458.000 1.000
41.300 381.000 1.000
41.360 306.000 1.000
41.420 200.000 1.000
41.480 147.000 1.000
41.540 112.000 1.000
41.600 102.000 1.000
41.660 89.000 1.000
41.720 81.000 1.000
41.780 89.000 1.000
41.840 71.000 1.000
41.900 72.000 1.000
41.960 73.000 1.000
42.020 70.000 1.000
42.080 64.000 1.000
42.140 70.000 1.000
42.200 59.000 1.000
42.260 55.000 1.000
42.320 65.000 1.000
42.380 65.000 1.000
42.440 63.000 1.000
42.500 63.000 1.000
42.560 67.000 1.000
42.620 69.000 1.000
42.680 66.000 1.000
42.740 58.000 1.000
42.800 60.000 1.000
42.860 58.000 1.000
42.920 65.000 1.000
42.980 60.000 1.000
43.040 67.000 1.000
43.100 70.000 1.000
43.160 79.000 1.000
43.220 62.000 1.000
43.280 69.000 1.000
43.340 74.000 1.000
43.400 81.000 1.000
43.460 80.000 1.000
43.520 87.000 1.000
43.580 99.000 1.000
43.640 95.000 1.000
43.700 109.000 1.000
43.760 131.000 1.000
43.820 167.000 1.000
43.880 155.000 1.000
43.940 166.000 1.000
44.000 173.000 1.000
44.060 143.000 1.000
44.120 130.000 1.000
44.180 103.000 1.000
44.240 106.000 1.000
44.300 97.000 1.000
44.360 77.000 1.000
44.420 87.000 1.000
44.480 62.000 1.000
44.540 80.000 1.000
44.600 60.000 1.000
44.660 72.000 1.000
44.720 70.000 1.000
44.780 63.000 1.000
44.840 69.000 1.000
44.900 55.000 1.000
44.960 57.000 1.000
45.020 71.000 1.000
45.080 66.000 1.000
45.140 58.000 1.000
45.200 50.000 1.000
45.260 55.000 1.000
45.320 51.000 1.000
45.380 63.000 1.000
45.440 64.000 1.000
45.500 62.000 1.000
45.560 46.000 1.000
45.620 64.000 1.000
45.680 62.000 1.000
45.740 53.000 1.000
45.800 54.000 1.000
45.860 50.000 1.000
45.920 49.000 1.000
45.980 56.000 1.000
46.040 55.000 1.000
46.100 58.000 1.000
46.160 61.000 1.000
46.220 62.000 1.000
46.280 46.000 1.000
46.340 61.000 1.000
46.400 63.000 1.000
46.460 51.000 1.000
46.520 59.000 1.000
46.580 63.000 1.000
46.640 50.000 1.000
46.700 59.000 1.000
46.760 51.000 1.000
46.820 68.000 1.000
46.880 68.000 1.000
46.940 55.000 1.000
47.000 61.000 1.000
47.060 68.000 1.000
47.120 64.000 1.000
47.180 70.000 1.000
47.240 70.000 1.000
47.300 71.000 1.000
47.360 59.000 1.000
47.420 83.000 1.000
47.480 83.000 1.000
47.540 70.000 1.000
47.600 67.000 1.000
47.660 66.000 1.000
47.720 72.000 1.000
47.780 73.000 1.000
47.840 72.000 1.000
47.900 79.000 1.000
47.960 59.000 1.000
48.020 86.000 1.000
48.080 79.000 1.000
48.140 72.000 1.000
48.200 74.000 1.000
48.260 68.000 1.000
48.320 59.000 1.000
48.380 74.000 1.000
48.440 76.000 1.000
48.500 82.000 1.000
48.560 72.000 1.000
48.620 75.000 1.000
48.680 68.000 1.000
48.740 78.000 1.000
48.800 70.000 1.000
48.860 65.000 1.000
48.920 66.000 1.000
48.980 83.000 1.000
49.040 71.000 1.000
49.100 65.000 1.000
49.160 67.000 1.000
49.220 66.000 1.000
49.280 68.000 1.000
49.340 73.000 1.000
49.400 53.000 1.000
49.460 64.000 1.000
49.520 60.000 1.000
49.580 48.000 1.000
49.640 61.000 1.000
49.700 61.000 1.000
49.760 60.000 1.000
49.820 62.000 1.000
49.880 67.000 1.000
49.940 63.000 1.000
50.000 62.000 1.000
50.060 48.000 1.000
50.120 62.000 1.000
50.180 67.000 1.000
50.240 56.000 1.000
50.300 48.000 1.000
50.360 43.000 1.000
50.420 49.000 1.000
50.480 45.000 1.000
50.540 41.000 1.000
50.600 51.000 1.000
50.660 46.000 1.000
50.720 50.000 1.000
50.780 44.000 1.000
50.840 50.000 1.000
50.900 54.000 1.000
50.960 46.000 1.000
51.020 55.000 1.000
51.080 55.000 1.000
51.140 57.000 1.000
51.200 47.000 1.000
51.260 54.000 1.000
51.320 46.000 1.000
51.380 40.000 1.000
51.440 50.000 1.000
51.500 47.000 1.000
51.560 51.000 1.000
51.620 47.000 1.000
51.680 50.000 1.000
51.740 42.000 1.000
51.800 57.000 1.000
51.860 59.000 1.000
51.920 60.000 1.000
51.980 58.000 1.000
52.040 61.000 1.000
52.100 56.000 1.000
52.160 59.000 1.000
52.220 56.000 1.000
52.280 64.000 1.000
52.340 64.000 1.000
52.400 57.000 1.000
52.460 60.000 1.000
52.520 71.000 1.000
52.580 78.000 1.000
52.640 78.000 1.000
52.700 78.000 1.000
52.760 70.000 1.000
52.820 75.000 1.000
52.880 87.000 1.000
52.940 73.000 1.000
53.000 85.000 1.000
53.060 86.000 1.000
53.120 80.000 1.000
53.180 90.000 1.000
53.240 97.000 1.000
53.300 93.000 1.000
53.360 94.000 1.000
53.420 100.000 1.000
53.480 125.000 1.000
53.540 125.000 1.000
53.600 141.000 1.000
53.660 133.000 1.000
53.720 147.000 1.000
53.780 174.000 1.000
53.840 198.000 1.000
53.900 235.000 1.000
53.960 280.000 1.000
54.020 387.000 1.000
54.080 527.000 1.000
54.140 657.000 1.000
54.200 808.000 1.000
54.260 861.000 1.000
54.320 786.000 1.000
54.380 690.000 1.000
54.440 560.000 1.000
54.500 417.000 1.000
54.560 343.000 1.000
54.620 270.000 1.000
54.680 226.000 1.000
54.740 200.000 1.000
54.800 200.000 1.000
54.860 146.000 1.000
54.920 144.000 1.000
54.980 130.000 1.000
55.040 136.000 1.000
55.100 136.000 1.000
55.160 102.000 1.000
55.220 118.000 1.000
55.280 118.000 1.000
55.340 104.000 1.000
55.400 100.000 1.000
55.460 93.000 1.000
55.520 93.000 1.000
55.580 81.000 1.000
55.640 93.000 1.000
55.700 79.000 1.000
55.760 92.000 1.000
55.820 82.000 1.000
55.880 83.000 1.000
55.940 95.000 1.000
56.000 101.000 1.000
56.060 123.000 1.000
56.120 119.000 1.000
56.180 143.000 1.000
56.240 155.000 1.000
56.300 193.000 1.000
56.360 248.000 1.000
56.420 291.000 1.000
56.480 291.000 1.000
56.540 275.000 1.000
56.600 239.000 1.000
56.660 203.000 1.000
56.720 181.000 1.000
56.780 145.000 1.000
56.840 118.000 1.000
56.900 95.000 1.000
56.960 107.000 1.000
57.020 89.000 1.000
57.080 89.000 1.000
57.140 70.000 1.000
57.200 86.000 1.000
57.260 87.000 1.000
57.320 73.000 1.000
57.380 77.000 1.000
57.440 65.000 1.000
57.500 73.000 1.000
57.560 59.000 1.000
57.620 58.000 1.000
57.680 65.000 1.000
57.740 59.000 1.000
57.800 62.000 1.000
57.860 67.000 1.000
57.920 68.000 1.000
57.980 77.000 1.000
58.040 55.000 1.000
58.100 56.000 1.000
58.160 62.000 1.000
58.220 60.000 1.000
58.280 65.000 1.000
58.340 46.000 1.000
58.400 52.000 1.000
58.460 61.000 1.000
58.520 57.000 1.000
58.580 48.000 1.000
58.640 49.000 1.000
58.700 61.000 1.000
58.760 55.000 1.000
58.820 68.000 1.000
58.880 57.000 1.000
58.940 55.000 1.000
59.000 57.000 1.000
59.060 48.000 1.000
59.120 40.000 1.000
59.180 47.000 1.000
59.240 54.000 1.000
59.300 59.000 1.000
59.360 47.000 1.000
59.420 52.000 1.000
59.480 47.000 1.000
59.540 48.000 1.000
59.600 44.000 1.000
59.660 51.000 1.000
59.720 42.000 1.000
59.780 35.000 1.000
59.840 49.000 1.000
59.900 52.000 1.000
59.960 37.000 1.000
60.020 58.000 1.000
60.080 41.000 1.000
60.140 46.000 1.000
60.200 50.000 1.000
60.260 53.000 1.000
60.320 45.000 1.000
60.380 52.000 1.000
60.440 45.000 1.000
60.500 45.000 1.000
60.560 43.000 1.000
60.620 42.000 1.000
60.680 56.000 1.000
60.740 35.000 1.000
60.800 51.000 1.000
60.860 44.000 1.000
60.920 38.000 1.000
60.980 47.000 1.000
61.040 57.000 1.000
61.100 52.000 1.000
61.160 37.000 1.000
61.220 47.000 1.000
61.280 49.000 1.000
61.340 52.000 1.000
61.400 45.000 1.000
61.460 56.000 1.000
61.520 49.000 1.000
61.580 55.000 1.000
61.640 63.000 1.000
61.700 47.000 1.000
61.760 52.000 1.000
61.820 52.000 1.000
61.880 59.000 1.000
61.940 64.000 1.000
62.000 63.000 1.000
62.060 66.000 1.000
62.120 60.000 1.000
62.180 65.000 1.000
62.240 72.000 1.000
62.300 62.000 1.000
62.360 60.000 1.000
62.420 60.000 1.000
62.480 58.000 1.000
62.540 84.000 1.000
62.600 84.000 1.000
62.660 95.000 1.000
62.720 140.000 1.000
62.780 215.000 1.000
62.840 202.000 1.000
62.900 158.000 1.000
62.960 159.000 1.000
63.020 158.000 1.000
63.080 98.000 1.000
63.140 93.000 1.000
63.200 80.000 1.000
63.260 79.000 1.000
63.320 73.000 1.000
63.380 77.000 1.000
63.440 81.000 1.000
63.500 81.000 1.000
63.560 81.000 1.000
63.620 99.000 1.000
63.680 107.000 1.000
63.740 114.000 1.000
63.800 132.000 1.000
63.860 124.000 1.000
63.920 137.000 1.000
63.980 126.000 1.000
64.040 114.000 1.000
64.100 103.000 1.000
64.160 101.000 1.000
64.220 91.000 1.000
64.280 76.000 1.000
64.340 63.000 1.000
64.400 69.000 1.000
64.460 72.000 1.000
64.520 58.000 1.000
64.580 53.000 1.000
64.640 55.000 1.000
64.700 59.000 1.000
64.760 54.000 1.000
64.820 49.000 1.000
64.880 52.000 1.000
64.940 57.000 1.000
65.000 52.000 1.000
65.060 49.000 1.000
65.120 54.000 1.000
65.180 48.000 1.000
65.240 50.000 1.000
65.300 52.000 1.000
65.360 63.000 1.000
65.420 62.000 1.000
65.480 57.000 1.000
65.540 39.000 1.000
65.600 48.000 1.000
65.660 54.000 1.000
65.720 49.000 1.000
65.780 43.000 1.000
65.840 44.000 1.000
65.900 43.000 1.000
65.960 51.000 1.000
66.020 47.000 1.000
66.080 35.000 1.000
66.140 42.000 1.000
66.200 43.000 1.000
66.260 45.000 1.000
66.320 49.000 1.000
66.380 43.000 1.000
66.440 53.000 1.000
66.500 42.000 1.000
66.560 39.000 1.000
66.620 46.000 1.000
66.680 48.000 1.000
66.740 48.000 1.000
66.800 54.000 1.000
66.860 45.000 1.000
66.920 47.000 1.000
66.980 44.000 1.000
67.040 39.000 1.000
67.100 48.000 1.000
67.160 51.000 1.000
67.220 47.000 1.000
67.280 50.000 1.000
67.340 59.000 1.000
67.400 49.000 1.000
67.460 49.000 1.000
67.520 48.000 1.000
67.580 55.000 1.000
67.640 59.000 1.000
67.700 54.000 1.000
67.760 55.000 1.000
67.820 58.000 1.000
67.880 58.000 1.000
67.940 63.000 1.000
68.000 66.000 1.000
68.060 55.000 1.000
68.120 61.000 1.000
68.180 56.000 1.000
68.240 64.000 1.000
68.300 84.000 1.000
68.360 79.000 1.000
68.420 92.000 1.000
68.480 102.000 1.000
68.540 122.000 1.000
68.600 150.000 1.000
68.660 198.000 1.000
68.720 187.000 1.000
68.780 238.000 1.000
68.840 250.000 1.000
68.900 255.000 1.000
68.960 243.000 1.000
69.020 227.000 1.000
69.080 189.000 1.000
69.140 177.000 1.000
69.200 143.000 1.000
69.260 120.000 1.000
69.320 100.000 1.000
69.380 119.000 1.000
69.440 93.000 1.000
69.500 105.000 1.000
69.560 105.000 1.000
69.620 104.000 1.000
69.680 139.000 1.000
69.740 165.000 1.000
69.800 206.000 1.000
69.860 172.000 1.000
69.920 154.000 1.000
69.980 153.000 1.000
70.040 136.000 1.000
70.100 108.000 1.000
70.160 81.000 1.000
70.220 68.000 1.000
70.280 68.000 1.000
70.340 70.000 1.000
70.400 55.000 1.000
70.460 52.000 1.000
70.520 52.000 1.000
70.580 40.000 1.000
70.640 40.000 1.000
70.700 51.000 1.000
70.760 31.000 1.000
70.820 42.000 1.000
70.880 41.000 1.000
70.940 43.000 1.000
71.000 39.000 1.000
71.060 40.000 1.000
71.120 38.000 1.000
71.180 35.000 1.000
71.240 43.000 1.000
71.300 41.000 1.000
71.360 36.000 1.000
71.420 39.000 1.000
71.480 32.000 1.000
71.540 34.000 1.000
71.600 40.000 1.000
71.660 37.000 1.000
71.720 39.000 1.000
71.780 37.000 1.000
71.840 48.000 1.000
71.900 40.000 1.000
71.960 44.000 1.000
72.020 40.000 1.000
72.080 38.000 1.000
72.140 40.000 1.000
72.200 45.000 1.000
72.260 45.000 1.000
72.320 49.000 1.000
72.380 38.000 1.000
72.440 42.000 1.000
72.500 46.000 1.000
72.560 38.000 1.000
72.620 39.000 1.000
72.680 36.000 1.000
72.740 36.000 1.000
72.800 41.000 1.000
72.860 37.000 1.000
72.920 37.000 1.000
72.980 38.000 1.000
73.040 32.000 1.000
73.100 37.000 1.000
73.160 30.000 1.000
73.220 39.000 1.000
73.280 41.000 1.000
73.340 32.000 1.000
73.400 39.000 1.000
73.460 28.000 1.000
73.520 35.000 1.000
73.580 39.000 1.000
73.640 36.000 1.000
73.700 31.000 1.000
73.760 41.000 1.000
73.820 33.000 1.000
73.880 38.000 1.000
73.940 37.000 1.000
74.000 38.000 1.000
74.060 41.000 1.000
74.120 34.000 1.000
74.180 48.000 1.000
74.240 36.000 1.000
74.300 37.000 1.000
74.360 37.000 1.000
74.420 32.000 1.000
74.480 33.000 1.000
74.540 32.000 1.000
74.600 42.000 1.000
74.660 40.000 1.000
74.720 38.000 1.000
74.780 37.000 1.000
74.840 36.000 1.000
74.900 36.000 1.000
74.960 36.000 1.000
75.020 29.000 1.000
75.080 36.000 1.000
75.140 42.000 1.000
75.200 37.000 1.000
75.260 41.000 1.000
75.320 36.000 1.000
75.380 38.000 1.000
75.440 41.000 1.000
75.500 47.000 1.000
75.560 28.000 1.000
75.620 43.000 1.000
75.680 35.000 1.000
75.740 29.000 1.000
75.800 36.000 1.000
75.860 42.000 1.000
75.920 36.000 1.000
75.980 47.000 1.000
76.040 31.000 1.000
76.100 38.000 1.000
76.160 38.000 1.000
76.220 40.000 1.000
76.280 41.000 1.000
76.340 49.000 1.000
76.400 46.000 1.000
76.460 47.000 1.000
76.520 54.000 1.000
76.580 53.000 1.000
76.640 55.000 1.000
76.700 56.000 1.000
76.760 57.000 1.000
76.820 48.000 1.000
76.880 37.000 1.000
76.940 43.000 1.000
77.000 38.000 1.000
77.060 36.000 1.000
77.120 34.000 1.000
77.180 32.000 1.000
77.240 32.000 1.000
77.300 33.000 1.000
77.360 26.000 1.000
77.420 33.000 1.000
77.480 26.000 1.000
77.540 31.000 1.000
77.600 30.000 1.000
77.660 29.000 1.000
77.720 31.000 1.000
77.780 37.000 1.000
77.840 30.000 1.000
77.900 22.000 1.000
77.960 27.000 1.000
78.020 26.000 1.000
78.080 21.000 1.000
78.140 30.000 1.000
78.200 30.000 1.000
78.260 34.000 1.000
78.320 28.000 1.000
78.380 31.000 1.000
78.440 27.000 1.000
78.500 33.000 1.000
78.560 32.000 1.000
78.620 33.000 1.000
78.680 27.000 1.000
78.740 32.000 1.000
78.800 25.000 1.000
78.860 28.000 1.000
78.920 27.000 1.000
78.980 27.000 1.000
79.040 25.000 1.000
79.100 32.000 1.000
79.160 33.000 1.000
79.220 34.000 1.000
79.280 29.000 1.000
79.340 35.000 1.000
79.400 34.000 1.000
79.460 28.000 1.000
79.520 38.000 1.000
79.580 32.000 1.000
79.640 38.000 1.000
79.700 42.000 1.000
79.760 41.000 1.000
79.820 48.000 1.000
79.880 44.000 1.000
79.940 38.000 1.000
80.000 42.000 1.000
80.060 30.000 1.000
80.120 36.000 1.000
80.180 30.000 1.000
80.240 37.000 1.000
80.300 33.000 1.000
80.360 30.000 1.000
80.420 34.000 1.000
80.480 37.000 1.000
80.540 28.000 1.000
80.600 36.000 1.000
80.660 26.000 1.000
80.720 31.000 1.000
80.780 35.000 1.000
80.840 33.000 1.000
80.900 30.000 1.000
80.960 32.000 1.000
81.020 33.000 1.000
81.080 33.000 1.000
81.140 31.000 1.000
81.200 33.000 1.000
81.260 31.000 1.000
81.320 32.000 1.000
81.380 31.000 1.000
81.440 40.000 1.000
81.500 40.000 1.000
81.560 31.000 1.000
81.620 34.000 1.000
81.680 39.000 1.000
81.740 38.000 1.000
81.800 42.000 1.000
81.860 48.000 1.000
81.920 59.000 1.000
81.980 70.000 1.000
82.040 61.000 1.000
82.100 67.000 1.000
82.160 72.000 1.000
82.220 64.000 1.000
82.280 78.000 1.000
82.340 63.000 1.000
82.400 54.000 1.000
82.460 64.000 1.000
82.520 50.000 1.000
82.580 54.000 1.000
82.640 46.000 1.000
82.700 37.000 1.000
82.760 36.000 1.000
82.820 44.000 1.000
82.880 37.000 1.000
82.940 30.000 1.000
83.000 43.000 1.000
83.060 45.000 1.000
83.120 41.000 1.000
83.180 34.000 1.000
83.240 44.000 1.000
83.300 42.000 1.000
83.360 34.000 1.000
83.420 36.000 1.000
83.480 42.000 1.000
83.540 37.000 1.000
83.600 45.000 1.000
83.660 48.000 1.000
83.720 40.000 1.000
83.780 47.000 1.000
83.840 53.000 1.000
83.900 55.000 1.000
83.960 69.000 1.000
84.020 49.000 1.000
84.080 62.000 1.000
84.140 58.000 1.000
84.200 57.000 1.000
84.260 45.000 1.000
84.320 49.000 1.000
84.380 40.000 1.000
84.440 39.000 1.000
84.500 37.000 1.000
84.560 30.000 1.000
84.620 33.000 1.000
84.680 27.000 1.000
84.740 33.000 1.000
84.800 29.000 1.000
84.860 26.000 1.000
84.920 24.000 1.000
84.980 30.000 1.000
85.040 26.000 1.000
85.100 33.000 1.000
85.160 29.000 1.000
85.220 31.000 1.000
85.280 25.000 1.000
85.340 32.000 1.000
85.400 26.000 1.000
85.460 33.000 1.000
85.520 31.000 1.000
85.580 32.000 1.000
85.640 28.000 1.000
85.700 25.000 1.000
85.760 25.000 1.000
85.820 36.000 1.000
85.880 26.000 1.000
85.940 27.000 1.000
86.000 26.000 1.000
86.060 24.000 1.000
86.120 31.000 1.000
86.180 25.000 1.000
86.240 30.000 1.000
86.300 33.000 1.000
86.360 31.000 1.000
86.420 27.000 1.000
86.480 23.000 1.000
86.540 33.000 1.000
86.600 33.000 1.000
86.660 25.000 1.000
86.720 28.000 1.000
86.780 19.000 1.000
86.840 35.000 1.000
86.900 26.000 1.000
86.960 27.000 1.000
87.020 27.000 1.000
87.080 35.000 1.000
87.140 31.000 1.000
87.200 39.000 1.000
87.260 32.000 1.000
87.320 30.000 1.000
87.380 31.000 1.000
87.440 34.000 1.000
87.500 34.000 1.000
87.560 31.000 1.000
87.620 39.000 1.000
87.680 30.000 1.000
87.740 25.000 1.000
87.800 29.000 1.000
87.860 27.000 1.000
87.920 28.000 1.000
87.980 25.000 1.000
88.040 31.000 1.000
88.100 23.000 1.000
88.160 28.000 1.000
88.220 20.000 1.000
88.280 30.000 1.000
88.340 25.000 1.000
88.400 30.000 1.000
88.460 31.000 1.000
88.520 28.000 1.000
88.580 25.000 1.000
88.640 31.000 1.000
88.700 32.000 1.000
88.760 28.000 1.000
88.820 28.000 1.000
88.880 38.000 1.000
88.940 38.000 1.000
89.000 35.000 1.000
89.060 35.000 1.000
89.120 49.000 1.000
89.180 54.000 1.000
89.240 59.000 1.000
89.300 76.000 1.000
89.360 88.000 1.000
89.420 96.000 1.000
89.480 99.000 1.000
89.540 93.000 1.000
89.600 82.000 1.000
89.660 78.000 1.000
89.720 70.000 1.000
89.780 76.000 1.000
89.840 60.000 1.000
89.900 59.000 1.000
89.960 53.000 1.000
90.000 53.000 1.000
*RAS_INT_END
*RAS_DATA_END