File: ras-to-csv_converter_plotter/example/ras/TiO2-1-6h-BET.ras
*RAS_DATA_START
*RAS_HEADER_START
*CORR_POS_DB_NAME "correction_file_020419"
*CORR_POS_GONIO_RADIUS ""
*CORR_POS_NODE_INDEX01 ""
*CORR_POS_NODE_INDEX02 ""
*CORR_POS_NODE_INDEX03 ""
*CORR_POS_NODE_INDEX04 ""
*CORR_POS_NODE_INDEX05 ""
*CORR_POS_NODE_INDEX06 ""
*CORR_POS_NODE_INDEX07 ""
*CORR_POS_NODE_INDEX08 ""
*CORR_POS_NODE_INDEX09 ""
*CORR_POS_NODE_INDEX10 ""
*CORR_POS_NODE_INDEX11 ""
*CORR_POS_NODE_LABEL01 "Si(111)"
*CORR_POS_NODE_LABEL02 "Si(220)"
*CORR_POS_NODE_LABEL03 "Si(311)"
*CORR_POS_NODE_LABEL04 "Si(400)"
*CORR_POS_NODE_LABEL05 "Si(331)"
*CORR_POS_NODE_LABEL06 "Si(422)"
*CORR_POS_NODE_LABEL07 "Si(511)"
*CORR_POS_NODE_LABEL08 "Si(440)"
*CORR_POS_NODE_LABEL09 "Si(531)"
*CORR_POS_NODE_LABEL10 "Si(620)"
*CORR_POS_NODE_LABEL11 "Si(533)"
*CORR_POS_NODE_POS_CALC01 "28.4137"
*CORR_POS_NODE_POS_CALC02 "47.2707"
*CORR_POS_NODE_POS_CALC03 "56.0883"
*CORR_POS_NODE_POS_CALC04 "69.0934"
*CORR_POS_NODE_POS_CALC05 "76.3385"
*CORR_POS_NODE_POS_CALC06 "87.9915"
*CORR_POS_NODE_POS_CALC07 "94.9137"
*CORR_POS_NODE_POS_CALC08 "106.67"
*CORR_POS_NODE_POS_CALC09 "114.054"
*CORR_POS_NODE_POS_CALC10 "127.508"
*CORR_POS_NODE_POS_CALC11 "136.858"
*CORR_POS_NODE_POS_MEAS01 "28.463"
*CORR_POS_NODE_POS_MEAS02 "47.3124"
*CORR_POS_NODE_POS_MEAS03 "56.1276"
*CORR_POS_NODE_POS_MEAS04 "69.1418"
*CORR_POS_NODE_POS_MEAS05 "76.3865"
*CORR_POS_NODE_POS_MEAS06 "88.0411"
*CORR_POS_NODE_POS_MEAS07 "94.9598"
*CORR_POS_NODE_POS_MEAS08 "106.713"
*CORR_POS_NODE_POS_MEAS09 "114.102"
*CORR_POS_NODE_POS_MEAS10 "127.558"
*CORR_POS_NODE_POS_MEAS11 "136.911"
*CORR_POS_OPT_ATTR "集中法"
*CORR_POS_PARAM_MU ""
*CORR_POS_PARAM_PL ""
*CORR_POS_SEMODEL_TYPE "0"
*CORR_POS_STANDARD_TYPE ""
*CORR_POS_VALUE_ANALYZER "None"
*CORR_POS_VALUE_CMONO "None"
*CORR_POS_VALUE_IMONO "None"
*CORR_POS_VALUE_IS "0.625deg"
*CORR_POS_VALUE_ISL "10.0mm"
*CORR_POS_VALUE_ISOLLER "2.5deg"
*CORR_POS_VALUE_RS1 "13.0mm"
*CORR_POS_VALUE_RS2 "13.0mm"
*CORR_POS_VALUE_RSOLLER "2.5deg"
*CORR_POS_XG_FOCUS_L ""
*CORR_POS_XG_WAVE_TYPE ""
*CORR_POS_XG_WAVE_VALUE ""
*DISP_FMT_X "%.2f"
*DISP_FMT_Y "%.0f"
*DISP_FULLSCALE "26480.0000000000"
*DISP_LINE_COLOR "255.0000000000"
*DISP_LINE_STYLE "0.0000000000"
*DISP_LINE_WIDTH "0.2500000000"
*DISP_NOTE "Collected Data-2"
*DISP_OFFSET_Y "0.0000000000"
*DISP_PEAKSEARCH_UNIT_Y "cps"
*DISP_RANGE_BOTTOM "0.0000000000"
*DISP_RANGE_LEFT "5.0000000000"
*DISP_RANGE_LOGCUTOFF "0.0100000000"
*DISP_RANGE_RIGHT "90.0000000000"
*DISP_RANGE_TOP "26480.0000000000"
*DISP_SCALE_MODE_Y "0.0000000000"
*DISP_TAB_NAME "Theta/2-Theta"
*DISP_TITLE_Y "Intensity"
*DISP_UNIT_Y "cps"
*DISP_WINDOW_NAME "MSG_MACROENGINE"
*FILE_COMMENT " "
*FILE_MD5 ""
*FILE_MEMO " "
*FILE_OPERATOR "SDU_RIGAKU"
*FILE_SAMPLE "TiO2-1-6h-BET"
*FILE_TYPE "RAS_RAW"
*FILE_USERGROUP "System User"
*FILE_VERSION "1.0000000000"
*HW_ATTACHMENT_ID "ATT1031"
*HW_ATTACHMENT_NAME "6サンプルチェンジャ|ASC-6"
*HW_COUNTER_ID-0 "CUT0025"
*HW_COUNTER_ID-1 "CUT0020"
*HW_COUNTER_ID-2 "CUT0020"
*HW_COUNTER_ID-3 "CMC0021"
*HW_COUNTER_NAME-0 "D/teX Ultra|D/teX Ultra"
*HW_COUNTER_NAME-1 "None|None"
*HW_COUNTER_NAME-2 "None|None"
*HW_COUNTER_NAME-3 "検出器モノクロメータ|Detector monochromator"
*HW_COUNTER_SELECT_NAME "D/teX Ultra|D/teX Ultra"
*HW_GONIOMETER_ID "GON0070"
*HW_GONIOMETER_NAME "MiniFlex 300/600|MiniFlex 300/600"
*HW_GONIOMETER_RADIUS-0 "79.0"
*HW_GONIOMETER_RADIUS-1 "91.5"
*HW_GONIOMETER_RADIUS-2 "150.0"
*HW_GONIOMETER_RADIUS-3 "0"
*HW_GONIOMETER_RADIUS-4 "103.4"
*HW_GONIOMETER_RADIUS-5 "150.0"
*HW_GONIOMETER_RADIUS-6 "46.6"
*HW_GONIOMETER_RADIUS-7 "160.0"
*HW_I_OPT_ID-0 "ISL0021"
*HW_I_OPT_ID-1 "ISO0021"
*HW_I_OPT_NAME-0 "発散スリット|Divergence slit"
*HW_I_OPT_NAME-1 "入射平行スリット|Incident parallel slit"
*HW_R_ATTENUATER_AUTOMODE "0"
*HW_R_OPT_ID-0 "RSS0021"
*HW_R_OPT_ID-1 "RSO0021"
*HW_R_OPT_ID-2 "RRS0021"
*HW_R_OPT_NAME-0 "散乱スリット|Scattering slit"
*HW_R_OPT_NAME-1 "受光平行スリット|Receiving soller slit"
*HW_R_OPT_NAME-2 "受光スリット|Receiving slit"
*HW_SAMPLE_HOLDER_ID "SMP0000"
*HW_SAMPLE_HOLDER_NAME "無し|None"
*HW_XG_CURRENT_MAX "15"
*HW_XG_CURRENT_MIN "2"
*HW_XG_CURRENT_RESOLUTION "1"
*HW_XG_CURRENT_UNIT "mA"
*HW_XG_FOCUS "1mm x 10mm"
*HW_XG_FOCUS_TYPE "Normal"
*HW_XG_ID ""
*HW_XG_NAME "300W/600W 封入管-B|300W/600W Sealed tube-B"
*HW_XG_TARGET_ATOMIC_NUMBER "29.0000000000"
*HW_XG_TARGET_NAME "Cu"
*HW_XG_TYPE "Hermetic"
*HW_XG_VOLTAGE_MAX "40"
*HW_XG_VOLTAGE_MIN "20"
*HW_XG_VOLTAGE_RESOLUTION "1"
*HW_XG_VOLTAGE_UNIT "kV"
*HW_XG_WATT_MAX "1"
*HW_XG_WATT_UNIT "kW"
*HW_XG_WAVE_LENGTH_ALPHA1 "1.540593"
*HW_XG_WAVE_LENGTH_ALPHA2 "1.544414"
*HW_XG_WAVE_LENGTH_BETA "1.392250"
*MEAS_COND_AXIS_NAME-0 "Theta/2-Theta"
*MEAS_COND_AXIS_NAME-1 "Spin"
*MEAS_COND_AXIS_NAME-2 "Change"
*MEAS_COND_AXIS_NAME-3 "Soller(inc.)"
*MEAS_COND_AXIS_NAME-4 "IHS"
*MEAS_COND_AXIS_NAME-5 "DS"
*MEAS_COND_AXIS_NAME-6 "SS"
*MEAS_COND_AXIS_NAME-7 "Soller(rec.)"
*MEAS_COND_AXIS_NAME-8 "RS"
*MEAS_COND_AXIS_NAME-9 "Filter"
*MEAS_COND_AXIS_NAME-10 "Monochromator"
*MEAS_COND_AXIS_NAME-11 "PHA"
*MEAS_COND_AXIS_NAME_INTERNAL-0 "TwoThetaTheta"
*MEAS_COND_AXIS_NAME_INTERNAL-1 "Spin"
*MEAS_COND_AXIS_NAME_INTERNAL-2 "Change"
*MEAS_COND_AXIS_NAME_INTERNAL-3 "IncidentSollerSlit"
*MEAS_COND_AXIS_NAME_INTERNAL-4 "IncidentAxdSlit"
*MEAS_COND_AXIS_NAME_INTERNAL-5 "IncidentSlitBox"
*MEAS_COND_AXIS_NAME_INTERNAL-6 "ReceivingSlitBox1"
*MEAS_COND_AXIS_NAME_INTERNAL-7 "ReceivingSollerSlit"
*MEAS_COND_AXIS_NAME_INTERNAL-8 "ReceivingSlitBox2"
*MEAS_COND_AXIS_NAME_INTERNAL-9 "Filter"
*MEAS_COND_AXIS_NAME_INTERNAL-10 "CounterMonochromator"
*MEAS_COND_AXIS_NAME_INTERNAL-11 "PHA"
*MEAS_COND_AXIS_NAME_MAGICNO-0 "268632064.0000000000"
*MEAS_COND_AXIS_NAME_MAGICNO-1 "16842752.0000000000"
*MEAS_COND_AXIS_NAME_MAGICNO-2 "16842752.0000000000"
*MEAS_COND_AXIS_NAME_MAGICNO-3 "20971521.0000000000"
*MEAS_COND_AXIS_NAME_MAGICNO-4 "22020097.0000000000"
*MEAS_COND_AXIS_NAME_MAGICNO-5 "22020097.0000000000"
*MEAS_COND_AXIS_NAME_MAGICNO-6 "23068673.0000000000"
*MEAS_COND_AXIS_NAME_MAGICNO-7 "20971521.0000000000"
*MEAS_COND_AXIS_NAME_MAGICNO-8 "23068673.0000000000"
*MEAS_COND_AXIS_NAME_MAGICNO-9 "20971521.0000000000"
*MEAS_COND_AXIS_NAME_MAGICNO-10 "20971521.0000000000"
*MEAS_COND_AXIS_NAME_MAGICNO-11 "0.0000000000"
*MEAS_COND_AXIS_OFFSET-0 "0.0000000000"
*MEAS_COND_AXIS_OFFSET-1 "-"
*MEAS_COND_AXIS_OFFSET-2 "-"
*MEAS_COND_AXIS_OFFSET-3 "-"
*MEAS_COND_AXIS_OFFSET-4 "-"
*MEAS_COND_AXIS_OFFSET-5 "-"
*MEAS_COND_AXIS_OFFSET-6 "-"
*MEAS_COND_AXIS_OFFSET-7 "-"
*MEAS_COND_AXIS_OFFSET-8 "-"
*MEAS_COND_AXIS_OFFSET-9 "-"
*MEAS_COND_AXIS_OFFSET-10 "-"
*MEAS_COND_AXIS_OFFSET-11 "-"
*MEAS_COND_AXIS_POSITION-0 "92.5100000000"
*MEAS_COND_AXIS_POSITION-1 "0.0000000000"
*MEAS_COND_AXIS_POSITION-2 "4.0000000000"
*MEAS_COND_AXIS_POSITION-3 "2.5deg"
*MEAS_COND_AXIS_POSITION-4 "10.0mm"
*MEAS_COND_AXIS_POSITION-5 "0.625deg"
*MEAS_COND_AXIS_POSITION-6 "13.0mm"
*MEAS_COND_AXIS_POSITION-7 "2.5deg"
*MEAS_COND_AXIS_POSITION-8 "13.0mm"
*MEAS_COND_AXIS_POSITION-9 "K-beta(x1)"
*MEAS_COND_AXIS_POSITION-10 "None"
*MEAS_COND_AXIS_POSITION-11 "42.0000000000"
*MEAS_COND_AXIS_UNIT-0 "deg"
*MEAS_COND_AXIS_UNIT-1 ""
*MEAS_COND_AXIS_UNIT-2 ""
*MEAS_COND_AXIS_UNIT-3 ""
*MEAS_COND_AXIS_UNIT-4 ""
*MEAS_COND_AXIS_UNIT-5 ""
*MEAS_COND_AXIS_UNIT-6 ""
*MEAS_COND_AXIS_UNIT-7 ""
*MEAS_COND_AXIS_UNIT-8 ""
*MEAS_COND_AXIS_UNIT-9 ""
*MEAS_COND_AXIS_UNIT-10 ""
*MEAS_COND_AXIS_UNIT-11 "div"
*MEAS_COND_CORRECTION_SLIT_COUNTERMONO "None"
*MEAS_COND_CORRECTION_SLIT_DS "0.625deg"
*MEAS_COND_CORRECTION_SLIT_FILTER "None"
*MEAS_COND_CORRECTION_SLIT_IHS "10.0mm"
*MEAS_COND_CORRECTION_SLIT_RS "13.0mm"
*MEAS_COND_CORRECTION_SLIT_SOLLER_INC "2.5deg"
*MEAS_COND_CORRECTION_SLIT_SOLLER_REC "2.5deg"
*MEAS_COND_CORRECTION_SLIT_SS "13.0mm"
*MEAS_COND_COUNTER_CNTLOSS_CORR "0.0000000000"
*MEAS_COND_COUNTER_PHABASE "42.0000000000"
*MEAS_COND_COUNTER_PHAWINDOW "15.0000000000"
*MEAS_COND_COUNTER_PHA_UNIT "div"
*MEAS_COND_COUNTER_TAUDIFF "0.2500000000"
*MEAS_COND_COUNTER_TAUINT "0.7500000000"
*MEAS_COND_IRRADIATION_MODE "OFF"
*MEAS_COND_IRRADIATION_WIDTH ""
*MEAS_COND_OPT_ATTR " "
*MEAS_COND_OPT_NAME ""
*MEAS_COND_UNSYMMETRIC_MODE "OFF"
*MEAS_COND_XG_CURRENT "15.0000000000"
*MEAS_COND_XG_VOLTAGE "40.0000000000"
*MEAS_COND_XG_WAVE_TYPE "Ka"
*MEAS_DATA_COUNT "4251.0000000000"
*MEAS_SCAN_AXIS_X "Theta/2-Theta"
*MEAS_SCAN_AXIS_X_INTERNAL "TwoThetaTheta"
*MEAS_SCAN_END_TIME "04/16/19 12:02:15"
*MEAS_SCAN_MODE "CONTINUOUS"
*MEAS_SCAN_MONITOR "0"
*MEAS_SCAN_RESOLUTION_X "0.005"
*MEAS_SCAN_SPEED "10.000"
*MEAS_SCAN_SPEED_UNIT "deg/min"
*MEAS_SCAN_START "5.0000000000"
*MEAS_SCAN_START_TIME "04/16/19 11:52:49"
*MEAS_SCAN_STEP "0.0200000000"
*MEAS_SCAN_STOP "90.0000000000"
*MEAS_SCAN_UNIT_X "deg"
*MEAS_SCAN_UNIT_Y "counts"
*SLIT_SYSTEM "0"
*RAS_HEADER_END
*RAS_INT_START
5.000 321.000 1.000
5.060 328.000 1.000
5.120 315.000 1.000
5.180 310.000 1.000
5.240 317.000 1.000
5.300 271.000 1.000
5.360 305.000 1.000
5.420 307.000 1.000
5.480 291.000 1.000
5.540 268.000 1.000
5.600 275.000 1.000
5.660 238.000 1.000
5.720 269.000 1.000
5.780 216.000 1.000
5.840 259.000 1.000
5.900 239.000 1.000
5.960 230.000 1.000
6.020 248.000 1.000
6.080 207.000 1.000
6.140 213.000 1.000
6.200 209.000 1.000
6.260 207.000 1.000
6.320 229.000 1.000
6.380 202.000 1.000
6.440 216.000 1.000
6.500 203.000 1.000
6.560 211.000 1.000
6.620 209.000 1.000
6.680 203.000 1.000
6.740 201.000 1.000
6.800 202.000 1.000
6.860 180.000 1.000
6.920 197.000 1.000
6.980 166.000 1.000
7.040 203.000 1.000
7.100 183.000 1.000
7.160 170.000 1.000
7.220 172.000 1.000
7.280 180.000 1.000
7.340 169.000 1.000
7.400 174.000 1.000
7.460 160.000 1.000
7.520 169.000 1.000
7.580 177.000 1.000
7.640 165.000 1.000
7.700 170.000 1.000
7.760 166.000 1.000
7.820 131.000 1.000
7.880 172.000 1.000
7.940 158.000 1.000
8.000 165.000 1.000
8.060 139.000 1.000
8.120 139.000 1.000
8.180 132.000 1.000
8.240 135.000 1.000
8.300 150.000 1.000
8.360 132.000 1.000
8.420 134.000 1.000
8.480 147.000 1.000
8.540 149.000 1.000
8.600 142.000 1.000
8.660 125.000 1.000
8.720 144.000 1.000
8.780 143.000 1.000
8.840 124.000 1.000
8.900 133.000 1.000
8.960 140.000 1.000
9.020 141.000 1.000
9.080 142.000 1.000
9.140 147.000 1.000
9.200 149.000 1.000
9.260 151.000 1.000
9.320 130.000 1.000
9.380 136.000 1.000
9.440 132.000 1.000
9.500 145.000 1.000
9.560 144.000 1.000
9.620 141.000 1.000
9.680 140.000 1.000
9.740 140.000 1.000
9.800 122.000 1.000
9.860 136.000 1.000
9.920 136.000 1.000
9.980 148.000 1.000
10.040 141.000 1.000
10.100 121.000 1.000
10.160 135.000 1.000
10.220 117.000 1.000
10.280 127.000 1.000
10.340 128.000 1.000
10.400 128.000 1.000
10.460 129.000 1.000
10.520 127.000 1.000
10.580 129.000 1.000
10.640 133.000 1.000
10.700 126.000 1.000
10.760 128.000 1.000
10.820 127.000 1.000
10.880 122.000 1.000
10.940 124.000 1.000
11.000 120.000 1.000
11.060 119.000 1.000
11.120 120.000 1.000
11.180 111.000 1.000
11.240 132.000 1.000
11.300 128.000 1.000
11.360 128.000 1.000
11.420 122.000 1.000
11.480 126.000 1.000
11.540 116.000 1.000
11.600 119.000 1.000
11.660 137.000 1.000
11.720 120.000 1.000
11.780 123.000 1.000
11.840 134.000 1.000
11.900 130.000 1.000
11.960 117.000 1.000
12.020 134.000 1.000
12.080 107.000 1.000
12.140 124.000 1.000
12.200 127.000 1.000
12.260 127.000 1.000
12.320 120.000 1.000
12.380 117.000 1.000
12.440 128.000 1.000
12.500 121.000 1.000
12.560 112.000 1.000
12.620 108.000 1.000
12.680 125.000 1.000
12.740 116.000 1.000
12.800 116.000 1.000
12.860 118.000 1.000
12.920 116.000 1.000
12.980 120.000 1.000
13.040 117.000 1.000
13.100 123.000 1.000
13.160 130.000 1.000
13.220 122.000 1.000
13.280 114.000 1.000
13.340 117.000 1.000
13.400 120.000 1.000
13.460 112.000 1.000
13.520 117.000 1.000
13.580 118.000 1.000
13.640 121.000 1.000
13.700 108.000 1.000
13.760 119.000 1.000
13.820 107.000 1.000
13.880 110.000 1.000
13.940 121.000 1.000
14.000 108.000 1.000
14.060 128.000 1.000
14.120 123.000 1.000
14.180 121.000 1.000
14.240 128.000 1.000
14.300 122.000 1.000
14.360 125.000 1.000
14.420 119.000 1.000
14.480 113.000 1.000
14.540 116.000 1.000
14.600 101.000 1.000
14.660 102.000 1.000
14.720 124.000 1.000
14.780 113.000 1.000
14.840 111.000 1.000
14.900 100.000 1.000
14.960 105.000 1.000
15.020 120.000 1.000
15.080 114.000 1.000
15.140 105.000 1.000
15.200 102.000 1.000
15.260 110.000 1.000
15.320 99.000 1.000
15.380 112.000 1.000
15.440 96.000 1.000
15.500 122.000 1.000
15.560 109.000 1.000
15.620 117.000 1.000
15.680 113.000 1.000
15.740 104.000 1.000
15.800 101.000 1.000
15.860 115.000 1.000
15.920 101.000 1.000
15.980 104.000 1.000
16.040 127.000 1.000
16.100 96.000 1.000
16.160 102.000 1.000
16.220 114.000 1.000
16.280 107.000 1.000
16.340 121.000 1.000
16.400 105.000 1.000
16.460 97.000 1.000
16.520 104.000 1.000
16.580 105.000 1.000
16.640 86.000 1.000
16.700 112.000 1.000
16.760 109.000 1.000
16.820 99.000 1.000
16.880 96.000 1.000
16.940 116.000 1.000
17.000 114.000 1.000
17.060 100.000 1.000
17.120 100.000 1.000
17.180 115.000 1.000
17.240 102.000 1.000
17.300 97.000 1.000
17.360 113.000 1.000
17.420 113.000 1.000
17.480 100.000 1.000
17.540 93.000 1.000
17.600 99.000 1.000
17.660 97.000 1.000
17.720 96.000 1.000
17.780 106.000 1.000
17.840 92.000 1.000
17.900 103.000 1.000
17.960 90.000 1.000
18.020 91.000 1.000
18.080 89.000 1.000
18.140 92.000 1.000
18.200 96.000 1.000
18.260 98.000 1.000
18.320 96.000 1.000
18.380 103.000 1.000
18.440 101.000 1.000
18.500 102.000 1.000
18.560 94.000 1.000
18.620 102.000 1.000
18.680 92.000 1.000
18.740 87.000 1.000
18.800 101.000 1.000
18.860 91.000 1.000
18.920 98.000 1.000
18.980 93.000 1.000
19.040 86.000 1.000
19.100 97.000 1.000
19.160 97.000 1.000
19.220 104.000 1.000
19.280 100.000 1.000
19.340 89.000 1.000
19.400 90.000 1.000
19.460 88.000 1.000
19.520 98.000 1.000
19.580 90.000 1.000
19.640 91.000 1.000
19.700 86.000 1.000
19.760 102.000 1.000
19.820 79.000 1.000
19.880 87.000 1.000
19.940 77.000 1.000
20.000 94.000 1.000
20.060 92.000 1.000
20.120 83.000 1.000
20.180 95.000 1.000
20.240 78.000 1.000
20.300 88.000 1.000
20.360 94.000 1.000
20.420 76.000 1.000
20.480 96.000 1.000
20.540 86.000 1.000
20.600 84.000 1.000
20.660 85.000 1.000
20.720 95.000 1.000
20.780 81.000 1.000
20.840 84.000 1.000
20.900 85.000 1.000
20.960 90.000 1.000
21.020 78.000 1.000
21.080 91.000 1.000
21.140 92.000 1.000
21.200 83.000 1.000
21.260 74.000 1.000
21.320 86.000 1.000
21.380 83.000 1.000
21.440 83.000 1.000
21.500 79.000 1.000
21.560 77.000 1.000
21.620 71.000 1.000
21.680 87.000 1.000
21.740 76.000 1.000
21.800 81.000 1.000
21.860 84.000 1.000
21.920 83.000 1.000
21.980 73.000 1.000
22.040 81.000 1.000
22.100 81.000 1.000
22.160 87.000 1.000
22.220 86.000 1.000
22.280 79.000 1.000
22.340 75.000 1.000
22.400 76.000 1.000
22.460 82.000 1.000
22.520 88.000 1.000
22.580 76.000 1.000
22.640 73.000 1.000
22.700 76.000 1.000
22.760 77.000 1.000
22.820 81.000 1.000
22.880 79.000 1.000
22.940 76.000 1.000
23.000 82.000 1.000
23.060 90.000 1.000
23.120 77.000 1.000
23.180 97.000 1.000
23.240 76.000 1.000
23.300 68.000 1.000
23.360 78.000 1.000
23.420 79.000 1.000
23.480 84.000 1.000
23.540 76.000 1.000
23.600 90.000 1.000
23.660 84.000 1.000
23.720 94.000 1.000
23.780 86.000 1.000
23.840 83.000 1.000
23.900 87.000 1.000
23.960 84.000 1.000
24.020 98.000 1.000
24.080 86.000 1.000
24.140 80.000 1.000
24.200 98.000 1.000
24.260 83.000 1.000
24.320 94.000 1.000
24.380 106.000 1.000
24.440 100.000 1.000
24.500 93.000 1.000
24.560 114.000 1.000
24.620 101.000 1.000
24.680 94.000 1.000
24.740 123.000 1.000
24.800 110.000 1.000
24.860 115.000 1.000
24.920 131.000 1.000
24.980 134.000 1.000
25.040 126.000 1.000
25.100 160.000 1.000
25.160 126.000 1.000
25.220 156.000 1.000
25.280 145.000 1.000
25.340 148.000 1.000
25.400 151.000 1.000
25.460 151.000 1.000
25.520 160.000 1.000
25.580 161.000 1.000
25.640 146.000 1.000
25.700 158.000 1.000
25.760 154.000 1.000
25.820 158.000 1.000
25.880 161.000 1.000
25.940 168.000 1.000
26.000 148.000 1.000
26.060 145.000 1.000
26.120 154.000 1.000
26.180 140.000 1.000
26.240 144.000 1.000
26.300 148.000 1.000
26.360 134.000 1.000
26.420 152.000 1.000
26.480 137.000 1.000
26.540 149.000 1.000
26.600 154.000 1.000
26.660 172.000 1.000
26.720 183.000 1.000
26.780 197.000 1.000
26.840 207.000 1.000
26.900 247.000 1.000
26.960 280.000 1.000
27.020 331.000 1.000
27.080 378.000 1.000
27.140 459.000 1.000
27.200 609.000 1.000
27.260 850.000 1.000
27.320 1300.000 1.000
27.380 1898.000 1.000
27.440 2411.000 1.000
27.500 2637.000 1.000
27.560 2428.000 1.000
27.620 1881.000 1.000
27.680 1311.000 1.000
27.740 903.000 1.000
27.800 626.000 1.000
27.860 477.000 1.000
27.920 365.000 1.000
27.980 336.000 1.000
28.040 268.000 1.000
28.100 249.000 1.000
28.160 220.000 1.000
28.220 211.000 1.000
28.280 157.000 1.000
28.340 170.000 1.000
28.400 144.000 1.000
28.460 137.000 1.000
28.520 125.000 1.000
28.580 137.000 1.000
28.640 122.000 1.000
28.700 110.000 1.000
28.760 120.000 1.000
28.820 117.000 1.000
28.880 114.000 1.000
28.940 95.000 1.000
29.000 103.000 1.000
29.060 112.000 1.000
29.120 100.000 1.000
29.180 97.000 1.000
29.240 95.000 1.000
29.300 84.000 1.000
29.360 85.000 1.000
29.420 87.000 1.000
29.480 86.000 1.000
29.540 94.000 1.000
29.600 86.000 1.000
29.660 85.000 1.000
29.720 86.000 1.000
29.780 84.000 1.000
29.840 83.000 1.000
29.900 81.000 1.000
29.960 81.000 1.000
30.020 85.000 1.000
30.080 79.000 1.000
30.140 83.000 1.000
30.200 85.000 1.000
30.260 86.000 1.000
30.320 84.000 1.000
30.380 95.000 1.000
30.440 90.000 1.000
30.500 91.000 1.000
30.560 84.000 1.000
30.620 84.000 1.000
30.680 98.000 1.000
30.740 97.000 1.000
30.800 84.000 1.000
30.860 88.000 1.000
30.920 99.000 1.000
30.980 89.000 1.000
31.040 101.000 1.000
31.100 89.000 1.000
31.160 99.000 1.000
31.220 82.000 1.000
31.280 84.000 1.000
31.340 85.000 1.000
31.400 88.000 1.000
31.460 82.000 1.000
31.520 69.000 1.000
31.580 72.000 1.000
31.640 72.000 1.000
31.700 72.000 1.000
31.760 80.000 1.000
31.820 76.000 1.000
31.880 77.000 1.000
31.940 67.000 1.000
32.000 62.000 1.000
32.060 61.000 1.000
32.120 66.000 1.000
32.180 57.000 1.000
32.240 57.000 1.000
32.300 61.000 1.000
32.360 52.000 1.000
32.420 66.000 1.000
32.480 65.000 1.000
32.540 57.000 1.000
32.600 56.000 1.000
32.660 60.000 1.000
32.720 69.000 1.000
32.780 63.000 1.000
32.840 57.000 1.000
32.900 64.000 1.000
32.960 59.000 1.000
33.020 63.000 1.000
33.080 51.000 1.000
33.140 49.000 1.000
33.200 66.000 1.000
33.260 59.000 1.000
33.320 52.000 1.000
33.380 60.000 1.000
33.440 56.000 1.000
33.500 48.000 1.000
33.560 48.000 1.000
33.620 57.000 1.000
33.680 61.000 1.000
33.740 59.000 1.000
33.800 58.000 1.000
33.860 59.000 1.000
33.920 56.000 1.000
33.980 55.000 1.000
34.040 55.000 1.000
34.100 70.000 1.000
34.160 57.000 1.000
34.220 47.000 1.000
34.280 56.000 1.000
34.340 64.000 1.000
34.400 50.000 1.000
34.460 58.000 1.000
34.520 60.000 1.000
34.580 58.000 1.000
34.640 58.000 1.000
34.700 67.000 1.000
34.760 63.000 1.000
34.820 54.000 1.000
34.880 82.000 1.000
34.940 66.000 1.000
35.000 70.000 1.000
35.060 76.000 1.000
35.120 67.000 1.000
35.180 69.000 1.000
35.240 77.000 1.000
35.300 78.000 1.000
35.360 76.000 1.000
35.420 87.000 1.000
35.480 97.000 1.000
35.540 97.000 1.000
35.600 116.000 1.000
35.660 129.000 1.000
35.720 115.000 1.000
35.780 142.000 1.000
35.840 175.000 1.000
35.900 211.000 1.000
35.960 278.000 1.000
36.020 442.000 1.000
36.080 767.000 1.000
36.140 1209.000 1.000
36.200 1314.000 1.000
36.260 1106.000 1.000
36.320 778.000 1.000
36.380 456.000 1.000
36.440 317.000 1.000
36.500 209.000 1.000
36.560 189.000 1.000
36.620 142.000 1.000
36.680 124.000 1.000
36.740 105.000 1.000
36.800 107.000 1.000
36.860 98.000 1.000
36.920 86.000 1.000
36.980 88.000 1.000
37.040 69.000 1.000
37.100 75.000 1.000
37.160 69.000 1.000
37.220 72.000 1.000
37.280 82.000 1.000
37.340 75.000 1.000
37.400 65.000 1.000
37.460 67.000 1.000
37.520 70.000 1.000
37.580 68.000 1.000
37.640 62.000 1.000
37.700 65.000 1.000
37.760 60.000 1.000
37.820 77.000 1.000
37.880 59.000 1.000
37.940 59.000 1.000
38.000 63.000 1.000
38.060 55.000 1.000
38.120 57.000 1.000
38.180 74.000 1.000
38.240 56.000 1.000
38.300 70.000 1.000
38.360 70.000 1.000
38.420 58.000 1.000
38.480 56.000 1.000
38.540 68.000 1.000
38.600 59.000 1.000
38.660 63.000 1.000
38.720 65.000 1.000
38.780 71.000 1.000
38.840 73.000 1.000
38.900 81.000 1.000
38.960 93.000 1.000
39.020 93.000 1.000
39.080 125.000 1.000
39.140 148.000 1.000
39.200 172.000 1.000
39.260 175.000 1.000
39.320 151.000 1.000
39.380 151.000 1.000
39.440 108.000 1.000
39.500 93.000 1.000
39.560 74.000 1.000
39.620 72.000 1.000
39.680 66.000 1.000
39.740 68.000 1.000
39.800 66.000 1.000
39.860 68.000 1.000
39.920 67.000 1.000
39.980 59.000 1.000
40.040 85.000 1.000
40.100 63.000 1.000
40.160 76.000 1.000
40.220 58.000 1.000
40.280 66.000 1.000
40.340 66.000 1.000
40.400 59.000 1.000
40.460 69.000 1.000
40.520 70.000 1.000
40.580 59.000 1.000
40.640 65.000 1.000
40.700 76.000 1.000
40.760 78.000 1.000
40.820 80.000 1.000
40.880 78.000 1.000
40.940 91.000 1.000
41.000 109.000 1.000
41.060 130.000 1.000
41.120 194.000 1.000
41.180 301.000 1.000
41.240 452.000 1.000
41.300 654.000 1.000
41.360 650.000 1.000
41.420 567.000 1.000
41.480 363.000 1.000
41.540 244.000 1.000
41.600 166.000 1.000
41.660 122.000 1.000
41.720 108.000 1.000
41.780 96.000 1.000
41.840 78.000 1.000
41.900 77.000 1.000
41.960 60.000 1.000
42.020 70.000 1.000
42.080 59.000 1.000
42.140 64.000 1.000
42.200 48.000 1.000
42.260 43.000 1.000
42.320 58.000 1.000
42.380 47.000 1.000
42.440 44.000 1.000
42.500 56.000 1.000
42.560 40.000 1.000
42.620 57.000 1.000
42.680 50.000 1.000
42.740 56.000 1.000
42.800 59.000 1.000
42.860 49.000 1.000
42.920 46.000 1.000
42.980 43.000 1.000
43.040 48.000 1.000
43.100 53.000 1.000
43.160 62.000 1.000
43.220 48.000 1.000
43.280 65.000 1.000
43.340 37.000 1.000
43.400 48.000 1.000
43.460 53.000 1.000
43.520 56.000 1.000
43.580 65.000 1.000
43.640 74.000 1.000
43.700 83.000 1.000
43.760 80.000 1.000
43.820 94.000 1.000
43.880 126.000 1.000
43.940 152.000 1.000
44.000 195.000 1.000
44.060 199.000 1.000
44.120 232.000 1.000
44.180 171.000 1.000
44.240 134.000 1.000
44.300 110.000 1.000
44.360 78.000 1.000
44.420 76.000 1.000
44.480 68.000 1.000
44.540 58.000 1.000
44.600 58.000 1.000
44.660 55.000 1.000
44.720 52.000 1.000
44.780 47.000 1.000
44.840 42.000 1.000
44.900 46.000 1.000
44.960 39.000 1.000
45.020 30.000 1.000
45.080 46.000 1.000
45.140 39.000 1.000
45.200 40.000 1.000
45.260 31.000 1.000
45.320 42.000 1.000
45.380 44.000 1.000
45.440 42.000 1.000
45.500 47.000 1.000
45.560 38.000 1.000
45.620 49.000 1.000
45.680 53.000 1.000
45.740 36.000 1.000
45.800 36.000 1.000
45.860 52.000 1.000
45.920 47.000 1.000
45.980 44.000 1.000
46.040 36.000 1.000
46.100 45.000 1.000
46.160 45.000 1.000
46.220 46.000 1.000
46.280 40.000 1.000
46.340 43.000 1.000
46.400 49.000 1.000
46.460 42.000 1.000
46.520 46.000 1.000
46.580 47.000 1.000
46.640 48.000 1.000
46.700 44.000 1.000
46.760 39.000 1.000
46.820 38.000 1.000
46.880 40.000 1.000
46.940 36.000 1.000
47.000 45.000 1.000
47.060 35.000 1.000
47.120 41.000 1.000
47.180 40.000 1.000
47.240 39.000 1.000
47.300 49.000 1.000
47.360 52.000 1.000
47.420 41.000 1.000
47.480 49.000 1.000
47.540 41.000 1.000
47.600 47.000 1.000
47.660 50.000 1.000
47.720 57.000 1.000
47.780 40.000 1.000
47.840 58.000 1.000
47.900 42.000 1.000
47.960 57.000 1.000
48.020 53.000 1.000
48.080 44.000 1.000
48.140 50.000 1.000
48.200 61.000 1.000
48.260 40.000 1.000
48.320 49.000 1.000
48.380 36.000 1.000
48.440 50.000 1.000
48.500 49.000 1.000
48.560 51.000 1.000
48.620 52.000 1.000
48.680 53.000 1.000
48.740 41.000 1.000
48.800 48.000 1.000
48.860 51.000 1.000
48.920 40.000 1.000
48.980 51.000 1.000
49.040 43.000 1.000
49.100 38.000 1.000
49.160 48.000 1.000
49.220 48.000 1.000
49.280 44.000 1.000
49.340 39.000 1.000
49.400 39.000 1.000
49.460 45.000 1.000
49.520 39.000 1.000
49.580 39.000 1.000
49.640 42.000 1.000
49.700 43.000 1.000
49.760 42.000 1.000
49.820 36.000 1.000
49.880 35.000 1.000
49.940 44.000 1.000
50.000 42.000 1.000
50.060 45.000 1.000
50.120 28.000 1.000
50.180 35.000 1.000
50.240 38.000 1.000
50.300 35.000 1.000
50.360 36.000 1.000
50.420 36.000 1.000
50.480 29.000 1.000
50.540 29.000 1.000
50.600 34.000 1.000
50.660 33.000 1.000
50.720 34.000 1.000
50.780 36.000 1.000
50.840 37.000 1.000
50.900 39.000 1.000
50.960 37.000 1.000
51.020 37.000 1.000
51.080 33.000 1.000
51.140 31.000 1.000
51.200 36.000 1.000
51.260 31.000 1.000
51.320 37.000 1.000
51.380 33.000 1.000
51.440 30.000 1.000
51.500 42.000 1.000
51.560 47.000 1.000
51.620 45.000 1.000
51.680 39.000 1.000
51.740 44.000 1.000
51.800 30.000 1.000
51.860 48.000 1.000
51.920 38.000 1.000
51.980 23.000 1.000
52.040 35.000 1.000
52.100 37.000 1.000
52.160 43.000 1.000
52.220 37.000 1.000
52.280 43.000 1.000
52.340 39.000 1.000
52.400 40.000 1.000
52.460 40.000 1.000
52.520 52.000 1.000
52.580 62.000 1.000
52.640 45.000 1.000
52.700 52.000 1.000
52.760 48.000 1.000
52.820 57.000 1.000
52.880 49.000 1.000
52.940 62.000 1.000
53.000 64.000 1.000
53.060 61.000 1.000
53.120 60.000 1.000
53.180 56.000 1.000
53.240 88.000 1.000
53.300 66.000 1.000
53.360 76.000 1.000
53.420 69.000 1.000
53.480 78.000 1.000
53.540 91.000 1.000
53.600 84.000 1.000
53.660 105.000 1.000
53.720 107.000 1.000
53.780 127.000 1.000
53.840 143.000 1.000
53.900 164.000 1.000
53.960 212.000 1.000
54.020 242.000 1.000
54.080 323.000 1.000
54.140 441.000 1.000
54.200 631.000 1.000
54.260 996.000 1.000
54.320 1178.000 1.000
54.380 1220.000 1.000
54.440 1140.000 1.000
54.500 969.000 1.000
54.560 765.000 1.000
54.620 591.000 1.000
54.680 416.000 1.000
54.740 284.000 1.000
54.800 258.000 1.000
54.860 195.000 1.000
54.920 180.000 1.000
54.980 153.000 1.000
55.040 125.000 1.000
55.100 122.000 1.000
55.160 113.000 1.000
55.220 98.000 1.000
55.280 101.000 1.000
55.340 85.000 1.000
55.400 100.000 1.000
55.460 95.000 1.000
55.520 82.000 1.000
55.580 85.000 1.000
55.640 83.000 1.000
55.700 104.000 1.000
55.760 76.000 1.000
55.820 84.000 1.000
55.880 73.000 1.000
55.940 75.000 1.000
56.000 83.000 1.000
56.060 81.000 1.000
56.120 94.000 1.000
56.180 108.000 1.000
56.240 110.000 1.000
56.300 123.000 1.000
56.360 178.000 1.000
56.420 225.000 1.000
56.480 280.000 1.000
56.540 353.000 1.000
56.600 441.000 1.000
56.660 407.000 1.000
56.720 367.000 1.000
56.780 291.000 1.000
56.840 239.000 1.000
56.900 168.000 1.000
56.960 158.000 1.000
57.020 125.000 1.000
57.080 107.000 1.000
57.140 106.000 1.000
57.200 68.000 1.000
57.260 82.000 1.000
57.320 55.000 1.000
57.380 65.000 1.000
57.440 64.000 1.000
57.500 41.000 1.000
57.560 58.000 1.000
57.620 49.000 1.000
57.680 55.000 1.000
57.740 54.000 1.000
57.800 55.000 1.000
57.860 46.000 1.000
57.920 45.000 1.000
57.980 29.000 1.000
58.040 48.000 1.000
58.100 42.000 1.000
58.160 44.000 1.000
58.220 34.000 1.000
58.280 40.000 1.000
58.340 40.000 1.000
58.400 37.000 1.000
58.460 28.000 1.000
58.520 25.000 1.000
58.580 32.000 1.000
58.640 33.000 1.000
58.700 28.000 1.000
58.760 37.000 1.000
58.820 34.000 1.000
58.880 45.000 1.000
58.940 35.000 1.000
59.000 34.000 1.000
59.060 40.000 1.000
59.120 31.000 1.000
59.180 37.000 1.000
59.240 40.000 1.000
59.300 35.000 1.000
59.360 41.000 1.000
59.420 29.000 1.000
59.480 44.000 1.000
59.540 45.000 1.000
59.600 35.000 1.000
59.660 39.000 1.000
59.720 38.000 1.000
59.780 39.000 1.000
59.840 34.000 1.000
59.900 36.000 1.000
59.960 41.000 1.000
60.020 33.000 1.000
60.080 41.000 1.000
60.140 31.000 1.000
60.200 33.000 1.000
60.260 34.000 1.000
60.320 39.000 1.000
60.380 40.000 1.000
60.440 35.000 1.000
60.500 40.000 1.000
60.560 27.000 1.000
60.620 35.000 1.000
60.680 36.000 1.000
60.740 37.000 1.000
60.800 26.000 1.000
60.860 32.000 1.000
60.920 30.000 1.000
60.980 42.000 1.000
61.040 29.000 1.000
61.100 24.000 1.000
61.160 40.000 1.000
61.220 36.000 1.000
61.280 27.000 1.000
61.340 39.000 1.000
61.400 40.000 1.000
61.460 35.000 1.000
61.520 29.000 1.000
61.580 42.000 1.000
61.640 33.000 1.000
61.700 41.000 1.000
61.760 30.000 1.000
61.820 38.000 1.000
61.880 43.000 1.000
61.940 50.000 1.000
62.000 44.000 1.000
62.060 37.000 1.000
62.120 51.000 1.000
62.180 41.000 1.000
62.240 48.000 1.000
62.300 41.000 1.000
62.360 52.000 1.000
62.420 37.000 1.000
62.480 56.000 1.000
62.540 48.000 1.000
62.600 52.000 1.000
62.660 69.000 1.000
62.720 82.000 1.000
62.780 108.000 1.000
62.840 233.000 1.000
62.900 307.000 1.000
62.960 210.000 1.000
63.020 202.000 1.000
63.080 214.000 1.000
63.140 113.000 1.000
63.200 82.000 1.000
63.260 68.000 1.000
63.320 61.000 1.000
63.380 68.000 1.000
63.440 59.000 1.000
63.500 66.000 1.000
63.560 77.000 1.000
63.620 66.000 1.000
63.680 86.000 1.000
63.740 95.000 1.000
63.800 108.000 1.000
63.860 131.000 1.000
63.920 160.000 1.000
63.980 164.000 1.000
64.040 168.000 1.000
64.100 173.000 1.000
64.160 156.000 1.000
64.220 129.000 1.000
64.280 117.000 1.000
64.340 96.000 1.000
64.400 82.000 1.000
64.460 71.000 1.000
64.520 78.000 1.000
64.580 56.000 1.000
64.640 62.000 1.000
64.700 63.000 1.000
64.760 46.000 1.000
64.820 48.000 1.000
64.880 48.000 1.000
64.940 53.000 1.000
65.000 49.000 1.000
65.060 50.000 1.000
65.120 53.000 1.000
65.180 55.000 1.000
65.240 40.000 1.000
65.300 48.000 1.000
65.360 45.000 1.000
65.420 54.000 1.000
65.480 49.000 1.000
65.540 52.000 1.000
65.600 52.000 1.000
65.660 46.000 1.000
65.720 46.000 1.000
65.780 40.000 1.000
65.840 38.000 1.000
65.900 48.000 1.000
65.960 51.000 1.000
66.020 34.000 1.000
66.080 35.000 1.000
66.140 36.000 1.000
66.200 33.000 1.000
66.260 36.000 1.000
66.320 33.000 1.000
66.380 37.000 1.000
66.440 32.000 1.000
66.500 39.000 1.000
66.560 42.000 1.000
66.620 36.000 1.000
66.680 35.000 1.000
66.740 25.000 1.000
66.800 36.000 1.000
66.860 35.000 1.000
66.920 34.000 1.000
66.980 29.000 1.000
67.040 33.000 1.000
67.100 27.000 1.000
67.160 36.000 1.000
67.220 40.000 1.000
67.280 35.000 1.000
67.340 33.000 1.000
67.400 33.000 1.000
67.460 33.000 1.000
67.520 31.000 1.000
67.580 40.000 1.000
67.640 45.000 1.000
67.700 37.000 1.000
67.760 36.000 1.000
67.820 44.000 1.000
67.880 39.000 1.000
67.940 34.000 1.000
68.000 45.000 1.000
68.060 47.000 1.000
68.120 49.000 1.000
68.180 48.000 1.000
68.240 53.000 1.000
68.300 54.000 1.000
68.360 68.000 1.000
68.420 69.000 1.000
68.480 87.000 1.000
68.540 92.000 1.000
68.600 111.000 1.000
68.660 129.000 1.000
68.720 148.000 1.000
68.780 198.000 1.000
68.840 271.000 1.000
68.900 349.000 1.000
68.960 363.000 1.000
69.020 374.000 1.000
69.080 359.000 1.000
69.140 304.000 1.000
69.200 273.000 1.000
69.260 217.000 1.000
69.320 181.000 1.000
69.380 152.000 1.000
69.440 114.000 1.000
69.500 109.000 1.000
69.560 118.000 1.000
69.620 108.000 1.000
69.680 124.000 1.000
69.740 139.000 1.000
69.800 200.000 1.000
69.860 279.000 1.000
69.920 274.000 1.000
69.980 220.000 1.000
70.040 192.000 1.000
70.100 191.000 1.000
70.160 139.000 1.000
70.220 110.000 1.000
70.280 82.000 1.000
70.340 64.000 1.000
70.400 56.000 1.000
70.460 50.000 1.000
70.520 46.000 1.000
70.580 49.000 1.000
70.640 40.000 1.000
70.700 46.000 1.000
70.760 41.000 1.000
70.820 47.000 1.000
70.880 36.000 1.000
70.940 36.000 1.000
71.000 42.000 1.000
71.060 37.000 1.000
71.120 33.000 1.000
71.180 40.000 1.000
71.240 37.000 1.000
71.300 35.000 1.000
71.360 42.000 1.000
71.420 32.000 1.000
71.480 35.000 1.000
71.540 29.000 1.000
71.600 28.000 1.000
71.660 31.000 1.000
71.720 27.000 1.000
71.780 37.000 1.000
71.840 35.000 1.000
71.900 34.000 1.000
71.960 34.000 1.000
72.020 39.000 1.000
72.080 32.000 1.000
72.140 34.000 1.000
72.200 42.000 1.000
72.260 49.000 1.000
72.320 43.000 1.000
72.380 48.000 1.000
72.440 45.000 1.000
72.500 33.000 1.000
72.560 42.000 1.000
72.620 37.000 1.000
72.680 34.000 1.000
72.740 33.000 1.000
72.800 24.000 1.000
72.860 38.000 1.000
72.920 33.000 1.000
72.980 27.000 1.000
73.040 26.000 1.000
73.100 31.000 1.000
73.160 29.000 1.000
73.220 31.000 1.000
73.280 22.000 1.000
73.340 26.000 1.000
73.400 27.000 1.000
73.460 25.000 1.000
73.520 22.000 1.000
73.580 27.000 1.000
73.640 24.000 1.000
73.700 24.000 1.000
73.760 27.000 1.000
73.820 22.000 1.000
73.880 31.000 1.000
73.940 26.000 1.000
74.000 24.000 1.000
74.060 26.000 1.000
74.120 24.000 1.000
74.180 37.000 1.000
74.240 26.000 1.000
74.300 28.000 1.000
74.360 18.000 1.000
74.420 29.000 1.000
74.480 27.000 1.000
74.540 29.000 1.000
74.600 30.000 1.000
74.660 27.000 1.000
74.720 22.000 1.000
74.780 25.000 1.000
74.840 27.000 1.000
74.900 31.000 1.000
74.960 24.000 1.000
75.020 29.000 1.000
75.080 26.000 1.000
75.140 22.000 1.000
75.200 23.000 1.000
75.260 25.000 1.000
75.320 26.000 1.000
75.380 28.000 1.000
75.440 32.000 1.000
75.500 23.000 1.000
75.560 27.000 1.000
75.620 23.000 1.000
75.680 30.000 1.000
75.740 31.000 1.000
75.800 26.000 1.000
75.860 31.000 1.000
75.920 26.000 1.000
75.980 29.000 1.000
76.040 31.000 1.000
76.100 31.000 1.000
76.160 28.000 1.000
76.220 30.000 1.000
76.280 27.000 1.000
76.340 39.000 1.000
76.400 34.000 1.000
76.460 46.000 1.000
76.520 53.000 1.000
76.580 61.000 1.000
76.640 68.000 1.000
76.700 58.000 1.000
76.760 58.000 1.000
76.820 60.000 1.000
76.880 48.000 1.000
76.940 41.000 1.000
77.000 34.000 1.000
77.060 31.000 1.000
77.120 37.000 1.000
77.180 27.000 1.000
77.240 23.000 1.000
77.300 31.000 1.000
77.360 24.000 1.000
77.420 29.000 1.000
77.480 25.000 1.000
77.540 22.000 1.000
77.600 28.000 1.000
77.660 23.000 1.000
77.720 26.000 1.000
77.780 25.000 1.000
77.840 21.000 1.000
77.900 25.000 1.000
77.960 23.000 1.000
78.020 26.000 1.000
78.080 31.000 1.000
78.140 27.000 1.000
78.200 23.000 1.000
78.260 24.000 1.000
78.320 30.000 1.000
78.380 30.000 1.000
78.440 19.000 1.000
78.500 23.000 1.000
78.560 24.000 1.000
78.620 21.000 1.000
78.680 24.000 1.000
78.740 21.000 1.000
78.800 22.000 1.000
78.860 15.000 1.000
78.920 23.000 1.000
78.980 25.000 1.000
79.040 28.000 1.000
79.100 27.000 1.000
79.160 24.000 1.000
79.220 25.000 1.000
79.280 28.000 1.000
79.340 20.000 1.000
79.400 30.000 1.000
79.460 25.000 1.000
79.520 31.000 1.000
79.580 26.000 1.000
79.640 30.000 1.000
79.700 32.000 1.000
79.760 34.000 1.000
79.820 42.000 1.000
79.880 41.000 1.000
79.940 37.000 1.000
80.000 38.000 1.000
80.060 31.000 1.000
80.120 32.000 1.000
80.180 31.000 1.000
80.240 32.000 1.000
80.300 32.000 1.000
80.360 33.000 1.000
80.420 19.000 1.000
80.480 27.000 1.000
80.540 23.000 1.000
80.600 24.000 1.000
80.660 28.000 1.000
80.720 23.000 1.000
80.780 23.000 1.000
80.840 20.000 1.000
80.900 27.000 1.000
80.960 27.000 1.000
81.020 20.000 1.000
81.080 30.000 1.000
81.140 31.000 1.000
81.200 28.000 1.000
81.260 23.000 1.000
81.320 28.000 1.000
81.380 25.000 1.000
81.440 31.000 1.000
81.500 24.000 1.000
81.560 29.000 1.000
81.620 21.000 1.000
81.680 29.000 1.000
81.740 34.000 1.000
81.800 36.000 1.000
81.860 27.000 1.000
81.920 48.000 1.000
81.980 43.000 1.000
82.040 49.000 1.000
82.100 76.000 1.000
82.160 74.000 1.000
82.220 90.000 1.000
82.280 84.000 1.000
82.340 80.000 1.000
82.400 99.000 1.000
82.460 77.000 1.000
82.520 68.000 1.000
82.580 64.000 1.000
82.640 64.000 1.000
82.700 52.000 1.000
82.760 40.000 1.000
82.820 47.000 1.000
82.880 36.000 1.000
82.940 31.000 1.000
83.000 35.000 1.000
83.060 32.000 1.000
83.120 38.000 1.000
83.180 28.000 1.000
83.240 29.000 1.000
83.300 36.000 1.000
83.360 26.000 1.000
83.420 33.000 1.000
83.480 37.000 1.000
83.540 30.000 1.000
83.600 33.000 1.000
83.660 35.000 1.000
83.720 35.000 1.000
83.780 38.000 1.000
83.840 46.000 1.000
83.900 39.000 1.000
83.960 59.000 1.000
84.020 58.000 1.000
84.080 68.000 1.000
84.140 56.000 1.000
84.200 67.000 1.000
84.260 61.000 1.000
84.320 52.000 1.000
84.380 52.000 1.000
84.440 45.000 1.000
84.500 45.000 1.000
84.560 45.000 1.000
84.620 34.000 1.000
84.680 34.000 1.000
84.740 31.000 1.000
84.800 33.000 1.000
84.860 28.000 1.000
84.920 28.000 1.000
84.980 35.000 1.000
85.040 23.000 1.000
85.100 29.000 1.000
85.160 21.000 1.000
85.220 36.000 1.000
85.280 29.000 1.000
85.340 26.000 1.000
85.400 20.000 1.000
85.460 27.000 1.000
85.520 32.000 1.000
85.580 25.000 1.000
85.640 22.000 1.000
85.700 24.000 1.000
85.760 18.000 1.000
85.820 24.000 1.000
85.880 26.000 1.000
85.940 32.000 1.000
86.000 30.000 1.000
86.060 23.000 1.000
86.120 28.000 1.000
86.180 25.000 1.000
86.240 26.000 1.000
86.300 28.000 1.000
86.360 22.000 1.000
86.420 27.000 1.000
86.480 28.000 1.000
86.540 23.000 1.000
86.600 24.000 1.000
86.660 21.000 1.000
86.720 21.000 1.000
86.780 20.000 1.000
86.840 32.000 1.000
86.900 24.000 1.000
86.960 20.000 1.000
87.020 29.000 1.000
87.080 37.000 1.000
87.140 37.000 1.000
87.200 33.000 1.000
87.260 32.000 1.000
87.320 35.000 1.000
87.380 37.000 1.000
87.440 38.000 1.000
87.500 38.000 1.000
87.560 27.000 1.000
87.620 39.000 1.000
87.680 33.000 1.000
87.740 29.000 1.000
87.800 28.000 1.000
87.860 27.000 1.000
87.920 26.000 1.000
87.980 26.000 1.000
88.040 20.000 1.000
88.100 26.000 1.000
88.160 27.000 1.000
88.220 30.000 1.000
88.280 28.000 1.000
88.340 20.000 1.000
88.400 27.000 1.000
88.460 27.000 1.000
88.520 24.000 1.000
88.580 29.000 1.000
88.640 26.000 1.000
88.700 24.000 1.000
88.760 23.000 1.000
88.820 24.000 1.000
88.880 31.000 1.000
88.940 30.000 1.000
89.000 32.000 1.000
89.060 33.000 1.000
89.120 42.000 1.000
89.180 43.000 1.000
89.240 47.000 1.000
89.300 58.000 1.000
89.360 83.000 1.000
89.420 102.000 1.000
89.480 120.000 1.000
89.540 142.000 1.000
89.600 128.000 1.000
89.660 124.000 1.000
89.720 100.000 1.000
89.780 115.000 1.000
89.840 101.000 1.000
89.900 94.000 1.000
89.960 76.000 1.000
90.000 76.000 1.000
*RAS_INT_END
*RAS_DATA_END